ERROR      2018-07-29 15:58:39,544 Internal Server Error: /
Traceback (most recent call last):
  File "/usr/local/lib/python3.6/dist-packages/django/core/handlers/exception.py", line 35, in inner
    response = get_response(request)
  File "/usr/local/lib/python3.6/dist-packages/django/core/handlers/base.py", line 128, in _get_response
    response = self.process_exception_by_middleware(e, request)
  File "/usr/local/lib/python3.6/dist-packages/django/core/handlers/base.py", line 126, in _get_response
    response = wrapped_callback(request, *callback_args, **callback_kwargs)
  File "/home/oleg/git/mainapp/views.py", line 17, in main
    return render(request, 'mainapp/base.html', content)
  File "/usr/local/lib/python3.6/dist-packages/django/shortcuts.py", line 36, in render
    content = loader.render_to_string(template_name, context, request, using=using)
  File "/usr/local/lib/python3.6/dist-packages/django/template/loader.py", line 62, in render_to_string
    return template.render(context, request)
  File "/usr/local/lib/python3.6/dist-packages/django/template/backends/django.py", line 61, in render
    return self.template.render(context)
  File "/usr/local/lib/python3.6/dist-packages/django/template/base.py", line 175, in render
    return self._render(context)
  File "/usr/local/lib/python3.6/dist-packages/django/template/base.py", line 167, in _render
    return self.nodelist.render(context)
  File "/usr/local/lib/python3.6/dist-packages/django/template/base.py", line 943, in render
    bit = node.render_annotated(context)
  File "/usr/local/lib/python3.6/dist-packages/django/template/base.py", line 910, in render_annotated
    return self.render(context)
  File "/usr/local/lib/python3.6/dist-packages/django/template/loader_tags.py", line 194, in render
    return template.render(context)
  File "/usr/local/lib/python3.6/dist-packages/django/template/base.py", line 177, in render
    return self._render(context)
  File "/usr/local/lib/python3.6/dist-packages/django/template/base.py", line 167, in _render
    return self.nodelist.render(context)
  File "/usr/local/lib/python3.6/dist-packages/django/template/base.py", line 943, in render
    bit = node.render_annotated(context)
  File "/usr/local/lib/python3.6/dist-packages/django/template/base.py", line 910, in render_annotated
    return self.render(context)
  File "/usr/local/lib/python3.6/dist-packages/django/template/defaulttags.py", line 447, in render
    url = reverse(view_name, args=args, kwargs=kwargs, current_app=current_app)
  File "/usr/local/lib/python3.6/dist-packages/django/urls/base.py", line 88, in reverse
    return iri_to_uri(resolver._reverse_with_prefix(view, prefix, *args, **kwargs))
  File "/usr/local/lib/python3.6/dist-packages/django/urls/resolvers.py", line 632, in _reverse_with_prefix
    raise NoReverseMatch(msg)
django.urls.exceptions.NoReverseMatch: Reverse for 'category' not found. 'category' is not a valid view function or pattern name.
ERROR      2018-07-29 15:59:43,572 Internal Server Error: /
Traceback (most recent call last):
  File "/usr/local/lib/python3.6/dist-packages/django/core/handlers/exception.py", line 35, in inner
    response = get_response(request)
  File "/usr/local/lib/python3.6/dist-packages/django/core/handlers/base.py", line 128, in _get_response
    response = self.process_exception_by_middleware(e, request)
  File "/usr/local/lib/python3.6/dist-packages/django/core/handlers/base.py", line 126, in _get_response
    response = wrapped_callback(request, *callback_args, **callback_kwargs)
  File "/home/oleg/git/mainapp/views.py", line 17, in main
    return render(request, 'mainapp/base.html', content)
  File "/usr/local/lib/python3.6/dist-packages/django/shortcuts.py", line 36, in render
    content = loader.render_to_string(template_name, context, request, using=using)
  File "/usr/local/lib/python3.6/dist-packages/django/template/loader.py", line 62, in render_to_string
    return template.render(context, request)
  File "/usr/local/lib/python3.6/dist-packages/django/template/backends/django.py", line 61, in render
    return self.template.render(context)
  File "/usr/local/lib/python3.6/dist-packages/django/template/base.py", line 175, in render
    return self._render(context)
  File "/usr/local/lib/python3.6/dist-packages/django/template/base.py", line 167, in _render
    return self.nodelist.render(context)
  File "/usr/local/lib/python3.6/dist-packages/django/template/base.py", line 943, in render
    bit = node.render_annotated(context)
  File "/usr/local/lib/python3.6/dist-packages/django/template/base.py", line 910, in render_annotated
    return self.render(context)
  File "/usr/local/lib/python3.6/dist-packages/django/template/loader_tags.py", line 194, in render
    return template.render(context)
  File "/usr/local/lib/python3.6/dist-packages/django/template/base.py", line 177, in render
    return self._render(context)
  File "/usr/local/lib/python3.6/dist-packages/django/template/base.py", line 167, in _render
    return self.nodelist.render(context)
  File "/usr/local/lib/python3.6/dist-packages/django/template/base.py", line 943, in render
    bit = node.render_annotated(context)
  File "/usr/local/lib/python3.6/dist-packages/django/template/base.py", line 910, in render_annotated
    return self.render(context)
  File "/usr/local/lib/python3.6/dist-packages/django/template/defaulttags.py", line 447, in render
    url = reverse(view_name, args=args, kwargs=kwargs, current_app=current_app)
  File "/usr/local/lib/python3.6/dist-packages/django/urls/base.py", line 88, in reverse
    return iri_to_uri(resolver._reverse_with_prefix(view, prefix, *args, **kwargs))
  File "/usr/local/lib/python3.6/dist-packages/django/urls/resolvers.py", line 632, in _reverse_with_prefix
    raise NoReverseMatch(msg)
django.urls.exceptions.NoReverseMatch: Reverse for 'category' with no arguments not found. 1 pattern(s) tried: ['category\\/\\((?P<pk>[0-9]+)\\)\\/page\\/\\((?P<page>[0-9]+)\\)\\/$']
ERROR      2018-07-29 16:01:15,139 Internal Server Error: /
Traceback (most recent call last):
  File "/usr/local/lib/python3.6/dist-packages/django/urls/base.py", line 74, in reverse
    extra, resolver = resolver.namespace_dict[ns]
KeyError: 'auth'

During handling of the above exception, another exception occurred:

Traceback (most recent call last):
  File "/usr/local/lib/python3.6/dist-packages/django/core/handlers/exception.py", line 35, in inner
    response = get_response(request)
  File "/usr/local/lib/python3.6/dist-packages/django/core/handlers/base.py", line 128, in _get_response
    response = self.process_exception_by_middleware(e, request)
  File "/usr/local/lib/python3.6/dist-packages/django/core/handlers/base.py", line 126, in _get_response
    response = wrapped_callback(request, *callback_args, **callback_kwargs)
  File "/home/oleg/git/mainapp/views.py", line 17, in main
    return render(request, 'mainapp/base.html', content)
  File "/usr/local/lib/python3.6/dist-packages/django/shortcuts.py", line 36, in render
    content = loader.render_to_string(template_name, context, request, using=using)
  File "/usr/local/lib/python3.6/dist-packages/django/template/loader.py", line 62, in render_to_string
    return template.render(context, request)
  File "/usr/local/lib/python3.6/dist-packages/django/template/backends/django.py", line 61, in render
    return self.template.render(context)
  File "/usr/local/lib/python3.6/dist-packages/django/template/base.py", line 175, in render
    return self._render(context)
  File "/usr/local/lib/python3.6/dist-packages/django/template/base.py", line 167, in _render
    return self.nodelist.render(context)
  File "/usr/local/lib/python3.6/dist-packages/django/template/base.py", line 943, in render
    bit = node.render_annotated(context)
  File "/usr/local/lib/python3.6/dist-packages/django/template/base.py", line 910, in render_annotated
    return self.render(context)
  File "/usr/local/lib/python3.6/dist-packages/django/template/loader_tags.py", line 194, in render
    return template.render(context)
  File "/usr/local/lib/python3.6/dist-packages/django/template/base.py", line 177, in render
    return self._render(context)
  File "/usr/local/lib/python3.6/dist-packages/django/template/base.py", line 167, in _render
    return self.nodelist.render(context)
  File "/usr/local/lib/python3.6/dist-packages/django/template/base.py", line 943, in render
    bit = node.render_annotated(context)
  File "/usr/local/lib/python3.6/dist-packages/django/template/base.py", line 910, in render_annotated
    return self.render(context)
  File "/usr/local/lib/python3.6/dist-packages/django/template/defaulttags.py", line 314, in render
    return nodelist.render(context)
  File "/usr/local/lib/python3.6/dist-packages/django/template/base.py", line 943, in render
    bit = node.render_annotated(context)
  File "/usr/local/lib/python3.6/dist-packages/django/template/base.py", line 910, in render_annotated
    return self.render(context)
  File "/usr/local/lib/python3.6/dist-packages/django/template/defaulttags.py", line 447, in render
    url = reverse(view_name, args=args, kwargs=kwargs, current_app=current_app)
  File "/usr/local/lib/python3.6/dist-packages/django/urls/base.py", line 84, in reverse
    raise NoReverseMatch("%s is not a registered namespace" % key)
django.urls.exceptions.NoReverseMatch: 'auth' is not a registered namespace
ERROR      2018-07-29 16:02:55,750 Internal Server Error: /
Traceback (most recent call last):
  File "/usr/local/lib/python3.6/dist-packages/django/urls/base.py", line 74, in reverse
    extra, resolver = resolver.namespace_dict[ns]
KeyError: 'auth'

During handling of the above exception, another exception occurred:

Traceback (most recent call last):
  File "/usr/local/lib/python3.6/dist-packages/django/core/handlers/exception.py", line 35, in inner
    response = get_response(request)
  File "/usr/local/lib/python3.6/dist-packages/django/core/handlers/base.py", line 128, in _get_response
    response = self.process_exception_by_middleware(e, request)
  File "/usr/local/lib/python3.6/dist-packages/django/core/handlers/base.py", line 126, in _get_response
    response = wrapped_callback(request, *callback_args, **callback_kwargs)
  File "/home/oleg/git/mainapp/views.py", line 17, in main
    return render(request, 'mainapp/base.html', content)
  File "/usr/local/lib/python3.6/dist-packages/django/shortcuts.py", line 36, in render
    content = loader.render_to_string(template_name, context, request, using=using)
  File "/usr/local/lib/python3.6/dist-packages/django/template/loader.py", line 62, in render_to_string
    return template.render(context, request)
  File "/usr/local/lib/python3.6/dist-packages/django/template/backends/django.py", line 61, in render
    return self.template.render(context)
  File "/usr/local/lib/python3.6/dist-packages/django/template/base.py", line 175, in render
    return self._render(context)
  File "/usr/local/lib/python3.6/dist-packages/django/template/base.py", line 167, in _render
    return self.nodelist.render(context)
  File "/usr/local/lib/python3.6/dist-packages/django/template/base.py", line 943, in render
    bit = node.render_annotated(context)
  File "/usr/local/lib/python3.6/dist-packages/django/template/base.py", line 910, in render_annotated
    return self.render(context)
  File "/usr/local/lib/python3.6/dist-packages/django/template/loader_tags.py", line 194, in render
    return template.render(context)
  File "/usr/local/lib/python3.6/dist-packages/django/template/base.py", line 177, in render
    return self._render(context)
  File "/usr/local/lib/python3.6/dist-packages/django/template/base.py", line 167, in _render
    return self.nodelist.render(context)
  File "/usr/local/lib/python3.6/dist-packages/django/template/base.py", line 943, in render
    bit = node.render_annotated(context)
  File "/usr/local/lib/python3.6/dist-packages/django/template/base.py", line 910, in render_annotated
    return self.render(context)
  File "/usr/local/lib/python3.6/dist-packages/django/template/defaulttags.py", line 314, in render
    return nodelist.render(context)
  File "/usr/local/lib/python3.6/dist-packages/django/template/base.py", line 943, in render
    bit = node.render_annotated(context)
  File "/usr/local/lib/python3.6/dist-packages/django/template/base.py", line 910, in render_annotated
    return self.render(context)
  File "/usr/local/lib/python3.6/dist-packages/django/template/defaulttags.py", line 447, in render
    url = reverse(view_name, args=args, kwargs=kwargs, current_app=current_app)
  File "/usr/local/lib/python3.6/dist-packages/django/urls/base.py", line 84, in reverse
    raise NoReverseMatch("%s is not a registered namespace" % key)
django.urls.exceptions.NoReverseMatch: 'auth' is not a registered namespace
ERROR      2018-07-29 16:27:10,291 Internal Server Error: /
Traceback (most recent call last):
  File "/usr/local/lib/python3.6/dist-packages/django/urls/base.py", line 74, in reverse
    extra, resolver = resolver.namespace_dict[ns]
KeyError: 'auth'

During handling of the above exception, another exception occurred:

Traceback (most recent call last):
  File "/usr/local/lib/python3.6/dist-packages/django/core/handlers/exception.py", line 35, in inner
    response = get_response(request)
  File "/usr/local/lib/python3.6/dist-packages/django/core/handlers/base.py", line 128, in _get_response
    response = self.process_exception_by_middleware(e, request)
  File "/usr/local/lib/python3.6/dist-packages/django/core/handlers/base.py", line 126, in _get_response
    response = wrapped_callback(request, *callback_args, **callback_kwargs)
  File "/home/oleg/git/mainapp/views.py", line 17, in main
    return render(request, 'mainapp/base.html', content)
  File "/usr/local/lib/python3.6/dist-packages/django/shortcuts.py", line 36, in render
    content = loader.render_to_string(template_name, context, request, using=using)
  File "/usr/local/lib/python3.6/dist-packages/django/template/loader.py", line 62, in render_to_string
    return template.render(context, request)
  File "/usr/local/lib/python3.6/dist-packages/django/template/backends/django.py", line 61, in render
    return self.template.render(context)
  File "/usr/local/lib/python3.6/dist-packages/django/template/base.py", line 175, in render
    return self._render(context)
  File "/usr/local/lib/python3.6/dist-packages/django/template/base.py", line 167, in _render
    return self.nodelist.render(context)
  File "/usr/local/lib/python3.6/dist-packages/django/template/base.py", line 943, in render
    bit = node.render_annotated(context)
  File "/usr/local/lib/python3.6/dist-packages/django/template/base.py", line 910, in render_annotated
    return self.render(context)
  File "/usr/local/lib/python3.6/dist-packages/django/template/loader_tags.py", line 194, in render
    return template.render(context)
  File "/usr/local/lib/python3.6/dist-packages/django/template/base.py", line 177, in render
    return self._render(context)
  File "/usr/local/lib/python3.6/dist-packages/django/template/base.py", line 167, in _render
    return self.nodelist.render(context)
  File "/usr/local/lib/python3.6/dist-packages/django/template/base.py", line 943, in render
    bit = node.render_annotated(context)
  File "/usr/local/lib/python3.6/dist-packages/django/template/base.py", line 910, in render_annotated
    return self.render(context)
  File "/usr/local/lib/python3.6/dist-packages/django/template/defaulttags.py", line 314, in render
    return nodelist.render(context)
  File "/usr/local/lib/python3.6/dist-packages/django/template/base.py", line 943, in render
    bit = node.render_annotated(context)
  File "/usr/local/lib/python3.6/dist-packages/django/template/base.py", line 910, in render_annotated
    return self.render(context)
  File "/usr/local/lib/python3.6/dist-packages/django/template/defaulttags.py", line 447, in render
    url = reverse(view_name, args=args, kwargs=kwargs, current_app=current_app)
  File "/usr/local/lib/python3.6/dist-packages/django/urls/base.py", line 84, in reverse
    raise NoReverseMatch("%s is not a registered namespace" % key)
django.urls.exceptions.NoReverseMatch: 'auth' is not a registered namespace
ERROR      2018-07-29 16:27:16,262 Internal Server Error: /
Traceback (most recent call last):
  File "/usr/local/lib/python3.6/dist-packages/django/urls/base.py", line 74, in reverse
    extra, resolver = resolver.namespace_dict[ns]
KeyError: 'auth'

During handling of the above exception, another exception occurred:

Traceback (most recent call last):
  File "/usr/local/lib/python3.6/dist-packages/django/core/handlers/exception.py", line 35, in inner
    response = get_response(request)
  File "/usr/local/lib/python3.6/dist-packages/django/core/handlers/base.py", line 128, in _get_response
    response = self.process_exception_by_middleware(e, request)
  File "/usr/local/lib/python3.6/dist-packages/django/core/handlers/base.py", line 126, in _get_response
    response = wrapped_callback(request, *callback_args, **callback_kwargs)
  File "/home/oleg/git/mainapp/views.py", line 17, in main
    return render(request, 'mainapp/base.html', content)
  File "/usr/local/lib/python3.6/dist-packages/django/shortcuts.py", line 36, in render
    content = loader.render_to_string(template_name, context, request, using=using)
  File "/usr/local/lib/python3.6/dist-packages/django/template/loader.py", line 62, in render_to_string
    return template.render(context, request)
  File "/usr/local/lib/python3.6/dist-packages/django/template/backends/django.py", line 61, in render
    return self.template.render(context)
  File "/usr/local/lib/python3.6/dist-packages/django/template/base.py", line 175, in render
    return self._render(context)
  File "/usr/local/lib/python3.6/dist-packages/django/template/base.py", line 167, in _render
    return self.nodelist.render(context)
  File "/usr/local/lib/python3.6/dist-packages/django/template/base.py", line 943, in render
    bit = node.render_annotated(context)
  File "/usr/local/lib/python3.6/dist-packages/django/template/base.py", line 910, in render_annotated
    return self.render(context)
  File "/usr/local/lib/python3.6/dist-packages/django/template/loader_tags.py", line 194, in render
    return template.render(context)
  File "/usr/local/lib/python3.6/dist-packages/django/template/base.py", line 177, in render
    return self._render(context)
  File "/usr/local/lib/python3.6/dist-packages/django/template/base.py", line 167, in _render
    return self.nodelist.render(context)
  File "/usr/local/lib/python3.6/dist-packages/django/template/base.py", line 943, in render
    bit = node.render_annotated(context)
  File "/usr/local/lib/python3.6/dist-packages/django/template/base.py", line 910, in render_annotated
    return self.render(context)
  File "/usr/local/lib/python3.6/dist-packages/django/template/defaulttags.py", line 314, in render
    return nodelist.render(context)
  File "/usr/local/lib/python3.6/dist-packages/django/template/base.py", line 943, in render
    bit = node.render_annotated(context)
  File "/usr/local/lib/python3.6/dist-packages/django/template/base.py", line 910, in render_annotated
    return self.render(context)
  File "/usr/local/lib/python3.6/dist-packages/django/template/defaulttags.py", line 447, in render
    url = reverse(view_name, args=args, kwargs=kwargs, current_app=current_app)
  File "/usr/local/lib/python3.6/dist-packages/django/urls/base.py", line 84, in reverse
    raise NoReverseMatch("%s is not a registered namespace" % key)
django.urls.exceptions.NoReverseMatch: 'auth' is not a registered namespace
ERROR      2018-07-29 16:35:28,912 Internal Server Error: /
Traceback (most recent call last):
  File "/usr/local/lib/python3.6/dist-packages/django/urls/base.py", line 74, in reverse
    extra, resolver = resolver.namespace_dict[ns]
KeyError: 'contacts'

During handling of the above exception, another exception occurred:

Traceback (most recent call last):
  File "/usr/local/lib/python3.6/dist-packages/django/core/handlers/exception.py", line 35, in inner
    response = get_response(request)
  File "/usr/local/lib/python3.6/dist-packages/django/core/handlers/base.py", line 128, in _get_response
    response = self.process_exception_by_middleware(e, request)
  File "/usr/local/lib/python3.6/dist-packages/django/core/handlers/base.py", line 126, in _get_response
    response = wrapped_callback(request, *callback_args, **callback_kwargs)
  File "/home/oleg/git/mainapp/views.py", line 17, in main
    return render(request, 'mainapp/base.html', content)
  File "/usr/local/lib/python3.6/dist-packages/django/shortcuts.py", line 36, in render
    content = loader.render_to_string(template_name, context, request, using=using)
  File "/usr/local/lib/python3.6/dist-packages/django/template/loader.py", line 62, in render_to_string
    return template.render(context, request)
  File "/usr/local/lib/python3.6/dist-packages/django/template/backends/django.py", line 61, in render
    return self.template.render(context)
  File "/usr/local/lib/python3.6/dist-packages/django/template/base.py", line 175, in render
    return self._render(context)
  File "/usr/local/lib/python3.6/dist-packages/django/template/base.py", line 167, in _render
    return self.nodelist.render(context)
  File "/usr/local/lib/python3.6/dist-packages/django/template/base.py", line 943, in render
    bit = node.render_annotated(context)
  File "/usr/local/lib/python3.6/dist-packages/django/template/base.py", line 910, in render_annotated
    return self.render(context)
  File "/usr/local/lib/python3.6/dist-packages/django/template/loader_tags.py", line 194, in render
    return template.render(context)
  File "/usr/local/lib/python3.6/dist-packages/django/template/base.py", line 177, in render
    return self._render(context)
  File "/usr/local/lib/python3.6/dist-packages/django/template/base.py", line 167, in _render
    return self.nodelist.render(context)
  File "/usr/local/lib/python3.6/dist-packages/django/template/base.py", line 943, in render
    bit = node.render_annotated(context)
  File "/usr/local/lib/python3.6/dist-packages/django/template/base.py", line 910, in render_annotated
    return self.render(context)
  File "/usr/local/lib/python3.6/dist-packages/django/template/defaulttags.py", line 447, in render
    url = reverse(view_name, args=args, kwargs=kwargs, current_app=current_app)
  File "/usr/local/lib/python3.6/dist-packages/django/urls/base.py", line 84, in reverse
    raise NoReverseMatch("%s is not a registered namespace" % key)
django.urls.exceptions.NoReverseMatch: 'contacts' is not a registered namespace
ERROR      2018-07-29 16:36:31,295 Internal Server Error: /
Traceback (most recent call last):
  File "/usr/local/lib/python3.6/dist-packages/django/urls/base.py", line 74, in reverse
    extra, resolver = resolver.namespace_dict[ns]
KeyError: 'contacts'

During handling of the above exception, another exception occurred:

Traceback (most recent call last):
  File "/usr/local/lib/python3.6/dist-packages/django/core/handlers/exception.py", line 35, in inner
    response = get_response(request)
  File "/usr/local/lib/python3.6/dist-packages/django/core/handlers/base.py", line 128, in _get_response
    response = self.process_exception_by_middleware(e, request)
  File "/usr/local/lib/python3.6/dist-packages/django/core/handlers/base.py", line 126, in _get_response
    response = wrapped_callback(request, *callback_args, **callback_kwargs)
  File "/home/oleg/git/mainapp/views.py", line 17, in main
    return render(request, 'mainapp/base.html', content)
  File "/usr/local/lib/python3.6/dist-packages/django/shortcuts.py", line 36, in render
    content = loader.render_to_string(template_name, context, request, using=using)
  File "/usr/local/lib/python3.6/dist-packages/django/template/loader.py", line 62, in render_to_string
    return template.render(context, request)
  File "/usr/local/lib/python3.6/dist-packages/django/template/backends/django.py", line 61, in render
    return self.template.render(context)
  File "/usr/local/lib/python3.6/dist-packages/django/template/base.py", line 175, in render
    return self._render(context)
  File "/usr/local/lib/python3.6/dist-packages/django/template/base.py", line 167, in _render
    return self.nodelist.render(context)
  File "/usr/local/lib/python3.6/dist-packages/django/template/base.py", line 943, in render
    bit = node.render_annotated(context)
  File "/usr/local/lib/python3.6/dist-packages/django/template/base.py", line 910, in render_annotated
    return self.render(context)
  File "/usr/local/lib/python3.6/dist-packages/django/template/loader_tags.py", line 194, in render
    return template.render(context)
  File "/usr/local/lib/python3.6/dist-packages/django/template/base.py", line 177, in render
    return self._render(context)
  File "/usr/local/lib/python3.6/dist-packages/django/template/base.py", line 167, in _render
    return self.nodelist.render(context)
  File "/usr/local/lib/python3.6/dist-packages/django/template/base.py", line 943, in render
    bit = node.render_annotated(context)
  File "/usr/local/lib/python3.6/dist-packages/django/template/base.py", line 910, in render_annotated
    return self.render(context)
  File "/usr/local/lib/python3.6/dist-packages/django/template/defaulttags.py", line 447, in render
    url = reverse(view_name, args=args, kwargs=kwargs, current_app=current_app)
  File "/usr/local/lib/python3.6/dist-packages/django/urls/base.py", line 84, in reverse
    raise NoReverseMatch("%s is not a registered namespace" % key)
django.urls.exceptions.NoReverseMatch: 'contacts' is not a registered namespace
ERROR      2018-07-29 16:37:12,975 Internal Server Error: /
Traceback (most recent call last):
  File "/usr/local/lib/python3.6/dist-packages/django/urls/base.py", line 74, in reverse
    extra, resolver = resolver.namespace_dict[ns]
KeyError: 'basket'

During handling of the above exception, another exception occurred:

Traceback (most recent call last):
  File "/usr/local/lib/python3.6/dist-packages/django/core/handlers/exception.py", line 35, in inner
    response = get_response(request)
  File "/usr/local/lib/python3.6/dist-packages/django/core/handlers/base.py", line 128, in _get_response
    response = self.process_exception_by_middleware(e, request)
  File "/usr/local/lib/python3.6/dist-packages/django/core/handlers/base.py", line 126, in _get_response
    response = wrapped_callback(request, *callback_args, **callback_kwargs)
  File "/home/oleg/git/mainapp/views.py", line 17, in main
    return render(request, 'mainapp/base.html', content)
  File "/usr/local/lib/python3.6/dist-packages/django/shortcuts.py", line 36, in render
    content = loader.render_to_string(template_name, context, request, using=using)
  File "/usr/local/lib/python3.6/dist-packages/django/template/loader.py", line 62, in render_to_string
    return template.render(context, request)
  File "/usr/local/lib/python3.6/dist-packages/django/template/backends/django.py", line 61, in render
    return self.template.render(context)
  File "/usr/local/lib/python3.6/dist-packages/django/template/base.py", line 175, in render
    return self._render(context)
  File "/usr/local/lib/python3.6/dist-packages/django/template/base.py", line 167, in _render
    return self.nodelist.render(context)
  File "/usr/local/lib/python3.6/dist-packages/django/template/base.py", line 943, in render
    bit = node.render_annotated(context)
  File "/usr/local/lib/python3.6/dist-packages/django/template/base.py", line 910, in render_annotated
    return self.render(context)
  File "/usr/local/lib/python3.6/dist-packages/django/template/loader_tags.py", line 194, in render
    return template.render(context)
  File "/usr/local/lib/python3.6/dist-packages/django/template/base.py", line 177, in render
    return self._render(context)
  File "/usr/local/lib/python3.6/dist-packages/django/template/base.py", line 167, in _render
    return self.nodelist.render(context)
  File "/usr/local/lib/python3.6/dist-packages/django/template/base.py", line 943, in render
    bit = node.render_annotated(context)
  File "/usr/local/lib/python3.6/dist-packages/django/template/base.py", line 910, in render_annotated
    return self.render(context)
  File "/usr/local/lib/python3.6/dist-packages/django/template/defaulttags.py", line 447, in render
    url = reverse(view_name, args=args, kwargs=kwargs, current_app=current_app)
  File "/usr/local/lib/python3.6/dist-packages/django/urls/base.py", line 84, in reverse
    raise NoReverseMatch("%s is not a registered namespace" % key)
django.urls.exceptions.NoReverseMatch: 'basket' is not a registered namespace
ERROR      2018-07-29 16:38:09,309 Internal Server Error: /
Traceback (most recent call last):
  File "/usr/local/lib/python3.6/dist-packages/django/urls/base.py", line 74, in reverse
    extra, resolver = resolver.namespace_dict[ns]
KeyError: 'contacts'

During handling of the above exception, another exception occurred:

Traceback (most recent call last):
  File "/usr/local/lib/python3.6/dist-packages/django/core/handlers/exception.py", line 35, in inner
    response = get_response(request)
  File "/usr/local/lib/python3.6/dist-packages/django/core/handlers/base.py", line 128, in _get_response
    response = self.process_exception_by_middleware(e, request)
  File "/usr/local/lib/python3.6/dist-packages/django/core/handlers/base.py", line 126, in _get_response
    response = wrapped_callback(request, *callback_args, **callback_kwargs)
  File "/home/oleg/git/mainapp/views.py", line 17, in main
    return render(request, 'mainapp/base.html', content)
  File "/usr/local/lib/python3.6/dist-packages/django/shortcuts.py", line 36, in render
    content = loader.render_to_string(template_name, context, request, using=using)
  File "/usr/local/lib/python3.6/dist-packages/django/template/loader.py", line 62, in render_to_string
    return template.render(context, request)
  File "/usr/local/lib/python3.6/dist-packages/django/template/backends/django.py", line 61, in render
    return self.template.render(context)
  File "/usr/local/lib/python3.6/dist-packages/django/template/base.py", line 175, in render
    return self._render(context)
  File "/usr/local/lib/python3.6/dist-packages/django/template/base.py", line 167, in _render
    return self.nodelist.render(context)
  File "/usr/local/lib/python3.6/dist-packages/django/template/base.py", line 943, in render
    bit = node.render_annotated(context)
  File "/usr/local/lib/python3.6/dist-packages/django/template/base.py", line 910, in render_annotated
    return self.render(context)
  File "/usr/local/lib/python3.6/dist-packages/django/template/loader_tags.py", line 194, in render
    return template.render(context)
  File "/usr/local/lib/python3.6/dist-packages/django/template/base.py", line 177, in render
    return self._render(context)
  File "/usr/local/lib/python3.6/dist-packages/django/template/base.py", line 167, in _render
    return self.nodelist.render(context)
  File "/usr/local/lib/python3.6/dist-packages/django/template/base.py", line 943, in render
    bit = node.render_annotated(context)
  File "/usr/local/lib/python3.6/dist-packages/django/template/base.py", line 910, in render_annotated
    return self.render(context)
  File "/usr/local/lib/python3.6/dist-packages/django/template/defaulttags.py", line 447, in render
    url = reverse(view_name, args=args, kwargs=kwargs, current_app=current_app)
  File "/usr/local/lib/python3.6/dist-packages/django/urls/base.py", line 84, in reverse
    raise NoReverseMatch("%s is not a registered namespace" % key)
django.urls.exceptions.NoReverseMatch: 'contacts' is not a registered namespace
WARNING    2018-07-29 16:38:57,797 Not Found: /basket/
ERROR      2018-07-29 16:41:28,801 Internal Server Error: /
Traceback (most recent call last):
  File "/usr/local/lib/python3.6/dist-packages/django/urls/base.py", line 74, in reverse
    extra, resolver = resolver.namespace_dict[ns]
KeyError: 'contacts'

During handling of the above exception, another exception occurred:

Traceback (most recent call last):
  File "/usr/local/lib/python3.6/dist-packages/django/core/handlers/exception.py", line 35, in inner
    response = get_response(request)
  File "/usr/local/lib/python3.6/dist-packages/django/core/handlers/base.py", line 128, in _get_response
    response = self.process_exception_by_middleware(e, request)
  File "/usr/local/lib/python3.6/dist-packages/django/core/handlers/base.py", line 126, in _get_response
    response = wrapped_callback(request, *callback_args, **callback_kwargs)
  File "/home/oleg/git/mainapp/views.py", line 17, in main
    return render(request, 'mainapp/base.html', content)
  File "/usr/local/lib/python3.6/dist-packages/django/shortcuts.py", line 36, in render
    content = loader.render_to_string(template_name, context, request, using=using)
  File "/usr/local/lib/python3.6/dist-packages/django/template/loader.py", line 62, in render_to_string
    return template.render(context, request)
  File "/usr/local/lib/python3.6/dist-packages/django/template/backends/django.py", line 61, in render
    return self.template.render(context)
  File "/usr/local/lib/python3.6/dist-packages/django/template/base.py", line 175, in render
    return self._render(context)
  File "/usr/local/lib/python3.6/dist-packages/django/template/base.py", line 167, in _render
    return self.nodelist.render(context)
  File "/usr/local/lib/python3.6/dist-packages/django/template/base.py", line 943, in render
    bit = node.render_annotated(context)
  File "/usr/local/lib/python3.6/dist-packages/django/template/base.py", line 910, in render_annotated
    return self.render(context)
  File "/usr/local/lib/python3.6/dist-packages/django/template/loader_tags.py", line 194, in render
    return template.render(context)
  File "/usr/local/lib/python3.6/dist-packages/django/template/base.py", line 177, in render
    return self._render(context)
  File "/usr/local/lib/python3.6/dist-packages/django/template/base.py", line 167, in _render
    return self.nodelist.render(context)
  File "/usr/local/lib/python3.6/dist-packages/django/template/base.py", line 943, in render
    bit = node.render_annotated(context)
  File "/usr/local/lib/python3.6/dist-packages/django/template/base.py", line 910, in render_annotated
    return self.render(context)
  File "/usr/local/lib/python3.6/dist-packages/django/template/defaulttags.py", line 447, in render
    url = reverse(view_name, args=args, kwargs=kwargs, current_app=current_app)
  File "/usr/local/lib/python3.6/dist-packages/django/urls/base.py", line 84, in reverse
    raise NoReverseMatch("%s is not a registered namespace" % key)
django.urls.exceptions.NoReverseMatch: 'contacts' is not a registered namespace
ERROR      2018-07-29 16:49:31,532 Internal Server Error: /
Traceback (most recent call last):
  File "/usr/local/lib/python3.6/dist-packages/django/urls/base.py", line 74, in reverse
    extra, resolver = resolver.namespace_dict[ns]
KeyError: 'contacts'

During handling of the above exception, another exception occurred:

Traceback (most recent call last):
  File "/usr/local/lib/python3.6/dist-packages/django/core/handlers/exception.py", line 35, in inner
    response = get_response(request)
  File "/usr/local/lib/python3.6/dist-packages/django/core/handlers/base.py", line 128, in _get_response
    response = self.process_exception_by_middleware(e, request)
  File "/usr/local/lib/python3.6/dist-packages/django/core/handlers/base.py", line 126, in _get_response
    response = wrapped_callback(request, *callback_args, **callback_kwargs)
  File "/home/oleg/git/mainapp/views.py", line 24, in main
    return render(request, 'mainapp/base.html', content)
  File "/usr/local/lib/python3.6/dist-packages/django/shortcuts.py", line 36, in render
    content = loader.render_to_string(template_name, context, request, using=using)
  File "/usr/local/lib/python3.6/dist-packages/django/template/loader.py", line 62, in render_to_string
    return template.render(context, request)
  File "/usr/local/lib/python3.6/dist-packages/django/template/backends/django.py", line 61, in render
    return self.template.render(context)
  File "/usr/local/lib/python3.6/dist-packages/django/template/base.py", line 175, in render
    return self._render(context)
  File "/usr/local/lib/python3.6/dist-packages/django/template/base.py", line 167, in _render
    return self.nodelist.render(context)
  File "/usr/local/lib/python3.6/dist-packages/django/template/base.py", line 943, in render
    bit = node.render_annotated(context)
  File "/usr/local/lib/python3.6/dist-packages/django/template/base.py", line 910, in render_annotated
    return self.render(context)
  File "/usr/local/lib/python3.6/dist-packages/django/template/loader_tags.py", line 194, in render
    return template.render(context)
  File "/usr/local/lib/python3.6/dist-packages/django/template/base.py", line 177, in render
    return self._render(context)
  File "/usr/local/lib/python3.6/dist-packages/django/template/base.py", line 167, in _render
    return self.nodelist.render(context)
  File "/usr/local/lib/python3.6/dist-packages/django/template/base.py", line 943, in render
    bit = node.render_annotated(context)
  File "/usr/local/lib/python3.6/dist-packages/django/template/base.py", line 910, in render_annotated
    return self.render(context)
  File "/usr/local/lib/python3.6/dist-packages/django/template/defaulttags.py", line 447, in render
    url = reverse(view_name, args=args, kwargs=kwargs, current_app=current_app)
  File "/usr/local/lib/python3.6/dist-packages/django/urls/base.py", line 84, in reverse
    raise NoReverseMatch("%s is not a registered namespace" % key)
django.urls.exceptions.NoReverseMatch: 'contacts' is not a registered namespace
ERROR      2018-07-29 16:52:04,106 Internal Server Error: /
Traceback (most recent call last):
  File "/usr/local/lib/python3.6/dist-packages/django/urls/base.py", line 74, in reverse
    extra, resolver = resolver.namespace_dict[ns]
KeyError: 'basket'

During handling of the above exception, another exception occurred:

Traceback (most recent call last):
  File "/usr/local/lib/python3.6/dist-packages/django/core/handlers/exception.py", line 35, in inner
    response = get_response(request)
  File "/usr/local/lib/python3.6/dist-packages/django/core/handlers/base.py", line 128, in _get_response
    response = self.process_exception_by_middleware(e, request)
  File "/usr/local/lib/python3.6/dist-packages/django/core/handlers/base.py", line 126, in _get_response
    response = wrapped_callback(request, *callback_args, **callback_kwargs)
  File "/home/oleg/git/mainapp/views.py", line 24, in main
    return render(request, 'mainapp/base.html', content)
  File "/usr/local/lib/python3.6/dist-packages/django/shortcuts.py", line 36, in render
    content = loader.render_to_string(template_name, context, request, using=using)
  File "/usr/local/lib/python3.6/dist-packages/django/template/loader.py", line 62, in render_to_string
    return template.render(context, request)
  File "/usr/local/lib/python3.6/dist-packages/django/template/backends/django.py", line 61, in render
    return self.template.render(context)
  File "/usr/local/lib/python3.6/dist-packages/django/template/base.py", line 175, in render
    return self._render(context)
  File "/usr/local/lib/python3.6/dist-packages/django/template/base.py", line 167, in _render
    return self.nodelist.render(context)
  File "/usr/local/lib/python3.6/dist-packages/django/template/base.py", line 943, in render
    bit = node.render_annotated(context)
  File "/usr/local/lib/python3.6/dist-packages/django/template/base.py", line 910, in render_annotated
    return self.render(context)
  File "/usr/local/lib/python3.6/dist-packages/django/template/loader_tags.py", line 194, in render
    return template.render(context)
  File "/usr/local/lib/python3.6/dist-packages/django/template/base.py", line 177, in render
    return self._render(context)
  File "/usr/local/lib/python3.6/dist-packages/django/template/base.py", line 167, in _render
    return self.nodelist.render(context)
  File "/usr/local/lib/python3.6/dist-packages/django/template/base.py", line 943, in render
    bit = node.render_annotated(context)
  File "/usr/local/lib/python3.6/dist-packages/django/template/base.py", line 910, in render_annotated
    return self.render(context)
  File "/usr/local/lib/python3.6/dist-packages/django/template/defaulttags.py", line 447, in render
    url = reverse(view_name, args=args, kwargs=kwargs, current_app=current_app)
  File "/usr/local/lib/python3.6/dist-packages/django/urls/base.py", line 84, in reverse
    raise NoReverseMatch("%s is not a registered namespace" % key)
django.urls.exceptions.NoReverseMatch: 'basket' is not a registered namespace
WARNING    2018-07-29 16:54:19,776 Not Found: /accounts/login/
ERROR      2018-07-29 16:54:53,076 Internal Server Error: /auth/login/
Traceback (most recent call last):
  File "/usr/local/lib/python3.6/dist-packages/django/db/backends/utils.py", line 85, in _execute
    return self.cursor.execute(sql, params)
psycopg2.ProgrammingError: relation "authapp_shopuser" does not exist
LINE 1: ...shopuser"."avatar", "authapp_shopuser"."age" FROM "authapp_s...
                                                             ^


The above exception was the direct cause of the following exception:

Traceback (most recent call last):
  File "/usr/local/lib/python3.6/dist-packages/django/core/handlers/exception.py", line 35, in inner
    response = get_response(request)
  File "/usr/local/lib/python3.6/dist-packages/django/core/handlers/base.py", line 128, in _get_response
    response = self.process_exception_by_middleware(e, request)
  File "/usr/local/lib/python3.6/dist-packages/django/core/handlers/base.py", line 126, in _get_response
    response = wrapped_callback(request, *callback_args, **callback_kwargs)
  File "/home/oleg/git/authapp/views.py", line 19, in login
    if request.method == 'POST' and login_form.is_valid():
  File "/usr/local/lib/python3.6/dist-packages/django/forms/forms.py", line 179, in is_valid
    return self.is_bound and not self.errors
  File "/usr/local/lib/python3.6/dist-packages/django/forms/forms.py", line 174, in errors
    self.full_clean()
  File "/usr/local/lib/python3.6/dist-packages/django/forms/forms.py", line 377, in full_clean
    self._clean_form()
  File "/usr/local/lib/python3.6/dist-packages/django/forms/forms.py", line 404, in _clean_form
    cleaned_data = self.clean()
  File "/usr/local/lib/python3.6/dist-packages/django/contrib/auth/forms.py", line 195, in clean
    self.user_cache = authenticate(self.request, username=username, password=password)
  File "/usr/local/lib/python3.6/dist-packages/django/contrib/auth/__init__.py", line 70, in authenticate
    user = _authenticate_with_backend(backend, backend_path, request, credentials)
  File "/usr/local/lib/python3.6/dist-packages/django/contrib/auth/__init__.py", line 116, in _authenticate_with_backend
    return backend.authenticate(*args, **credentials)
  File "/usr/local/lib/python3.6/dist-packages/django/contrib/auth/backends.py", line 16, in authenticate
    user = UserModel._default_manager.get_by_natural_key(username)
  File "/usr/local/lib/python3.6/dist-packages/django/contrib/auth/base_user.py", line 44, in get_by_natural_key
    return self.get(**{self.model.USERNAME_FIELD: username})
  File "/usr/local/lib/python3.6/dist-packages/django/db/models/manager.py", line 82, in manager_method
    return getattr(self.get_queryset(), name)(*args, **kwargs)
  File "/usr/local/lib/python3.6/dist-packages/django/db/models/query.py", line 397, in get
    num = len(clone)
  File "/usr/local/lib/python3.6/dist-packages/django/db/models/query.py", line 254, in __len__
    self._fetch_all()
  File "/usr/local/lib/python3.6/dist-packages/django/db/models/query.py", line 1179, in _fetch_all
    self._result_cache = list(self._iterable_class(self))
  File "/usr/local/lib/python3.6/dist-packages/django/db/models/query.py", line 53, in __iter__
    results = compiler.execute_sql(chunked_fetch=self.chunked_fetch, chunk_size=self.chunk_size)
  File "/usr/local/lib/python3.6/dist-packages/django/db/models/sql/compiler.py", line 1066, in execute_sql
    cursor.execute(sql, params)
  File "/usr/local/lib/python3.6/dist-packages/django/db/backends/utils.py", line 100, in execute
    return super().execute(sql, params)
  File "/usr/local/lib/python3.6/dist-packages/django/db/backends/utils.py", line 68, in execute
    return self._execute_with_wrappers(sql, params, many=False, executor=self._execute)
  File "/usr/local/lib/python3.6/dist-packages/django/db/backends/utils.py", line 77, in _execute_with_wrappers
    return executor(sql, params, many, context)
  File "/usr/local/lib/python3.6/dist-packages/django/db/backends/utils.py", line 85, in _execute
    return self.cursor.execute(sql, params)
  File "/usr/local/lib/python3.6/dist-packages/django/db/utils.py", line 89, in __exit__
    raise dj_exc_value.with_traceback(traceback) from exc_value
  File "/usr/local/lib/python3.6/dist-packages/django/db/backends/utils.py", line 85, in _execute
    return self.cursor.execute(sql, params)
django.db.utils.ProgrammingError: relation "authapp_shopuser" does not exist
LINE 1: ...shopuser"."avatar", "authapp_shopuser"."age" FROM "authapp_s...
                                                             ^

ERROR      2018-07-29 16:58:46,638 Internal Server Error: /auth/register/
Traceback (most recent call last):
  File "/usr/local/lib/python3.6/dist-packages/django/db/backends/utils.py", line 85, in _execute
    return self.cursor.execute(sql, params)
psycopg2.ProgrammingError: relation "authapp_shopuser" does not exist
LINE 1: SELECT (1) AS "a" FROM "authapp_shopuser" WHERE "authapp_sho...
                               ^


The above exception was the direct cause of the following exception:

Traceback (most recent call last):
  File "/usr/local/lib/python3.6/dist-packages/django/core/handlers/exception.py", line 35, in inner
    response = get_response(request)
  File "/usr/local/lib/python3.6/dist-packages/django/core/handlers/base.py", line 128, in _get_response
    response = self.process_exception_by_middleware(e, request)
  File "/usr/local/lib/python3.6/dist-packages/django/core/handlers/base.py", line 126, in _get_response
    response = wrapped_callback(request, *callback_args, **callback_kwargs)
  File "/home/oleg/git/authapp/views.py", line 46, in register
    if register_form.is_valid():
  File "/usr/local/lib/python3.6/dist-packages/django/forms/forms.py", line 179, in is_valid
    return self.is_bound and not self.errors
  File "/usr/local/lib/python3.6/dist-packages/django/forms/forms.py", line 174, in errors
    self.full_clean()
  File "/usr/local/lib/python3.6/dist-packages/django/forms/forms.py", line 378, in full_clean
    self._post_clean()
  File "/usr/local/lib/python3.6/dist-packages/django/contrib/auth/forms.py", line 106, in _post_clean
    super()._post_clean()
  File "/usr/local/lib/python3.6/dist-packages/django/forms/models.py", line 407, in _post_clean
    self.validate_unique()
  File "/usr/local/lib/python3.6/dist-packages/django/forms/models.py", line 416, in validate_unique
    self.instance.validate_unique(exclude=exclude)
  File "/usr/local/lib/python3.6/dist-packages/django/db/models/base.py", line 951, in validate_unique
    errors = self._perform_unique_checks(unique_checks)
  File "/usr/local/lib/python3.6/dist-packages/django/db/models/base.py", line 1047, in _perform_unique_checks
    if qs.exists():
  File "/usr/local/lib/python3.6/dist-packages/django/db/models/query.py", line 715, in exists
    return self.query.has_results(using=self.db)
  File "/usr/local/lib/python3.6/dist-packages/django/db/models/sql/query.py", line 509, in has_results
    return compiler.has_results()
  File "/usr/local/lib/python3.6/dist-packages/django/db/models/sql/compiler.py", line 1035, in has_results
    return bool(self.execute_sql(SINGLE))
  File "/usr/local/lib/python3.6/dist-packages/django/db/models/sql/compiler.py", line 1066, in execute_sql
    cursor.execute(sql, params)
  File "/usr/local/lib/python3.6/dist-packages/django/db/backends/utils.py", line 100, in execute
    return super().execute(sql, params)
  File "/usr/local/lib/python3.6/dist-packages/django/db/backends/utils.py", line 68, in execute
    return self._execute_with_wrappers(sql, params, many=False, executor=self._execute)
  File "/usr/local/lib/python3.6/dist-packages/django/db/backends/utils.py", line 77, in _execute_with_wrappers
    return executor(sql, params, many, context)
  File "/usr/local/lib/python3.6/dist-packages/django/db/backends/utils.py", line 85, in _execute
    return self.cursor.execute(sql, params)
  File "/usr/local/lib/python3.6/dist-packages/django/db/utils.py", line 89, in __exit__
    raise dj_exc_value.with_traceback(traceback) from exc_value
  File "/usr/local/lib/python3.6/dist-packages/django/db/backends/utils.py", line 85, in _execute
    return self.cursor.execute(sql, params)
django.db.utils.ProgrammingError: relation "authapp_shopuser" does not exist
LINE 1: SELECT (1) AS "a" FROM "authapp_shopuser" WHERE "authapp_sho...
                               ^

ERROR      2018-07-29 17:15:29,544 Internal Server Error: /category/
Traceback (most recent call last):
  File "/usr/local/lib/python3.6/dist-packages/django/core/handlers/exception.py", line 35, in inner
    response = get_response(request)
  File "/usr/local/lib/python3.6/dist-packages/django/core/handlers/base.py", line 128, in _get_response
    response = self.process_exception_by_middleware(e, request)
  File "/usr/local/lib/python3.6/dist-packages/django/core/handlers/base.py", line 126, in _get_response
    response = wrapped_callback(request, *callback_args, **callback_kwargs)
  File "/home/oleg/git/mainapp/views.py", line 36, in products
    links_menu = ProductCategory.objects.filter(is_active=True)
  File "/usr/local/lib/python3.6/dist-packages/django/db/models/manager.py", line 82, in manager_method
    return getattr(self.get_queryset(), name)(*args, **kwargs)
  File "/usr/local/lib/python3.6/dist-packages/django/db/models/query.py", line 836, in filter
    return self._filter_or_exclude(False, *args, **kwargs)
  File "/usr/local/lib/python3.6/dist-packages/django/db/models/query.py", line 854, in _filter_or_exclude
    clone.query.add_q(Q(*args, **kwargs))
  File "/usr/local/lib/python3.6/dist-packages/django/db/models/sql/query.py", line 1253, in add_q
    clause, _ = self._add_q(q_object, self.used_aliases)
  File "/usr/local/lib/python3.6/dist-packages/django/db/models/sql/query.py", line 1277, in _add_q
    split_subq=split_subq,
  File "/usr/local/lib/python3.6/dist-packages/django/db/models/sql/query.py", line 1153, in build_filter
    lookups, parts, reffed_expression = self.solve_lookup_type(arg)
  File "/usr/local/lib/python3.6/dist-packages/django/db/models/sql/query.py", line 1015, in solve_lookup_type
    _, field, _, lookup_parts = self.names_to_path(lookup_splitted, self.get_meta())
  File "/usr/local/lib/python3.6/dist-packages/django/db/models/sql/query.py", line 1379, in names_to_path
    "Choices are: %s" % (name, ", ".join(available)))
django.core.exceptions.FieldError: Cannot resolve keyword 'is_active' into field. Choices are: description, id, name, product
ERROR      2018-07-29 17:16:54,073 Internal Server Error: /admin/login/
Traceback (most recent call last):
  File "/usr/local/lib/python3.6/dist-packages/django/db/backends/utils.py", line 85, in _execute
    return self.cursor.execute(sql, params)
psycopg2.ProgrammingError: relation "authapp_shopuser" does not exist
LINE 1: ...shopuser"."avatar", "authapp_shopuser"."age" FROM "authapp_s...
                                                             ^


The above exception was the direct cause of the following exception:

Traceback (most recent call last):
  File "/usr/local/lib/python3.6/dist-packages/django/core/handlers/exception.py", line 35, in inner
    response = get_response(request)
  File "/usr/local/lib/python3.6/dist-packages/django/core/handlers/base.py", line 128, in _get_response
    response = self.process_exception_by_middleware(e, request)
  File "/usr/local/lib/python3.6/dist-packages/django/core/handlers/base.py", line 126, in _get_response
    response = wrapped_callback(request, *callback_args, **callback_kwargs)
  File "/usr/local/lib/python3.6/dist-packages/django/views/decorators/cache.py", line 44, in _wrapped_view_func
    response = view_func(request, *args, **kwargs)
  File "/usr/local/lib/python3.6/dist-packages/django/contrib/admin/sites.py", line 398, in login
    return LoginView.as_view(**defaults)(request)
  File "/usr/local/lib/python3.6/dist-packages/django/views/generic/base.py", line 69, in view
    return self.dispatch(request, *args, **kwargs)
  File "/usr/local/lib/python3.6/dist-packages/django/utils/decorators.py", line 62, in _wrapper
    return bound_func(*args, **kwargs)
  File "/usr/local/lib/python3.6/dist-packages/django/views/decorators/debug.py", line 76, in sensitive_post_parameters_wrapper
    return view(request, *args, **kwargs)
  File "/usr/local/lib/python3.6/dist-packages/django/utils/decorators.py", line 58, in bound_func
    return func.__get__(self, type(self))(*args2, **kwargs2)
  File "/usr/local/lib/python3.6/dist-packages/django/utils/decorators.py", line 62, in _wrapper
    return bound_func(*args, **kwargs)
  File "/usr/local/lib/python3.6/dist-packages/django/utils/decorators.py", line 142, in _wrapped_view
    response = view_func(request, *args, **kwargs)
  File "/usr/local/lib/python3.6/dist-packages/django/utils/decorators.py", line 58, in bound_func
    return func.__get__(self, type(self))(*args2, **kwargs2)
  File "/usr/local/lib/python3.6/dist-packages/django/utils/decorators.py", line 62, in _wrapper
    return bound_func(*args, **kwargs)
  File "/usr/local/lib/python3.6/dist-packages/django/views/decorators/cache.py", line 44, in _wrapped_view_func
    response = view_func(request, *args, **kwargs)
  File "/usr/local/lib/python3.6/dist-packages/django/utils/decorators.py", line 58, in bound_func
    return func.__get__(self, type(self))(*args2, **kwargs2)
  File "/usr/local/lib/python3.6/dist-packages/django/contrib/auth/views.py", line 66, in dispatch
    return super().dispatch(request, *args, **kwargs)
  File "/usr/local/lib/python3.6/dist-packages/django/views/generic/base.py", line 89, in dispatch
    return handler(request, *args, **kwargs)
  File "/usr/local/lib/python3.6/dist-packages/django/views/generic/edit.py", line 141, in post
    if form.is_valid():
  File "/usr/local/lib/python3.6/dist-packages/django/forms/forms.py", line 179, in is_valid
    return self.is_bound and not self.errors
  File "/usr/local/lib/python3.6/dist-packages/django/forms/forms.py", line 174, in errors
    self.full_clean()
  File "/usr/local/lib/python3.6/dist-packages/django/forms/forms.py", line 377, in full_clean
    self._clean_form()
  File "/usr/local/lib/python3.6/dist-packages/django/forms/forms.py", line 404, in _clean_form
    cleaned_data = self.clean()
  File "/usr/local/lib/python3.6/dist-packages/django/contrib/auth/forms.py", line 195, in clean
    self.user_cache = authenticate(self.request, username=username, password=password)
  File "/usr/local/lib/python3.6/dist-packages/django/contrib/auth/__init__.py", line 70, in authenticate
    user = _authenticate_with_backend(backend, backend_path, request, credentials)
  File "/usr/local/lib/python3.6/dist-packages/django/contrib/auth/__init__.py", line 116, in _authenticate_with_backend
    return backend.authenticate(*args, **credentials)
  File "/usr/local/lib/python3.6/dist-packages/django/contrib/auth/backends.py", line 16, in authenticate
    user = UserModel._default_manager.get_by_natural_key(username)
  File "/usr/local/lib/python3.6/dist-packages/django/contrib/auth/base_user.py", line 44, in get_by_natural_key
    return self.get(**{self.model.USERNAME_FIELD: username})
  File "/usr/local/lib/python3.6/dist-packages/django/db/models/manager.py", line 82, in manager_method
    return getattr(self.get_queryset(), name)(*args, **kwargs)
  File "/usr/local/lib/python3.6/dist-packages/django/db/models/query.py", line 397, in get
    num = len(clone)
  File "/usr/local/lib/python3.6/dist-packages/django/db/models/query.py", line 254, in __len__
    self._fetch_all()
  File "/usr/local/lib/python3.6/dist-packages/django/db/models/query.py", line 1179, in _fetch_all
    self._result_cache = list(self._iterable_class(self))
  File "/usr/local/lib/python3.6/dist-packages/django/db/models/query.py", line 53, in __iter__
    results = compiler.execute_sql(chunked_fetch=self.chunked_fetch, chunk_size=self.chunk_size)
  File "/usr/local/lib/python3.6/dist-packages/django/db/models/sql/compiler.py", line 1066, in execute_sql
    cursor.execute(sql, params)
  File "/usr/local/lib/python3.6/dist-packages/django/db/backends/utils.py", line 100, in execute
    return super().execute(sql, params)
  File "/usr/local/lib/python3.6/dist-packages/django/db/backends/utils.py", line 68, in execute
    return self._execute_with_wrappers(sql, params, many=False, executor=self._execute)
  File "/usr/local/lib/python3.6/dist-packages/django/db/backends/utils.py", line 77, in _execute_with_wrappers
    return executor(sql, params, many, context)
  File "/usr/local/lib/python3.6/dist-packages/django/db/backends/utils.py", line 85, in _execute
    return self.cursor.execute(sql, params)
  File "/usr/local/lib/python3.6/dist-packages/django/db/utils.py", line 89, in __exit__
    raise dj_exc_value.with_traceback(traceback) from exc_value
  File "/usr/local/lib/python3.6/dist-packages/django/db/backends/utils.py", line 85, in _execute
    return self.cursor.execute(sql, params)
django.db.utils.ProgrammingError: relation "authapp_shopuser" does not exist
LINE 1: ...shopuser"."avatar", "authapp_shopuser"."age" FROM "authapp_s...
                                                             ^

ERROR      2018-07-29 17:23:58,030 Internal Server Error: /admin/login/
Traceback (most recent call last):
  File "/usr/local/lib/python3.6/dist-packages/django/db/backends/utils.py", line 85, in _execute
    return self.cursor.execute(sql, params)
psycopg2.ProgrammingError: relation "authapp_shopuser" does not exist
LINE 1: ...shopuser"."avatar", "authapp_shopuser"."age" FROM "authapp_s...
                                                             ^


The above exception was the direct cause of the following exception:

Traceback (most recent call last):
  File "/usr/local/lib/python3.6/dist-packages/django/core/handlers/exception.py", line 35, in inner
    response = get_response(request)
  File "/usr/local/lib/python3.6/dist-packages/django/core/handlers/base.py", line 128, in _get_response
    response = self.process_exception_by_middleware(e, request)
  File "/usr/local/lib/python3.6/dist-packages/django/core/handlers/base.py", line 126, in _get_response
    response = wrapped_callback(request, *callback_args, **callback_kwargs)
  File "/usr/local/lib/python3.6/dist-packages/django/views/decorators/cache.py", line 44, in _wrapped_view_func
    response = view_func(request, *args, **kwargs)
  File "/usr/local/lib/python3.6/dist-packages/django/contrib/admin/sites.py", line 398, in login
    return LoginView.as_view(**defaults)(request)
  File "/usr/local/lib/python3.6/dist-packages/django/views/generic/base.py", line 69, in view
    return self.dispatch(request, *args, **kwargs)
  File "/usr/local/lib/python3.6/dist-packages/django/utils/decorators.py", line 62, in _wrapper
    return bound_func(*args, **kwargs)
  File "/usr/local/lib/python3.6/dist-packages/django/views/decorators/debug.py", line 76, in sensitive_post_parameters_wrapper
    return view(request, *args, **kwargs)
  File "/usr/local/lib/python3.6/dist-packages/django/utils/decorators.py", line 58, in bound_func
    return func.__get__(self, type(self))(*args2, **kwargs2)
  File "/usr/local/lib/python3.6/dist-packages/django/utils/decorators.py", line 62, in _wrapper
    return bound_func(*args, **kwargs)
  File "/usr/local/lib/python3.6/dist-packages/django/utils/decorators.py", line 142, in _wrapped_view
    response = view_func(request, *args, **kwargs)
  File "/usr/local/lib/python3.6/dist-packages/django/utils/decorators.py", line 58, in bound_func
    return func.__get__(self, type(self))(*args2, **kwargs2)
  File "/usr/local/lib/python3.6/dist-packages/django/utils/decorators.py", line 62, in _wrapper
    return bound_func(*args, **kwargs)
  File "/usr/local/lib/python3.6/dist-packages/django/views/decorators/cache.py", line 44, in _wrapped_view_func
    response = view_func(request, *args, **kwargs)
  File "/usr/local/lib/python3.6/dist-packages/django/utils/decorators.py", line 58, in bound_func
    return func.__get__(self, type(self))(*args2, **kwargs2)
  File "/usr/local/lib/python3.6/dist-packages/django/contrib/auth/views.py", line 66, in dispatch
    return super().dispatch(request, *args, **kwargs)
  File "/usr/local/lib/python3.6/dist-packages/django/views/generic/base.py", line 89, in dispatch
    return handler(request, *args, **kwargs)
  File "/usr/local/lib/python3.6/dist-packages/django/views/generic/edit.py", line 141, in post
    if form.is_valid():
  File "/usr/local/lib/python3.6/dist-packages/django/forms/forms.py", line 179, in is_valid
    return self.is_bound and not self.errors
  File "/usr/local/lib/python3.6/dist-packages/django/forms/forms.py", line 174, in errors
    self.full_clean()
  File "/usr/local/lib/python3.6/dist-packages/django/forms/forms.py", line 377, in full_clean
    self._clean_form()
  File "/usr/local/lib/python3.6/dist-packages/django/forms/forms.py", line 404, in _clean_form
    cleaned_data = self.clean()
  File "/usr/local/lib/python3.6/dist-packages/django/contrib/auth/forms.py", line 195, in clean
    self.user_cache = authenticate(self.request, username=username, password=password)
  File "/usr/local/lib/python3.6/dist-packages/django/contrib/auth/__init__.py", line 70, in authenticate
    user = _authenticate_with_backend(backend, backend_path, request, credentials)
  File "/usr/local/lib/python3.6/dist-packages/django/contrib/auth/__init__.py", line 116, in _authenticate_with_backend
    return backend.authenticate(*args, **credentials)
  File "/usr/local/lib/python3.6/dist-packages/django/contrib/auth/backends.py", line 16, in authenticate
    user = UserModel._default_manager.get_by_natural_key(username)
  File "/usr/local/lib/python3.6/dist-packages/django/contrib/auth/base_user.py", line 44, in get_by_natural_key
    return self.get(**{self.model.USERNAME_FIELD: username})
  File "/usr/local/lib/python3.6/dist-packages/django/db/models/manager.py", line 82, in manager_method
    return getattr(self.get_queryset(), name)(*args, **kwargs)
  File "/usr/local/lib/python3.6/dist-packages/django/db/models/query.py", line 397, in get
    num = len(clone)
  File "/usr/local/lib/python3.6/dist-packages/django/db/models/query.py", line 254, in __len__
    self._fetch_all()
  File "/usr/local/lib/python3.6/dist-packages/django/db/models/query.py", line 1179, in _fetch_all
    self._result_cache = list(self._iterable_class(self))
  File "/usr/local/lib/python3.6/dist-packages/django/db/models/query.py", line 53, in __iter__
    results = compiler.execute_sql(chunked_fetch=self.chunked_fetch, chunk_size=self.chunk_size)
  File "/usr/local/lib/python3.6/dist-packages/django/db/models/sql/compiler.py", line 1066, in execute_sql
    cursor.execute(sql, params)
  File "/usr/local/lib/python3.6/dist-packages/django/db/backends/utils.py", line 100, in execute
    return super().execute(sql, params)
  File "/usr/local/lib/python3.6/dist-packages/django/db/backends/utils.py", line 68, in execute
    return self._execute_with_wrappers(sql, params, many=False, executor=self._execute)
  File "/usr/local/lib/python3.6/dist-packages/django/db/backends/utils.py", line 77, in _execute_with_wrappers
    return executor(sql, params, many, context)
  File "/usr/local/lib/python3.6/dist-packages/django/db/backends/utils.py", line 85, in _execute
    return self.cursor.execute(sql, params)
  File "/usr/local/lib/python3.6/dist-packages/django/db/utils.py", line 89, in __exit__
    raise dj_exc_value.with_traceback(traceback) from exc_value
  File "/usr/local/lib/python3.6/dist-packages/django/db/backends/utils.py", line 85, in _execute
    return self.cursor.execute(sql, params)
django.db.utils.ProgrammingError: relation "authapp_shopuser" does not exist
LINE 1: ...shopuser"."avatar", "authapp_shopuser"."age" FROM "authapp_s...
                                                             ^

WARNING    2018-07-29 18:45:33,810 Not Found: /favicon.ico
ERROR      2018-07-29 18:46:56,546 Internal Server Error: /
Traceback (most recent call last):
  File "/usr/local/lib/python3.6/dist-packages/django/urls/base.py", line 74, in reverse
    extra, resolver = resolver.namespace_dict[ns]
KeyError: 'auth'

During handling of the above exception, another exception occurred:

Traceback (most recent call last):
  File "/usr/local/lib/python3.6/dist-packages/django/core/handlers/exception.py", line 35, in inner
    response = get_response(request)
  File "/usr/local/lib/python3.6/dist-packages/django/core/handlers/base.py", line 128, in _get_response
    response = self.process_exception_by_middleware(e, request)
  File "/usr/local/lib/python3.6/dist-packages/django/core/handlers/base.py", line 126, in _get_response
    response = wrapped_callback(request, *callback_args, **callback_kwargs)
  File "/home/oleg/git/mainapp/views.py", line 24, in main
    return render(request, 'mainapp/base.html', content)
  File "/usr/local/lib/python3.6/dist-packages/django/shortcuts.py", line 36, in render
    content = loader.render_to_string(template_name, context, request, using=using)
  File "/usr/local/lib/python3.6/dist-packages/django/template/loader.py", line 62, in render_to_string
    return template.render(context, request)
  File "/usr/local/lib/python3.6/dist-packages/django/template/backends/django.py", line 61, in render
    return self.template.render(context)
  File "/usr/local/lib/python3.6/dist-packages/django/template/base.py", line 175, in render
    return self._render(context)
  File "/usr/local/lib/python3.6/dist-packages/django/template/base.py", line 167, in _render
    return self.nodelist.render(context)
  File "/usr/local/lib/python3.6/dist-packages/django/template/base.py", line 943, in render
    bit = node.render_annotated(context)
  File "/usr/local/lib/python3.6/dist-packages/django/template/base.py", line 910, in render_annotated
    return self.render(context)
  File "/usr/local/lib/python3.6/dist-packages/django/template/loader_tags.py", line 194, in render
    return template.render(context)
  File "/usr/local/lib/python3.6/dist-packages/django/template/base.py", line 177, in render
    return self._render(context)
  File "/usr/local/lib/python3.6/dist-packages/django/template/base.py", line 167, in _render
    return self.nodelist.render(context)
  File "/usr/local/lib/python3.6/dist-packages/django/template/base.py", line 943, in render
    bit = node.render_annotated(context)
  File "/usr/local/lib/python3.6/dist-packages/django/template/base.py", line 910, in render_annotated
    return self.render(context)
  File "/usr/local/lib/python3.6/dist-packages/django/template/defaulttags.py", line 314, in render
    return nodelist.render(context)
  File "/usr/local/lib/python3.6/dist-packages/django/template/base.py", line 943, in render
    bit = node.render_annotated(context)
  File "/usr/local/lib/python3.6/dist-packages/django/template/base.py", line 910, in render_annotated
    return self.render(context)
  File "/usr/local/lib/python3.6/dist-packages/django/template/defaulttags.py", line 447, in render
    url = reverse(view_name, args=args, kwargs=kwargs, current_app=current_app)
  File "/usr/local/lib/python3.6/dist-packages/django/urls/base.py", line 84, in reverse
    raise NoReverseMatch("%s is not a registered namespace" % key)
django.urls.exceptions.NoReverseMatch: 'auth' is not a registered namespace
ERROR      2018-07-30 14:58:36,310 Internal Server Error: /auth/login
Traceback (most recent call last):
  File "/home/oleg/.local/lib/python3.6/site-packages/django/core/handlers/exception.py", line 35, in inner
    response = get_response(request)
  File "/home/oleg/.local/lib/python3.6/site-packages/django/utils/deprecation.py", line 93, in __call__
    response = self.process_request(request)
  File "/home/oleg/.local/lib/python3.6/site-packages/django/middleware/common.py", line 60, in process_request
    if self.should_redirect_with_slash(request):
  File "/home/oleg/.local/lib/python3.6/site-packages/django/middleware/common.py", line 78, in should_redirect_with_slash
    not is_valid_path(request.path_info, urlconf) and
  File "/home/oleg/.local/lib/python3.6/site-packages/django/urls/base.py", line 157, in is_valid_path
    resolve(path, urlconf)
  File "/home/oleg/.local/lib/python3.6/site-packages/django/urls/base.py", line 24, in resolve
    return get_resolver(urlconf).resolve(path)
  File "/home/oleg/.local/lib/python3.6/site-packages/django/urls/resolvers.py", line 498, in resolve
    for pattern in self.url_patterns:
  File "/home/oleg/.local/lib/python3.6/site-packages/django/utils/functional.py", line 36, in __get__
    res = instance.__dict__[self.name] = self.func(instance)
  File "/home/oleg/.local/lib/python3.6/site-packages/django/urls/resolvers.py", line 540, in url_patterns
    patterns = getattr(self.urlconf_module, "urlpatterns", self.urlconf_module)
  File "/home/oleg/.local/lib/python3.6/site-packages/django/utils/functional.py", line 36, in __get__
    res = instance.__dict__[self.name] = self.func(instance)
  File "/home/oleg/.local/lib/python3.6/site-packages/django/urls/resolvers.py", line 533, in urlconf_module
    return import_module(self.urlconf_name)
  File "/usr/lib/python3.6/importlib/__init__.py", line 126, in import_module
    return _bootstrap._gcd_import(name[level:], package, level)
  File "<frozen importlib._bootstrap>", line 994, in _gcd_import
  File "<frozen importlib._bootstrap>", line 971, in _find_and_load
  File "<frozen importlib._bootstrap>", line 955, in _find_and_load_unlocked
  File "<frozen importlib._bootstrap>", line 665, in _load_unlocked
  File "<frozen importlib._bootstrap_external>", line 678, in exec_module
  File "<frozen importlib._bootstrap>", line 219, in _call_with_frames_removed
  File "/home/oleg/YandexDisk/Python_Lessons/Django/myproject/myproject/urls.py", line 28, in <module>
    path('auth/', include('authapp.urls', namespace='auth')),
  File "/home/oleg/.local/lib/python3.6/site-packages/django/urls/conf.py", line 34, in include
    urlconf_module = import_module(urlconf_module)
  File "/usr/lib/python3.6/importlib/__init__.py", line 126, in import_module
    return _bootstrap._gcd_import(name[level:], package, level)
  File "<frozen importlib._bootstrap>", line 994, in _gcd_import
  File "<frozen importlib._bootstrap>", line 971, in _find_and_load
  File "<frozen importlib._bootstrap>", line 955, in _find_and_load_unlocked
  File "<frozen importlib._bootstrap>", line 665, in _load_unlocked
  File "<frozen importlib._bootstrap_external>", line 678, in exec_module
  File "<frozen importlib._bootstrap>", line 219, in _call_with_frames_removed
  File "/home/oleg/YandexDisk/Python_Lessons/Django/myproject/authapp/urls.py", line 1, in <module>
    import authapp.views as authapp
  File "/home/oleg/YandexDisk/Python_Lessons/Django/myproject/authapp/views.py", line 5, in <module>
    from authapp.forms import ShopUserRegisterForm
ImportError: cannot import name 'ShopUserRegisterForm'
ERROR      2018-07-30 14:58:38,696 Internal Server Error: /favicon.ico
Traceback (most recent call last):
  File "/home/oleg/.local/lib/python3.6/site-packages/django/core/handlers/exception.py", line 35, in inner
    response = get_response(request)
  File "/home/oleg/.local/lib/python3.6/site-packages/django/utils/deprecation.py", line 93, in __call__
    response = self.process_request(request)
  File "/home/oleg/.local/lib/python3.6/site-packages/django/middleware/common.py", line 60, in process_request
    if self.should_redirect_with_slash(request):
  File "/home/oleg/.local/lib/python3.6/site-packages/django/middleware/common.py", line 78, in should_redirect_with_slash
    not is_valid_path(request.path_info, urlconf) and
  File "/home/oleg/.local/lib/python3.6/site-packages/django/urls/base.py", line 157, in is_valid_path
    resolve(path, urlconf)
  File "/home/oleg/.local/lib/python3.6/site-packages/django/urls/base.py", line 24, in resolve
    return get_resolver(urlconf).resolve(path)
  File "/home/oleg/.local/lib/python3.6/site-packages/django/urls/resolvers.py", line 498, in resolve
    for pattern in self.url_patterns:
  File "/home/oleg/.local/lib/python3.6/site-packages/django/utils/functional.py", line 36, in __get__
    res = instance.__dict__[self.name] = self.func(instance)
  File "/home/oleg/.local/lib/python3.6/site-packages/django/urls/resolvers.py", line 540, in url_patterns
    patterns = getattr(self.urlconf_module, "urlpatterns", self.urlconf_module)
  File "/home/oleg/.local/lib/python3.6/site-packages/django/utils/functional.py", line 36, in __get__
    res = instance.__dict__[self.name] = self.func(instance)
  File "/home/oleg/.local/lib/python3.6/site-packages/django/urls/resolvers.py", line 533, in urlconf_module
    return import_module(self.urlconf_name)
  File "/usr/lib/python3.6/importlib/__init__.py", line 126, in import_module
    return _bootstrap._gcd_import(name[level:], package, level)
  File "<frozen importlib._bootstrap>", line 994, in _gcd_import
  File "<frozen importlib._bootstrap>", line 971, in _find_and_load
  File "<frozen importlib._bootstrap>", line 955, in _find_and_load_unlocked
  File "<frozen importlib._bootstrap>", line 665, in _load_unlocked
  File "<frozen importlib._bootstrap_external>", line 678, in exec_module
  File "<frozen importlib._bootstrap>", line 219, in _call_with_frames_removed
  File "/home/oleg/YandexDisk/Python_Lessons/Django/myproject/myproject/urls.py", line 28, in <module>
    path('auth/', include('authapp.urls', namespace='auth')),
  File "/home/oleg/.local/lib/python3.6/site-packages/django/urls/conf.py", line 34, in include
    urlconf_module = import_module(urlconf_module)
  File "/usr/lib/python3.6/importlib/__init__.py", line 126, in import_module
    return _bootstrap._gcd_import(name[level:], package, level)
  File "<frozen importlib._bootstrap>", line 994, in _gcd_import
  File "<frozen importlib._bootstrap>", line 971, in _find_and_load
  File "<frozen importlib._bootstrap>", line 955, in _find_and_load_unlocked
  File "<frozen importlib._bootstrap>", line 665, in _load_unlocked
  File "<frozen importlib._bootstrap_external>", line 678, in exec_module
  File "<frozen importlib._bootstrap>", line 219, in _call_with_frames_removed
  File "/home/oleg/YandexDisk/Python_Lessons/Django/myproject/authapp/urls.py", line 1, in <module>
    import authapp.views as authapp
  File "/home/oleg/YandexDisk/Python_Lessons/Django/myproject/authapp/views.py", line 5, in <module>
    from authapp.forms import ShopUserRegisterForm
ImportError: cannot import name 'ShopUserRegisterForm'
ERROR      2018-07-30 15:01:06,248 Internal Server Error: /auth/login
Traceback (most recent call last):
  File "/home/oleg/.local/lib/python3.6/site-packages/django/core/handlers/exception.py", line 35, in inner
    response = get_response(request)
  File "/home/oleg/.local/lib/python3.6/site-packages/django/utils/deprecation.py", line 93, in __call__
    response = self.process_request(request)
  File "/home/oleg/.local/lib/python3.6/site-packages/django/middleware/common.py", line 60, in process_request
    if self.should_redirect_with_slash(request):
  File "/home/oleg/.local/lib/python3.6/site-packages/django/middleware/common.py", line 78, in should_redirect_with_slash
    not is_valid_path(request.path_info, urlconf) and
  File "/home/oleg/.local/lib/python3.6/site-packages/django/urls/base.py", line 157, in is_valid_path
    resolve(path, urlconf)
  File "/home/oleg/.local/lib/python3.6/site-packages/django/urls/base.py", line 24, in resolve
    return get_resolver(urlconf).resolve(path)
  File "/home/oleg/.local/lib/python3.6/site-packages/django/urls/resolvers.py", line 498, in resolve
    for pattern in self.url_patterns:
  File "/home/oleg/.local/lib/python3.6/site-packages/django/utils/functional.py", line 36, in __get__
    res = instance.__dict__[self.name] = self.func(instance)
  File "/home/oleg/.local/lib/python3.6/site-packages/django/urls/resolvers.py", line 540, in url_patterns
    patterns = getattr(self.urlconf_module, "urlpatterns", self.urlconf_module)
  File "/home/oleg/.local/lib/python3.6/site-packages/django/utils/functional.py", line 36, in __get__
    res = instance.__dict__[self.name] = self.func(instance)
  File "/home/oleg/.local/lib/python3.6/site-packages/django/urls/resolvers.py", line 533, in urlconf_module
    return import_module(self.urlconf_name)
  File "/usr/lib/python3.6/importlib/__init__.py", line 126, in import_module
    return _bootstrap._gcd_import(name[level:], package, level)
  File "<frozen importlib._bootstrap>", line 994, in _gcd_import
  File "<frozen importlib._bootstrap>", line 971, in _find_and_load
  File "<frozen importlib._bootstrap>", line 955, in _find_and_load_unlocked
  File "<frozen importlib._bootstrap>", line 665, in _load_unlocked
  File "<frozen importlib._bootstrap_external>", line 678, in exec_module
  File "<frozen importlib._bootstrap>", line 219, in _call_with_frames_removed
  File "/home/oleg/YandexDisk/Python_Lessons/Django/myproject/myproject/urls.py", line 28, in <module>
    path('auth/', include('authapp.urls', namespace='auth')),
  File "/home/oleg/.local/lib/python3.6/site-packages/django/urls/conf.py", line 34, in include
    urlconf_module = import_module(urlconf_module)
  File "/usr/lib/python3.6/importlib/__init__.py", line 126, in import_module
    return _bootstrap._gcd_import(name[level:], package, level)
  File "<frozen importlib._bootstrap>", line 994, in _gcd_import
  File "<frozen importlib._bootstrap>", line 971, in _find_and_load
  File "<frozen importlib._bootstrap>", line 955, in _find_and_load_unlocked
  File "<frozen importlib._bootstrap>", line 665, in _load_unlocked
  File "<frozen importlib._bootstrap_external>", line 678, in exec_module
  File "<frozen importlib._bootstrap>", line 219, in _call_with_frames_removed
  File "/home/oleg/YandexDisk/Python_Lessons/Django/myproject/authapp/urls.py", line 1, in <module>
    import authapp.views as authapp
  File "/home/oleg/YandexDisk/Python_Lessons/Django/myproject/authapp/views.py", line 5, in <module>
    from authapp.forms import ShopUserRegisterForm
ImportError: cannot import name 'ShopUserRegisterForm'
ERROR      2018-07-30 15:01:06,774 Internal Server Error: /favicon.ico
Traceback (most recent call last):
  File "/home/oleg/.local/lib/python3.6/site-packages/django/core/handlers/exception.py", line 35, in inner
    response = get_response(request)
  File "/home/oleg/.local/lib/python3.6/site-packages/django/utils/deprecation.py", line 93, in __call__
    response = self.process_request(request)
  File "/home/oleg/.local/lib/python3.6/site-packages/django/middleware/common.py", line 60, in process_request
    if self.should_redirect_with_slash(request):
  File "/home/oleg/.local/lib/python3.6/site-packages/django/middleware/common.py", line 78, in should_redirect_with_slash
    not is_valid_path(request.path_info, urlconf) and
  File "/home/oleg/.local/lib/python3.6/site-packages/django/urls/base.py", line 157, in is_valid_path
    resolve(path, urlconf)
  File "/home/oleg/.local/lib/python3.6/site-packages/django/urls/base.py", line 24, in resolve
    return get_resolver(urlconf).resolve(path)
  File "/home/oleg/.local/lib/python3.6/site-packages/django/urls/resolvers.py", line 498, in resolve
    for pattern in self.url_patterns:
  File "/home/oleg/.local/lib/python3.6/site-packages/django/utils/functional.py", line 36, in __get__
    res = instance.__dict__[self.name] = self.func(instance)
  File "/home/oleg/.local/lib/python3.6/site-packages/django/urls/resolvers.py", line 540, in url_patterns
    patterns = getattr(self.urlconf_module, "urlpatterns", self.urlconf_module)
  File "/home/oleg/.local/lib/python3.6/site-packages/django/utils/functional.py", line 36, in __get__
    res = instance.__dict__[self.name] = self.func(instance)
  File "/home/oleg/.local/lib/python3.6/site-packages/django/urls/resolvers.py", line 533, in urlconf_module
    return import_module(self.urlconf_name)
  File "/usr/lib/python3.6/importlib/__init__.py", line 126, in import_module
    return _bootstrap._gcd_import(name[level:], package, level)
  File "<frozen importlib._bootstrap>", line 994, in _gcd_import
  File "<frozen importlib._bootstrap>", line 971, in _find_and_load
  File "<frozen importlib._bootstrap>", line 955, in _find_and_load_unlocked
  File "<frozen importlib._bootstrap>", line 665, in _load_unlocked
  File "<frozen importlib._bootstrap_external>", line 678, in exec_module
  File "<frozen importlib._bootstrap>", line 219, in _call_with_frames_removed
  File "/home/oleg/YandexDisk/Python_Lessons/Django/myproject/myproject/urls.py", line 28, in <module>
    path('auth/', include('authapp.urls', namespace='auth')),
  File "/home/oleg/.local/lib/python3.6/site-packages/django/urls/conf.py", line 34, in include
    urlconf_module = import_module(urlconf_module)
  File "/usr/lib/python3.6/importlib/__init__.py", line 126, in import_module
    return _bootstrap._gcd_import(name[level:], package, level)
  File "<frozen importlib._bootstrap>", line 994, in _gcd_import
  File "<frozen importlib._bootstrap>", line 971, in _find_and_load
  File "<frozen importlib._bootstrap>", line 955, in _find_and_load_unlocked
  File "<frozen importlib._bootstrap>", line 665, in _load_unlocked
  File "<frozen importlib._bootstrap_external>", line 678, in exec_module
  File "<frozen importlib._bootstrap>", line 219, in _call_with_frames_removed
  File "/home/oleg/YandexDisk/Python_Lessons/Django/myproject/authapp/urls.py", line 1, in <module>
    import authapp.views as authapp
  File "/home/oleg/YandexDisk/Python_Lessons/Django/myproject/authapp/views.py", line 5, in <module>
    from authapp.forms import ShopUserRegisterForm
ImportError: cannot import name 'ShopUserRegisterForm'
ERROR      2018-07-30 15:05:06,812 Internal Server Error: /auth/login
Traceback (most recent call last):
  File "/home/oleg/.local/lib/python3.6/site-packages/django/core/handlers/exception.py", line 35, in inner
    response = get_response(request)
  File "/home/oleg/.local/lib/python3.6/site-packages/django/utils/deprecation.py", line 93, in __call__
    response = self.process_request(request)
  File "/home/oleg/.local/lib/python3.6/site-packages/django/middleware/common.py", line 60, in process_request
    if self.should_redirect_with_slash(request):
  File "/home/oleg/.local/lib/python3.6/site-packages/django/middleware/common.py", line 78, in should_redirect_with_slash
    not is_valid_path(request.path_info, urlconf) and
  File "/home/oleg/.local/lib/python3.6/site-packages/django/urls/base.py", line 157, in is_valid_path
    resolve(path, urlconf)
  File "/home/oleg/.local/lib/python3.6/site-packages/django/urls/base.py", line 24, in resolve
    return get_resolver(urlconf).resolve(path)
  File "/home/oleg/.local/lib/python3.6/site-packages/django/urls/resolvers.py", line 498, in resolve
    for pattern in self.url_patterns:
  File "/home/oleg/.local/lib/python3.6/site-packages/django/utils/functional.py", line 36, in __get__
    res = instance.__dict__[self.name] = self.func(instance)
  File "/home/oleg/.local/lib/python3.6/site-packages/django/urls/resolvers.py", line 540, in url_patterns
    patterns = getattr(self.urlconf_module, "urlpatterns", self.urlconf_module)
  File "/home/oleg/.local/lib/python3.6/site-packages/django/utils/functional.py", line 36, in __get__
    res = instance.__dict__[self.name] = self.func(instance)
  File "/home/oleg/.local/lib/python3.6/site-packages/django/urls/resolvers.py", line 533, in urlconf_module
    return import_module(self.urlconf_name)
  File "/usr/lib/python3.6/importlib/__init__.py", line 126, in import_module
    return _bootstrap._gcd_import(name[level:], package, level)
  File "<frozen importlib._bootstrap>", line 994, in _gcd_import
  File "<frozen importlib._bootstrap>", line 971, in _find_and_load
  File "<frozen importlib._bootstrap>", line 955, in _find_and_load_unlocked
  File "<frozen importlib._bootstrap>", line 665, in _load_unlocked
  File "<frozen importlib._bootstrap_external>", line 678, in exec_module
  File "<frozen importlib._bootstrap>", line 219, in _call_with_frames_removed
  File "/home/oleg/YandexDisk/Python_Lessons/Django/myproject/myproject/urls.py", line 28, in <module>
    path('auth/', include('authapp.urls', namespace='auth')),
  File "/home/oleg/.local/lib/python3.6/site-packages/django/urls/conf.py", line 34, in include
    urlconf_module = import_module(urlconf_module)
  File "/usr/lib/python3.6/importlib/__init__.py", line 126, in import_module
    return _bootstrap._gcd_import(name[level:], package, level)
  File "<frozen importlib._bootstrap>", line 994, in _gcd_import
  File "<frozen importlib._bootstrap>", line 971, in _find_and_load
  File "<frozen importlib._bootstrap>", line 955, in _find_and_load_unlocked
  File "<frozen importlib._bootstrap>", line 665, in _load_unlocked
  File "<frozen importlib._bootstrap_external>", line 678, in exec_module
  File "<frozen importlib._bootstrap>", line 219, in _call_with_frames_removed
  File "/home/oleg/YandexDisk/Python_Lessons/Django/myproject/authapp/urls.py", line 1, in <module>
    import authapp.views as authapp
  File "/home/oleg/YandexDisk/Python_Lessons/Django/myproject/authapp/views.py", line 5, in <module>
    from authapp.forms import ShopUserRegisterForm
ImportError: cannot import name 'ShopUserRegisterForm'
ERROR      2018-07-30 15:05:07,550 Internal Server Error: /favicon.ico
Traceback (most recent call last):
  File "/home/oleg/.local/lib/python3.6/site-packages/django/core/handlers/exception.py", line 35, in inner
    response = get_response(request)
  File "/home/oleg/.local/lib/python3.6/site-packages/django/utils/deprecation.py", line 93, in __call__
    response = self.process_request(request)
  File "/home/oleg/.local/lib/python3.6/site-packages/django/middleware/common.py", line 60, in process_request
    if self.should_redirect_with_slash(request):
  File "/home/oleg/.local/lib/python3.6/site-packages/django/middleware/common.py", line 78, in should_redirect_with_slash
    not is_valid_path(request.path_info, urlconf) and
  File "/home/oleg/.local/lib/python3.6/site-packages/django/urls/base.py", line 157, in is_valid_path
    resolve(path, urlconf)
  File "/home/oleg/.local/lib/python3.6/site-packages/django/urls/base.py", line 24, in resolve
    return get_resolver(urlconf).resolve(path)
  File "/home/oleg/.local/lib/python3.6/site-packages/django/urls/resolvers.py", line 498, in resolve
    for pattern in self.url_patterns:
  File "/home/oleg/.local/lib/python3.6/site-packages/django/utils/functional.py", line 36, in __get__
    res = instance.__dict__[self.name] = self.func(instance)
  File "/home/oleg/.local/lib/python3.6/site-packages/django/urls/resolvers.py", line 540, in url_patterns
    patterns = getattr(self.urlconf_module, "urlpatterns", self.urlconf_module)
  File "/home/oleg/.local/lib/python3.6/site-packages/django/utils/functional.py", line 36, in __get__
    res = instance.__dict__[self.name] = self.func(instance)
  File "/home/oleg/.local/lib/python3.6/site-packages/django/urls/resolvers.py", line 533, in urlconf_module
    return import_module(self.urlconf_name)
  File "/usr/lib/python3.6/importlib/__init__.py", line 126, in import_module
    return _bootstrap._gcd_import(name[level:], package, level)
  File "<frozen importlib._bootstrap>", line 994, in _gcd_import
  File "<frozen importlib._bootstrap>", line 971, in _find_and_load
  File "<frozen importlib._bootstrap>", line 955, in _find_and_load_unlocked
  File "<frozen importlib._bootstrap>", line 665, in _load_unlocked
  File "<frozen importlib._bootstrap_external>", line 678, in exec_module
  File "<frozen importlib._bootstrap>", line 219, in _call_with_frames_removed
  File "/home/oleg/YandexDisk/Python_Lessons/Django/myproject/myproject/urls.py", line 28, in <module>
    path('auth/', include('authapp.urls', namespace='auth')),
  File "/home/oleg/.local/lib/python3.6/site-packages/django/urls/conf.py", line 34, in include
    urlconf_module = import_module(urlconf_module)
  File "/usr/lib/python3.6/importlib/__init__.py", line 126, in import_module
    return _bootstrap._gcd_import(name[level:], package, level)
  File "<frozen importlib._bootstrap>", line 994, in _gcd_import
  File "<frozen importlib._bootstrap>", line 971, in _find_and_load
  File "<frozen importlib._bootstrap>", line 955, in _find_and_load_unlocked
  File "<frozen importlib._bootstrap>", line 665, in _load_unlocked
  File "<frozen importlib._bootstrap_external>", line 678, in exec_module
  File "<frozen importlib._bootstrap>", line 219, in _call_with_frames_removed
  File "/home/oleg/YandexDisk/Python_Lessons/Django/myproject/authapp/urls.py", line 1, in <module>
    import authapp.views as authapp
  File "/home/oleg/YandexDisk/Python_Lessons/Django/myproject/authapp/views.py", line 5, in <module>
    from authapp.forms import ShopUserRegisterForm
ImportError: cannot import name 'ShopUserRegisterForm'
ERROR      2018-07-30 15:06:02,104 Internal Server Error: /auth/login/
Traceback (most recent call last):
  File "/home/oleg/.local/lib/python3.6/site-packages/django/core/handlers/exception.py", line 35, in inner
    response = get_response(request)
  File "/home/oleg/.local/lib/python3.6/site-packages/django/core/handlers/base.py", line 128, in _get_response
    response = self.process_exception_by_middleware(e, request)
  File "/home/oleg/.local/lib/python3.6/site-packages/django/core/handlers/base.py", line 126, in _get_response
    response = wrapped_callback(request, *callback_args, **callback_kwargs)
  File "/home/oleg/YandexDisk/Python_Lessons/Django/myproject/authapp/views.py", line 32, in login
    return render(request, 'authapp/login.html', content)
  File "/home/oleg/.local/lib/python3.6/site-packages/django/shortcuts.py", line 36, in render
    content = loader.render_to_string(template_name, context, request, using=using)
  File "/home/oleg/.local/lib/python3.6/site-packages/django/template/loader.py", line 61, in render_to_string
    template = get_template(template_name, using=using)
  File "/home/oleg/.local/lib/python3.6/site-packages/django/template/loader.py", line 19, in get_template
    raise TemplateDoesNotExist(template_name, chain=chain)
django.template.exceptions.TemplateDoesNotExist: authapp/login.html
WARNING    2018-07-30 15:06:02,565 Not Found: /favicon.ico
WARNING    2018-07-30 15:06:27,201 Not Found: /login/
WARNING    2018-07-30 15:06:34,462 Not Found: /auth
WARNING    2018-07-30 15:06:42,520 Not Found: /auth/
WARNING    2018-07-30 15:10:06,658 Not Found: /auth/
WARNING    2018-07-30 15:10:10,658 Not Found: /auth/
ERROR      2018-07-30 15:10:19,291 Internal Server Error: /auth/login/
Traceback (most recent call last):
  File "/home/oleg/.local/lib/python3.6/site-packages/django/core/handlers/exception.py", line 35, in inner
    response = get_response(request)
  File "/home/oleg/.local/lib/python3.6/site-packages/django/core/handlers/base.py", line 128, in _get_response
    response = self.process_exception_by_middleware(e, request)
  File "/home/oleg/.local/lib/python3.6/site-packages/django/core/handlers/base.py", line 126, in _get_response
    response = wrapped_callback(request, *callback_args, **callback_kwargs)
  File "/home/oleg/YandexDisk/Python_Lessons/Django/myproject/authapp/views.py", line 32, in login
    return render(request, 'authapp/login.html', content)
  File "/home/oleg/.local/lib/python3.6/site-packages/django/shortcuts.py", line 36, in render
    content = loader.render_to_string(template_name, context, request, using=using)
  File "/home/oleg/.local/lib/python3.6/site-packages/django/template/loader.py", line 62, in render_to_string
    return template.render(context, request)
  File "/home/oleg/.local/lib/python3.6/site-packages/django/template/backends/django.py", line 61, in render
    return self.template.render(context)
  File "/home/oleg/.local/lib/python3.6/site-packages/django/template/base.py", line 175, in render
    return self._render(context)
  File "/home/oleg/.local/lib/python3.6/site-packages/django/template/base.py", line 167, in _render
    return self.nodelist.render(context)
  File "/home/oleg/.local/lib/python3.6/site-packages/django/template/base.py", line 943, in render
    bit = node.render_annotated(context)
  File "/home/oleg/.local/lib/python3.6/site-packages/django/template/base.py", line 910, in render_annotated
    return self.render(context)
  File "/home/oleg/.local/lib/python3.6/site-packages/django/template/loader_tags.py", line 155, in render
    return compiled_parent._render(context)
  File "/home/oleg/.local/lib/python3.6/site-packages/django/template/base.py", line 167, in _render
    return self.nodelist.render(context)
  File "/home/oleg/.local/lib/python3.6/site-packages/django/template/base.py", line 943, in render
    bit = node.render_annotated(context)
  File "/home/oleg/.local/lib/python3.6/site-packages/django/template/base.py", line 910, in render_annotated
    return self.render(context)
  File "/home/oleg/.local/lib/python3.6/site-packages/django/template/loader_tags.py", line 67, in render
    result = block.nodelist.render(context)
  File "/home/oleg/.local/lib/python3.6/site-packages/django/template/base.py", line 943, in render
    bit = node.render_annotated(context)
  File "/home/oleg/.local/lib/python3.6/site-packages/django/template/base.py", line 910, in render_annotated
    return self.render(context)
  File "/home/oleg/.local/lib/python3.6/site-packages/django/template/defaulttags.py", line 447, in render
    url = reverse(view_name, args=args, kwargs=kwargs, current_app=current_app)
  File "/home/oleg/.local/lib/python3.6/site-packages/django/urls/base.py", line 90, in reverse
    return iri_to_uri(resolver._reverse_with_prefix(view, prefix, *args, **kwargs))
  File "/home/oleg/.local/lib/python3.6/site-packages/django/urls/resolvers.py", line 636, in _reverse_with_prefix
    raise NoReverseMatch(msg)
django.urls.exceptions.NoReverseMatch: Reverse for 'register' not found. 'register' is not a valid view function or pattern name.
ERROR      2018-07-31 14:20:53,702 Internal Server Error: /
Traceback (most recent call last):
  File "/home/oleg/.local/lib/python3.6/site-packages/django/urls/base.py", line 75, in reverse
    extra, resolver = resolver.namespace_dict[ns]
KeyError: 'basket'

During handling of the above exception, another exception occurred:

Traceback (most recent call last):
  File "/home/oleg/.local/lib/python3.6/site-packages/django/core/handlers/exception.py", line 35, in inner
    response = get_response(request)
  File "/home/oleg/.local/lib/python3.6/site-packages/django/core/handlers/base.py", line 128, in _get_response
    response = self.process_exception_by_middleware(e, request)
  File "/home/oleg/.local/lib/python3.6/site-packages/django/core/handlers/base.py", line 126, in _get_response
    response = wrapped_callback(request, *callback_args, **callback_kwargs)
  File "/home/oleg/YandexDisk/Python_Lessons/Django/myproject/mainapp/views.py", line 24, in main
    return render(request, 'mainapp/base.html', content)
  File "/home/oleg/.local/lib/python3.6/site-packages/django/shortcuts.py", line 36, in render
    content = loader.render_to_string(template_name, context, request, using=using)
  File "/home/oleg/.local/lib/python3.6/site-packages/django/template/loader.py", line 62, in render_to_string
    return template.render(context, request)
  File "/home/oleg/.local/lib/python3.6/site-packages/django/template/backends/django.py", line 61, in render
    return self.template.render(context)
  File "/home/oleg/.local/lib/python3.6/site-packages/django/template/base.py", line 175, in render
    return self._render(context)
  File "/home/oleg/.local/lib/python3.6/site-packages/django/template/base.py", line 167, in _render
    return self.nodelist.render(context)
  File "/home/oleg/.local/lib/python3.6/site-packages/django/template/base.py", line 943, in render
    bit = node.render_annotated(context)
  File "/home/oleg/.local/lib/python3.6/site-packages/django/template/base.py", line 910, in render_annotated
    return self.render(context)
  File "/home/oleg/.local/lib/python3.6/site-packages/django/template/loader_tags.py", line 194, in render
    return template.render(context)
  File "/home/oleg/.local/lib/python3.6/site-packages/django/template/base.py", line 177, in render
    return self._render(context)
  File "/home/oleg/.local/lib/python3.6/site-packages/django/template/base.py", line 167, in _render
    return self.nodelist.render(context)
  File "/home/oleg/.local/lib/python3.6/site-packages/django/template/base.py", line 943, in render
    bit = node.render_annotated(context)
  File "/home/oleg/.local/lib/python3.6/site-packages/django/template/base.py", line 910, in render_annotated
    return self.render(context)
  File "/home/oleg/.local/lib/python3.6/site-packages/django/template/defaulttags.py", line 447, in render
    url = reverse(view_name, args=args, kwargs=kwargs, current_app=current_app)
  File "/home/oleg/.local/lib/python3.6/site-packages/django/urls/base.py", line 86, in reverse
    raise NoReverseMatch("%s is not a registered namespace" % key)
django.urls.exceptions.NoReverseMatch: 'basket' is not a registered namespace
WARNING    2018-07-31 14:20:55,324 Not Found: /favicon.ico
ERROR      2018-07-31 14:40:29,660 Internal Server Error: /auth/login
Traceback (most recent call last):
  File "/home/oleg/.local/lib/python3.6/site-packages/django/core/handlers/exception.py", line 35, in inner
    response = get_response(request)
  File "/home/oleg/.local/lib/python3.6/site-packages/django/utils/deprecation.py", line 93, in __call__
    response = self.process_request(request)
  File "/home/oleg/.local/lib/python3.6/site-packages/django/middleware/common.py", line 60, in process_request
    if self.should_redirect_with_slash(request):
  File "/home/oleg/.local/lib/python3.6/site-packages/django/middleware/common.py", line 78, in should_redirect_with_slash
    not is_valid_path(request.path_info, urlconf) and
  File "/home/oleg/.local/lib/python3.6/site-packages/django/urls/base.py", line 157, in is_valid_path
    resolve(path, urlconf)
  File "/home/oleg/.local/lib/python3.6/site-packages/django/urls/base.py", line 24, in resolve
    return get_resolver(urlconf).resolve(path)
  File "/home/oleg/.local/lib/python3.6/site-packages/django/urls/resolvers.py", line 498, in resolve
    for pattern in self.url_patterns:
  File "/home/oleg/.local/lib/python3.6/site-packages/django/utils/functional.py", line 36, in __get__
    res = instance.__dict__[self.name] = self.func(instance)
  File "/home/oleg/.local/lib/python3.6/site-packages/django/urls/resolvers.py", line 540, in url_patterns
    patterns = getattr(self.urlconf_module, "urlpatterns", self.urlconf_module)
  File "/home/oleg/.local/lib/python3.6/site-packages/django/utils/functional.py", line 36, in __get__
    res = instance.__dict__[self.name] = self.func(instance)
  File "/home/oleg/.local/lib/python3.6/site-packages/django/urls/resolvers.py", line 533, in urlconf_module
    return import_module(self.urlconf_name)
  File "/usr/lib/python3.6/importlib/__init__.py", line 126, in import_module
    return _bootstrap._gcd_import(name[level:], package, level)
  File "<frozen importlib._bootstrap>", line 994, in _gcd_import
  File "<frozen importlib._bootstrap>", line 971, in _find_and_load
  File "<frozen importlib._bootstrap>", line 955, in _find_and_load_unlocked
  File "<frozen importlib._bootstrap>", line 665, in _load_unlocked
  File "<frozen importlib._bootstrap_external>", line 678, in exec_module
  File "<frozen importlib._bootstrap>", line 219, in _call_with_frames_removed
  File "/home/oleg/YandexDisk/Python_Lessons/Django/myproject/myproject/urls.py", line 28, in <module>
    path('auth/', include('authapp.urls', namespace='auth')),
  File "/home/oleg/.local/lib/python3.6/site-packages/django/urls/conf.py", line 34, in include
    urlconf_module = import_module(urlconf_module)
  File "/usr/lib/python3.6/importlib/__init__.py", line 126, in import_module
    return _bootstrap._gcd_import(name[level:], package, level)
  File "<frozen importlib._bootstrap>", line 994, in _gcd_import
  File "<frozen importlib._bootstrap>", line 971, in _find_and_load
  File "<frozen importlib._bootstrap>", line 955, in _find_and_load_unlocked
  File "<frozen importlib._bootstrap>", line 665, in _load_unlocked
  File "<frozen importlib._bootstrap_external>", line 678, in exec_module
  File "<frozen importlib._bootstrap>", line 219, in _call_with_frames_removed
  File "/home/oleg/YandexDisk/Python_Lessons/Django/myproject/authapp/urls.py", line 1, in <module>
    import authapp.views as authapp
  File "/home/oleg/YandexDisk/Python_Lessons/Django/myproject/authapp/views.py", line 5, in <module>
    from authapp.forms import ShopUserRegisterForm
ImportError: cannot import name 'ShopUserRegisterForm'
WARNING    2018-07-31 14:46:55,653 Not Found: /static/css/bootstrap.min.css
WARNING    2018-07-31 14:46:55,673 Not Found: /static/css/font-awesome.min.css
WARNING    2018-07-31 14:46:55,693 Not Found: /static/css/style.css
ERROR      2018-07-31 14:46:59,717 Internal Server Error: /auth/login/
Traceback (most recent call last):
  File "/home/oleg/.local/lib/python3.6/site-packages/django/db/backends/utils.py", line 85, in _execute
    return self.cursor.execute(sql, params)
psycopg2.ProgrammingError: relation "authapp_shopuser" does not exist
LINE 1: ...shopuser"."avatar", "authapp_shopuser"."age" FROM "authapp_s...
                                                             ^


The above exception was the direct cause of the following exception:

Traceback (most recent call last):
  File "/home/oleg/.local/lib/python3.6/site-packages/django/core/handlers/exception.py", line 35, in inner
    response = get_response(request)
  File "/home/oleg/.local/lib/python3.6/site-packages/django/core/handlers/base.py", line 128, in _get_response
    response = self.process_exception_by_middleware(e, request)
  File "/home/oleg/.local/lib/python3.6/site-packages/django/core/handlers/base.py", line 126, in _get_response
    response = wrapped_callback(request, *callback_args, **callback_kwargs)
  File "/home/oleg/YandexDisk/Python_Lessons/Django/myproject/authapp/views.py", line 19, in login
    if request.method == 'POST' and login_form.is_valid():
  File "/home/oleg/.local/lib/python3.6/site-packages/django/forms/forms.py", line 179, in is_valid
    return self.is_bound and not self.errors
  File "/home/oleg/.local/lib/python3.6/site-packages/django/forms/forms.py", line 174, in errors
    self.full_clean()
  File "/home/oleg/.local/lib/python3.6/site-packages/django/forms/forms.py", line 377, in full_clean
    self._clean_form()
  File "/home/oleg/.local/lib/python3.6/site-packages/django/forms/forms.py", line 404, in _clean_form
    cleaned_data = self.clean()
  File "/home/oleg/.local/lib/python3.6/site-packages/django/contrib/auth/forms.py", line 195, in clean
    self.user_cache = authenticate(self.request, username=username, password=password)
  File "/home/oleg/.local/lib/python3.6/site-packages/django/contrib/auth/__init__.py", line 70, in authenticate
    user = _authenticate_with_backend(backend, backend_path, request, credentials)
  File "/home/oleg/.local/lib/python3.6/site-packages/django/contrib/auth/__init__.py", line 116, in _authenticate_with_backend
    return backend.authenticate(*args, **credentials)
  File "/home/oleg/.local/lib/python3.6/site-packages/django/contrib/auth/backends.py", line 16, in authenticate
    user = UserModel._default_manager.get_by_natural_key(username)
  File "/home/oleg/.local/lib/python3.6/site-packages/django/contrib/auth/base_user.py", line 44, in get_by_natural_key
    return self.get(**{self.model.USERNAME_FIELD: username})
  File "/home/oleg/.local/lib/python3.6/site-packages/django/db/models/manager.py", line 82, in manager_method
    return getattr(self.get_queryset(), name)(*args, **kwargs)
  File "/home/oleg/.local/lib/python3.6/site-packages/django/db/models/query.py", line 397, in get
    num = len(clone)
  File "/home/oleg/.local/lib/python3.6/site-packages/django/db/models/query.py", line 254, in __len__
    self._fetch_all()
  File "/home/oleg/.local/lib/python3.6/site-packages/django/db/models/query.py", line 1179, in _fetch_all
    self._result_cache = list(self._iterable_class(self))
  File "/home/oleg/.local/lib/python3.6/site-packages/django/db/models/query.py", line 53, in __iter__
    results = compiler.execute_sql(chunked_fetch=self.chunked_fetch, chunk_size=self.chunk_size)
  File "/home/oleg/.local/lib/python3.6/site-packages/django/db/models/sql/compiler.py", line 1068, in execute_sql
    cursor.execute(sql, params)
  File "/home/oleg/.local/lib/python3.6/site-packages/django/db/backends/utils.py", line 100, in execute
    return super().execute(sql, params)
  File "/home/oleg/.local/lib/python3.6/site-packages/django/db/backends/utils.py", line 68, in execute
    return self._execute_with_wrappers(sql, params, many=False, executor=self._execute)
  File "/home/oleg/.local/lib/python3.6/site-packages/django/db/backends/utils.py", line 77, in _execute_with_wrappers
    return executor(sql, params, many, context)
  File "/home/oleg/.local/lib/python3.6/site-packages/django/db/backends/utils.py", line 85, in _execute
    return self.cursor.execute(sql, params)
  File "/home/oleg/.local/lib/python3.6/site-packages/django/db/utils.py", line 89, in __exit__
    raise dj_exc_value.with_traceback(traceback) from exc_value
  File "/home/oleg/.local/lib/python3.6/site-packages/django/db/backends/utils.py", line 85, in _execute
    return self.cursor.execute(sql, params)
django.db.utils.ProgrammingError: relation "authapp_shopuser" does not exist
LINE 1: ...shopuser"."avatar", "authapp_shopuser"."age" FROM "authapp_s...
                                                             ^

ERROR      2018-07-31 14:48:45,449 Internal Server Error: /auth/login/
Traceback (most recent call last):
  File "/home/oleg/.local/lib/python3.6/site-packages/django/db/backends/utils.py", line 85, in _execute
    return self.cursor.execute(sql, params)
psycopg2.ProgrammingError: relation "authapp_shopuser" does not exist
LINE 1: ...shopuser"."avatar", "authapp_shopuser"."age" FROM "authapp_s...
                                                             ^


The above exception was the direct cause of the following exception:

Traceback (most recent call last):
  File "/home/oleg/.local/lib/python3.6/site-packages/django/core/handlers/exception.py", line 35, in inner
    response = get_response(request)
  File "/home/oleg/.local/lib/python3.6/site-packages/django/core/handlers/base.py", line 128, in _get_response
    response = self.process_exception_by_middleware(e, request)
  File "/home/oleg/.local/lib/python3.6/site-packages/django/core/handlers/base.py", line 126, in _get_response
    response = wrapped_callback(request, *callback_args, **callback_kwargs)
  File "/home/oleg/YandexDisk/Python_Lessons/Django/myproject/authapp/views.py", line 19, in login
    if request.method == 'POST' and login_form.is_valid():
  File "/home/oleg/.local/lib/python3.6/site-packages/django/forms/forms.py", line 179, in is_valid
    return self.is_bound and not self.errors
  File "/home/oleg/.local/lib/python3.6/site-packages/django/forms/forms.py", line 174, in errors
    self.full_clean()
  File "/home/oleg/.local/lib/python3.6/site-packages/django/forms/forms.py", line 377, in full_clean
    self._clean_form()
  File "/home/oleg/.local/lib/python3.6/site-packages/django/forms/forms.py", line 404, in _clean_form
    cleaned_data = self.clean()
  File "/home/oleg/.local/lib/python3.6/site-packages/django/contrib/auth/forms.py", line 195, in clean
    self.user_cache = authenticate(self.request, username=username, password=password)
  File "/home/oleg/.local/lib/python3.6/site-packages/django/contrib/auth/__init__.py", line 70, in authenticate
    user = _authenticate_with_backend(backend, backend_path, request, credentials)
  File "/home/oleg/.local/lib/python3.6/site-packages/django/contrib/auth/__init__.py", line 116, in _authenticate_with_backend
    return backend.authenticate(*args, **credentials)
  File "/home/oleg/.local/lib/python3.6/site-packages/django/contrib/auth/backends.py", line 16, in authenticate
    user = UserModel._default_manager.get_by_natural_key(username)
  File "/home/oleg/.local/lib/python3.6/site-packages/django/contrib/auth/base_user.py", line 44, in get_by_natural_key
    return self.get(**{self.model.USERNAME_FIELD: username})
  File "/home/oleg/.local/lib/python3.6/site-packages/django/db/models/manager.py", line 82, in manager_method
    return getattr(self.get_queryset(), name)(*args, **kwargs)
  File "/home/oleg/.local/lib/python3.6/site-packages/django/db/models/query.py", line 397, in get
    num = len(clone)
  File "/home/oleg/.local/lib/python3.6/site-packages/django/db/models/query.py", line 254, in __len__
    self._fetch_all()
  File "/home/oleg/.local/lib/python3.6/site-packages/django/db/models/query.py", line 1179, in _fetch_all
    self._result_cache = list(self._iterable_class(self))
  File "/home/oleg/.local/lib/python3.6/site-packages/django/db/models/query.py", line 53, in __iter__
    results = compiler.execute_sql(chunked_fetch=self.chunked_fetch, chunk_size=self.chunk_size)
  File "/home/oleg/.local/lib/python3.6/site-packages/django/db/models/sql/compiler.py", line 1068, in execute_sql
    cursor.execute(sql, params)
  File "/home/oleg/.local/lib/python3.6/site-packages/django/db/backends/utils.py", line 100, in execute
    return super().execute(sql, params)
  File "/home/oleg/.local/lib/python3.6/site-packages/django/db/backends/utils.py", line 68, in execute
    return self._execute_with_wrappers(sql, params, many=False, executor=self._execute)
  File "/home/oleg/.local/lib/python3.6/site-packages/django/db/backends/utils.py", line 77, in _execute_with_wrappers
    return executor(sql, params, many, context)
  File "/home/oleg/.local/lib/python3.6/site-packages/django/db/backends/utils.py", line 85, in _execute
    return self.cursor.execute(sql, params)
  File "/home/oleg/.local/lib/python3.6/site-packages/django/db/utils.py", line 89, in __exit__
    raise dj_exc_value.with_traceback(traceback) from exc_value
  File "/home/oleg/.local/lib/python3.6/site-packages/django/db/backends/utils.py", line 85, in _execute
    return self.cursor.execute(sql, params)
django.db.utils.ProgrammingError: relation "authapp_shopuser" does not exist
LINE 1: ...shopuser"."avatar", "authapp_shopuser"."age" FROM "authapp_s...
                                                             ^

WARNING    2018-07-31 14:49:23,452 Not Found: /static/css/bootstrap.min.css
WARNING    2018-07-31 14:49:23,471 Not Found: /static/css/font-awesome.min.css
WARNING    2018-07-31 14:49:23,481 Not Found: /static/css/style.css
ERROR      2018-07-31 14:49:58,320 Internal Server Error: /auth/register/
Traceback (most recent call last):
  File "/home/oleg/.local/lib/python3.6/site-packages/django/db/backends/utils.py", line 85, in _execute
    return self.cursor.execute(sql, params)
psycopg2.ProgrammingError: relation "authapp_shopuser" does not exist
LINE 1: SELECT (1) AS "a" FROM "authapp_shopuser" WHERE "authapp_sho...
                               ^


The above exception was the direct cause of the following exception:

Traceback (most recent call last):
  File "/home/oleg/.local/lib/python3.6/site-packages/django/core/handlers/exception.py", line 35, in inner
    response = get_response(request)
  File "/home/oleg/.local/lib/python3.6/site-packages/django/core/handlers/base.py", line 128, in _get_response
    response = self.process_exception_by_middleware(e, request)
  File "/home/oleg/.local/lib/python3.6/site-packages/django/core/handlers/base.py", line 126, in _get_response
    response = wrapped_callback(request, *callback_args, **callback_kwargs)
  File "/home/oleg/YandexDisk/Python_Lessons/Django/myproject/authapp/views.py", line 46, in register
    if register_form.is_valid():
  File "/home/oleg/.local/lib/python3.6/site-packages/django/forms/forms.py", line 179, in is_valid
    return self.is_bound and not self.errors
  File "/home/oleg/.local/lib/python3.6/site-packages/django/forms/forms.py", line 174, in errors
    self.full_clean()
  File "/home/oleg/.local/lib/python3.6/site-packages/django/forms/forms.py", line 378, in full_clean
    self._post_clean()
  File "/home/oleg/.local/lib/python3.6/site-packages/django/contrib/auth/forms.py", line 106, in _post_clean
    super()._post_clean()
  File "/home/oleg/.local/lib/python3.6/site-packages/django/forms/models.py", line 407, in _post_clean
    self.validate_unique()
  File "/home/oleg/.local/lib/python3.6/site-packages/django/forms/models.py", line 416, in validate_unique
    self.instance.validate_unique(exclude=exclude)
  File "/home/oleg/.local/lib/python3.6/site-packages/django/db/models/base.py", line 951, in validate_unique
    errors = self._perform_unique_checks(unique_checks)
  File "/home/oleg/.local/lib/python3.6/site-packages/django/db/models/base.py", line 1047, in _perform_unique_checks
    if qs.exists():
  File "/home/oleg/.local/lib/python3.6/site-packages/django/db/models/query.py", line 715, in exists
    return self.query.has_results(using=self.db)
  File "/home/oleg/.local/lib/python3.6/site-packages/django/db/models/sql/query.py", line 509, in has_results
    return compiler.has_results()
  File "/home/oleg/.local/lib/python3.6/site-packages/django/db/models/sql/compiler.py", line 1037, in has_results
    return bool(self.execute_sql(SINGLE))
  File "/home/oleg/.local/lib/python3.6/site-packages/django/db/models/sql/compiler.py", line 1068, in execute_sql
    cursor.execute(sql, params)
  File "/home/oleg/.local/lib/python3.6/site-packages/django/db/backends/utils.py", line 100, in execute
    return super().execute(sql, params)
  File "/home/oleg/.local/lib/python3.6/site-packages/django/db/backends/utils.py", line 68, in execute
    return self._execute_with_wrappers(sql, params, many=False, executor=self._execute)
  File "/home/oleg/.local/lib/python3.6/site-packages/django/db/backends/utils.py", line 77, in _execute_with_wrappers
    return executor(sql, params, many, context)
  File "/home/oleg/.local/lib/python3.6/site-packages/django/db/backends/utils.py", line 85, in _execute
    return self.cursor.execute(sql, params)
  File "/home/oleg/.local/lib/python3.6/site-packages/django/db/utils.py", line 89, in __exit__
    raise dj_exc_value.with_traceback(traceback) from exc_value
  File "/home/oleg/.local/lib/python3.6/site-packages/django/db/backends/utils.py", line 85, in _execute
    return self.cursor.execute(sql, params)
django.db.utils.ProgrammingError: relation "authapp_shopuser" does not exist
LINE 1: SELECT (1) AS "a" FROM "authapp_shopuser" WHERE "authapp_sho...
                               ^

WARNING    2018-07-31 15:11:11,243 Not Found: /static/css/bootstrap.min.css
WARNING    2018-07-31 15:11:11,372 Not Found: /static/css/font-awesome.min.css
WARNING    2018-07-31 15:11:11,381 Not Found: /static/css/style.css
WARNING    2018-07-31 15:11:16,884 Not Found: /static/css/bootstrap.min.css
WARNING    2018-07-31 15:11:16,896 Not Found: /static/css/font-awesome.min.css
WARNING    2018-07-31 15:11:16,913 Not Found: /static/css/style.css
ERROR      2018-07-31 15:11:24,708 Internal Server Error: /
Traceback (most recent call last):
  File "/home/oleg/.local/lib/python3.6/site-packages/django/urls/base.py", line 75, in reverse
    extra, resolver = resolver.namespace_dict[ns]
KeyError: 'basket'

During handling of the above exception, another exception occurred:

Traceback (most recent call last):
  File "/home/oleg/.local/lib/python3.6/site-packages/django/core/handlers/exception.py", line 35, in inner
    response = get_response(request)
  File "/home/oleg/.local/lib/python3.6/site-packages/django/core/handlers/base.py", line 128, in _get_response
    response = self.process_exception_by_middleware(e, request)
  File "/home/oleg/.local/lib/python3.6/site-packages/django/core/handlers/base.py", line 126, in _get_response
    response = wrapped_callback(request, *callback_args, **callback_kwargs)
  File "/home/oleg/YandexDisk/Python_Lessons/Django/myproject/mainapp/views.py", line 24, in main
    return render(request, 'mainapp/base.html', content)
  File "/home/oleg/.local/lib/python3.6/site-packages/django/shortcuts.py", line 36, in render
    content = loader.render_to_string(template_name, context, request, using=using)
  File "/home/oleg/.local/lib/python3.6/site-packages/django/template/loader.py", line 62, in render_to_string
    return template.render(context, request)
  File "/home/oleg/.local/lib/python3.6/site-packages/django/template/backends/django.py", line 61, in render
    return self.template.render(context)
  File "/home/oleg/.local/lib/python3.6/site-packages/django/template/base.py", line 175, in render
    return self._render(context)
  File "/home/oleg/.local/lib/python3.6/site-packages/django/template/base.py", line 167, in _render
    return self.nodelist.render(context)
  File "/home/oleg/.local/lib/python3.6/site-packages/django/template/base.py", line 943, in render
    bit = node.render_annotated(context)
  File "/home/oleg/.local/lib/python3.6/site-packages/django/template/base.py", line 910, in render_annotated
    return self.render(context)
  File "/home/oleg/.local/lib/python3.6/site-packages/django/template/loader_tags.py", line 194, in render
    return template.render(context)
  File "/home/oleg/.local/lib/python3.6/site-packages/django/template/base.py", line 177, in render
    return self._render(context)
  File "/home/oleg/.local/lib/python3.6/site-packages/django/template/base.py", line 167, in _render
    return self.nodelist.render(context)
  File "/home/oleg/.local/lib/python3.6/site-packages/django/template/base.py", line 943, in render
    bit = node.render_annotated(context)
  File "/home/oleg/.local/lib/python3.6/site-packages/django/template/base.py", line 910, in render_annotated
    return self.render(context)
  File "/home/oleg/.local/lib/python3.6/site-packages/django/template/defaulttags.py", line 447, in render
    url = reverse(view_name, args=args, kwargs=kwargs, current_app=current_app)
  File "/home/oleg/.local/lib/python3.6/site-packages/django/urls/base.py", line 86, in reverse
    raise NoReverseMatch("%s is not a registered namespace" % key)
django.urls.exceptions.NoReverseMatch: 'basket' is not a registered namespace
WARNING    2018-07-31 15:19:32,327 Not Found: /static/css/bootstrap.min.css
WARNING    2018-07-31 15:19:33,100 Not Found: /static/css/font-awesome.min.css
WARNING    2018-07-31 15:19:33,112 Not Found: /static/css/style.css
WARNING    2018-07-31 15:19:33,274 Not Found: /static/img/sunrise_logo.png
WARNING    2018-07-31 15:19:33,289 Not Found: /static/img/image001.png
WARNING    2018-07-31 15:19:33,531 Not Found: /static/img/image002.png
WARNING    2018-07-31 15:19:33,691 Not Found: /static/img/image003.png
WARNING    2018-07-31 15:19:33,707 Not Found: /static/img/image004.png
WARNING    2018-07-31 15:19:33,719 Not Found: /static/img/image005.png
WARNING    2018-07-31 15:19:33,734 Not Found: /static/img/image006.png
WARNING    2018-07-31 15:19:33,750 Not Found: /static/img/image007.png
WARNING    2018-07-31 15:19:33,765 Not Found: /static/img/image008.png
WARNING    2018-07-31 15:19:33,777 Not Found: /static/img/001.jpg
WARNING    2018-07-31 15:19:34,032 Not Found: /static/img/002.jpg
WARNING    2018-07-31 15:19:34,050 Not Found: /static/img/003.jpg
WARNING    2018-07-31 15:19:34,063 Not Found: /static/img/004.jpg
WARNING    2018-07-31 15:19:34,076 Not Found: /static/img/005.jpg
WARNING    2018-07-31 15:19:34,088 Not Found: /static/img/006.jpg
WARNING    2018-07-31 15:19:34,103 Not Found: /static/img/maestero.png
WARNING    2018-07-31 15:19:34,115 Not Found: /static/img/mastercard.png
WARNING    2018-07-31 15:19:34,129 Not Found: /static/img/aex.png
WARNING    2018-07-31 15:19:34,140 Not Found: /static/img/paypal.png
WARNING    2018-07-31 15:19:34,151 Not Found: /static/img/discover.png
WARNING    2018-07-31 15:19:34,161 Not Found: /static/img/visa_straight.png
WARNING    2018-07-31 15:19:48,893 Not Found: /static/css/bootstrap.min.css
WARNING    2018-07-31 15:19:48,910 Not Found: /static/css/style.css
WARNING    2018-07-31 15:19:48,924 Not Found: /static/css/font-awesome.min.css
WARNING    2018-07-31 15:19:48,938 Not Found: /static/js/jquery-3.2.1.min.js
WARNING    2018-07-31 15:19:48,948 Not Found: /static/js/basket_scripts.js
WARNING    2018-07-31 15:19:50,525 Not Found: /static/css/bootstrap.min.css
WARNING    2018-07-31 15:19:50,620 Not Found: /static/css/font-awesome.min.css
WARNING    2018-07-31 15:19:50,636 Not Found: /static/css/style.css
WARNING    2018-07-31 15:19:50,646 Not Found: /static/img/sunrise_logo.png
WARNING    2018-07-31 15:19:50,657 Not Found: /static/img/image001.png
WARNING    2018-07-31 15:19:50,668 Not Found: /static/img/image002.png
WARNING    2018-07-31 15:19:50,680 Not Found: /static/img/image003.png
WARNING    2018-07-31 15:19:50,859 Not Found: /static/img/image004.png
WARNING    2018-07-31 15:19:50,900 Not Found: /static/img/image005.png
WARNING    2018-07-31 15:19:50,917 Not Found: /static/img/image006.png
WARNING    2018-07-31 15:19:50,932 Not Found: /static/img/image007.png
WARNING    2018-07-31 15:19:50,977 Not Found: /static/img/image008.png
WARNING    2018-07-31 15:19:50,987 Not Found: /static/img/001.jpg
WARNING    2018-07-31 15:19:51,076 Not Found: /static/img/002.jpg
WARNING    2018-07-31 15:19:51,089 Not Found: /static/img/003.jpg
WARNING    2018-07-31 15:19:51,110 Not Found: /static/img/004.jpg
WARNING    2018-07-31 15:19:51,124 Not Found: /static/img/005.jpg
WARNING    2018-07-31 15:19:51,141 Not Found: /static/img/006.jpg
WARNING    2018-07-31 15:19:51,151 Not Found: /static/img/maestero.png
WARNING    2018-07-31 15:19:51,232 Not Found: /static/img/mastercard.png
WARNING    2018-07-31 15:19:51,259 Not Found: /static/img/aex.png
WARNING    2018-07-31 15:19:51,271 Not Found: /static/img/paypal.png
WARNING    2018-07-31 15:19:51,288 Not Found: /static/img/discover.png
WARNING    2018-07-31 15:19:51,305 Not Found: /static/img/visa_straight.png
ERROR      2018-07-31 15:19:54,535 Internal Server Error: /contacts/
Traceback (most recent call last):
  File "/home/oleg/.local/lib/python3.6/site-packages/django/core/handlers/exception.py", line 35, in inner
    response = get_response(request)
  File "/home/oleg/.local/lib/python3.6/site-packages/django/core/handlers/base.py", line 128, in _get_response
    response = self.process_exception_by_middleware(e, request)
  File "/home/oleg/.local/lib/python3.6/site-packages/django/core/handlers/base.py", line 126, in _get_response
    response = wrapped_callback(request, *callback_args, **callback_kwargs)
  File "/home/oleg/YandexDisk/Python_Lessons/Django/myproject/contactsapp/views.py", line 20, in contact
    basket = getBasket(request.user)
  File "/home/oleg/YandexDisk/Python_Lessons/Django/myproject/mainapp/views.py", line 29, in getBasket
    return Basket.objects.filter(user=user)
NameError: name 'Basket' is not defined
WARNING    2018-07-31 15:27:31,322 Not Found: /static/css/bootstrap.min.css
WARNING    2018-07-31 15:27:31,563 Not Found: /static/css/font-awesome.min.css
WARNING    2018-07-31 15:27:31,573 Not Found: /static/css/style.css
WARNING    2018-07-31 15:27:31,584 Not Found: /static/img/sunrise_logo.png
WARNING    2018-07-31 15:27:31,594 Not Found: /static/img/image001.png
WARNING    2018-07-31 15:27:31,871 Not Found: /static/img/image002.png
WARNING    2018-07-31 15:27:32,127 Not Found: /static/img/image003.png
WARNING    2018-07-31 15:27:32,141 Not Found: /static/img/image004.png
WARNING    2018-07-31 15:27:32,151 Not Found: /static/img/image005.png
WARNING    2018-07-31 15:27:32,162 Not Found: /static/img/image006.png
WARNING    2018-07-31 15:27:32,173 Not Found: /static/img/image007.png
WARNING    2018-07-31 15:27:32,182 Not Found: /static/img/image008.png
WARNING    2018-07-31 15:27:32,531 Not Found: /static/img/001.jpg
WARNING    2018-07-31 15:27:32,603 Not Found: /static/img/002.jpg
WARNING    2018-07-31 15:27:32,618 Not Found: /static/img/003.jpg
WARNING    2018-07-31 15:27:32,631 Not Found: /static/img/004.jpg
WARNING    2018-07-31 15:27:32,643 Not Found: /static/img/005.jpg
WARNING    2018-07-31 15:27:32,655 Not Found: /static/img/006.jpg
WARNING    2018-07-31 15:27:32,667 Not Found: /static/img/maestero.png
WARNING    2018-07-31 15:27:32,680 Not Found: /static/img/mastercard.png
WARNING    2018-07-31 15:27:32,691 Not Found: /static/img/aex.png
WARNING    2018-07-31 15:27:32,703 Not Found: /static/img/paypal.png
WARNING    2018-07-31 15:27:32,714 Not Found: /static/img/discover.png
WARNING    2018-07-31 15:27:32,725 Not Found: /static/img/visa_straight.png
ERROR      2018-07-31 15:27:49,251 Internal Server Error: /category/
Traceback (most recent call last):
  File "/home/oleg/.local/lib/python3.6/site-packages/django/core/handlers/exception.py", line 35, in inner
    response = get_response(request)
  File "/home/oleg/.local/lib/python3.6/site-packages/django/core/handlers/base.py", line 128, in _get_response
    response = self.process_exception_by_middleware(e, request)
  File "/home/oleg/.local/lib/python3.6/site-packages/django/core/handlers/base.py", line 126, in _get_response
    response = wrapped_callback(request, *callback_args, **callback_kwargs)
  File "/home/oleg/YandexDisk/Python_Lessons/Django/myproject/mainapp/views.py", line 37, in products
    links_menu = ProductCategory.objects.filter(is_active=True)
  File "/home/oleg/.local/lib/python3.6/site-packages/django/db/models/manager.py", line 82, in manager_method
    return getattr(self.get_queryset(), name)(*args, **kwargs)
  File "/home/oleg/.local/lib/python3.6/site-packages/django/db/models/query.py", line 836, in filter
    return self._filter_or_exclude(False, *args, **kwargs)
  File "/home/oleg/.local/lib/python3.6/site-packages/django/db/models/query.py", line 854, in _filter_or_exclude
    clone.query.add_q(Q(*args, **kwargs))
  File "/home/oleg/.local/lib/python3.6/site-packages/django/db/models/sql/query.py", line 1253, in add_q
    clause, _ = self._add_q(q_object, self.used_aliases)
  File "/home/oleg/.local/lib/python3.6/site-packages/django/db/models/sql/query.py", line 1277, in _add_q
    split_subq=split_subq,
  File "/home/oleg/.local/lib/python3.6/site-packages/django/db/models/sql/query.py", line 1153, in build_filter
    lookups, parts, reffed_expression = self.solve_lookup_type(arg)
  File "/home/oleg/.local/lib/python3.6/site-packages/django/db/models/sql/query.py", line 1015, in solve_lookup_type
    _, field, _, lookup_parts = self.names_to_path(lookup_splitted, self.get_meta())
  File "/home/oleg/.local/lib/python3.6/site-packages/django/db/models/sql/query.py", line 1379, in names_to_path
    "Choices are: %s" % (name, ", ".join(available)))
django.core.exceptions.FieldError: Cannot resolve keyword 'is_active' into field. Choices are: description, id, name, product
WARNING    2018-07-31 15:50:40,616 Not Found: /static/css/bootstrap.min.css
WARNING    2018-07-31 15:50:40,632 Not Found: /static/css/font-awesome.min.css
WARNING    2018-07-31 15:50:40,643 Not Found: /static/css/style.css
WARNING    2018-07-31 15:50:40,656 Not Found: /static/img/sunrise_logo.png
WARNING    2018-07-31 15:50:40,668 Not Found: /static/img/image001.png
WARNING    2018-07-31 15:50:40,733 Not Found: /static/img/image002.png
WARNING    2018-07-31 15:50:40,749 Not Found: /static/img/image003.png
WARNING    2018-07-31 15:50:40,772 Not Found: /static/img/image004.png
WARNING    2018-07-31 15:50:40,785 Not Found: /static/img/image005.png
WARNING    2018-07-31 15:50:40,798 Not Found: /static/img/image006.png
WARNING    2018-07-31 15:50:40,813 Not Found: /static/img/image007.png
WARNING    2018-07-31 15:50:40,825 Not Found: /static/img/image008.png
WARNING    2018-07-31 15:50:40,864 Not Found: /static/img/001.jpg
WARNING    2018-07-31 15:50:40,879 Not Found: /static/img/002.jpg
WARNING    2018-07-31 15:50:40,891 Not Found: /static/img/003.jpg
WARNING    2018-07-31 15:50:40,903 Not Found: /static/img/004.jpg
WARNING    2018-07-31 15:50:40,914 Not Found: /static/img/005.jpg
WARNING    2018-07-31 15:50:40,929 Not Found: /static/img/006.jpg
WARNING    2018-07-31 15:50:40,975 Not Found: /static/img/maestero.png
WARNING    2018-07-31 15:50:40,992 Not Found: /static/img/mastercard.png
WARNING    2018-07-31 15:50:41,012 Not Found: /static/img/aex.png
WARNING    2018-07-31 15:50:41,029 Not Found: /static/img/paypal.png
WARNING    2018-07-31 15:50:41,045 Not Found: /static/img/discover.png
WARNING    2018-07-31 15:50:41,062 Not Found: /static/img/visa_straight.png
WARNING    2018-07-31 15:50:51,402 Not Found: /static/css/bootstrap.min.css
WARNING    2018-07-31 15:50:51,429 Not Found: /static/css/font-awesome.min.css
WARNING    2018-07-31 15:50:51,451 Not Found: /static/css/style.css
WARNING    2018-07-31 15:50:51,462 Not Found: /media/
WARNING    2018-07-31 15:50:54,751 Not Found: /static/css/bootstrap.min.css
WARNING    2018-07-31 15:50:54,774 Not Found: /static/css/font-awesome.min.css
WARNING    2018-07-31 15:50:54,787 Not Found: /static/css/style.css
WARNING    2018-07-31 15:50:54,802 Not Found: /static/img/sunrise_logo.png
WARNING    2018-07-31 15:50:54,841 Not Found: /static/img/image001.png
WARNING    2018-07-31 15:50:54,858 Not Found: /static/img/image002.png
WARNING    2018-07-31 15:50:54,871 Not Found: /static/img/image003.png
WARNING    2018-07-31 15:50:54,886 Not Found: /static/img/image004.png
WARNING    2018-07-31 15:50:54,899 Not Found: /static/img/image005.png
WARNING    2018-07-31 15:50:54,919 Not Found: /static/img/image006.png
WARNING    2018-07-31 15:50:54,930 Not Found: /static/img/image007.png
WARNING    2018-07-31 15:50:55,001 Not Found: /static/img/image008.png
WARNING    2018-07-31 15:50:55,019 Not Found: /static/img/001.jpg
WARNING    2018-07-31 15:50:55,031 Not Found: /static/img/002.jpg
WARNING    2018-07-31 15:50:55,042 Not Found: /static/img/003.jpg
WARNING    2018-07-31 15:50:55,055 Not Found: /static/img/004.jpg
WARNING    2018-07-31 15:50:55,069 Not Found: /static/img/005.jpg
WARNING    2018-07-31 15:50:55,089 Not Found: /static/img/006.jpg
WARNING    2018-07-31 15:50:55,155 Not Found: /static/img/maestero.png
WARNING    2018-07-31 15:50:55,173 Not Found: /static/img/mastercard.png
WARNING    2018-07-31 15:50:55,190 Not Found: /static/img/aex.png
WARNING    2018-07-31 15:50:55,203 Not Found: /static/img/paypal.png
WARNING    2018-07-31 15:50:55,220 Not Found: /static/img/discover.png
WARNING    2018-07-31 15:50:55,238 Not Found: /static/img/visa_straight.png
WARNING    2018-07-31 15:50:57,235 Not Found: /static/css/bootstrap.min.css
WARNING    2018-07-31 15:50:57,262 Not Found: /static/css/style.css
WARNING    2018-07-31 15:50:57,283 Not Found: /static/css/font-awesome.min.css
WARNING    2018-07-31 15:50:57,299 Not Found: /static/js/jquery-3.2.1.min.js
WARNING    2018-07-31 15:50:57,314 Not Found: /static/js/basket_scripts.js
WARNING    2018-07-31 15:50:58,633 Not Found: /static/css/bootstrap.min.css
WARNING    2018-07-31 15:50:58,660 Not Found: /static/css/font-awesome.min.css
WARNING    2018-07-31 15:50:58,673 Not Found: /static/css/style.css
WARNING    2018-07-31 15:50:58,684 Not Found: /static/img/sunrise_logo.png
WARNING    2018-07-31 15:50:58,696 Not Found: /static/img/image001.png
WARNING    2018-07-31 15:50:58,707 Not Found: /static/img/image002.png
WARNING    2018-07-31 15:50:58,718 Not Found: /static/img/image003.png
WARNING    2018-07-31 15:50:58,812 Not Found: /static/img/image004.png
WARNING    2018-07-31 15:50:58,831 Not Found: /static/img/image005.png
WARNING    2018-07-31 15:50:58,843 Not Found: /static/img/image006.png
WARNING    2018-07-31 15:50:58,862 Not Found: /static/img/image007.png
WARNING    2018-07-31 15:50:58,877 Not Found: /static/img/image008.png
WARNING    2018-07-31 15:50:58,893 Not Found: /static/img/001.jpg
WARNING    2018-07-31 15:50:58,907 Not Found: /static/img/002.jpg
WARNING    2018-07-31 15:50:58,922 Not Found: /static/img/003.jpg
WARNING    2018-07-31 15:50:58,937 Not Found: /static/img/004.jpg
WARNING    2018-07-31 15:50:58,961 Not Found: /static/img/005.jpg
WARNING    2018-07-31 15:50:58,975 Not Found: /static/img/006.jpg
WARNING    2018-07-31 15:50:59,003 Not Found: /static/img/maestero.png
WARNING    2018-07-31 15:50:59,017 Not Found: /static/img/mastercard.png
WARNING    2018-07-31 15:50:59,029 Not Found: /static/img/aex.png
WARNING    2018-07-31 15:50:59,045 Not Found: /static/img/paypal.png
WARNING    2018-07-31 15:50:59,057 Not Found: /static/img/discover.png
WARNING    2018-07-31 15:50:59,078 Not Found: /static/img/visa_straight.png
WARNING    2018-07-31 15:51:02,184 Not Found: /static/css/bootstrap.min.css
WARNING    2018-07-31 15:51:02,243 Not Found: /static/css/font-awesome.min.css
WARNING    2018-07-31 15:51:02,255 Not Found: /static/css/style.css
WARNING    2018-07-31 15:51:02,269 Not Found: /static/img/sunrise_logo.png
WARNING    2018-07-31 15:51:02,285 Not Found: /static/img/image001.png
WARNING    2018-07-31 15:51:02,300 Not Found: /static/img/image002.png
WARNING    2018-07-31 15:51:02,313 Not Found: /static/img/image003.png
WARNING    2018-07-31 15:51:02,376 Not Found: /static/img/image004.png
WARNING    2018-07-31 15:51:02,388 Not Found: /static/img/image005.png
WARNING    2018-07-31 15:51:02,400 Not Found: /static/img/image006.png
WARNING    2018-07-31 15:51:02,414 Not Found: /static/img/image007.png
WARNING    2018-07-31 15:51:02,424 Not Found: /static/img/image008.png
WARNING    2018-07-31 15:51:02,437 Not Found: /static/img/001.jpg
WARNING    2018-07-31 15:51:02,535 Not Found: /static/img/002.jpg
WARNING    2018-07-31 15:51:02,549 Not Found: /static/img/003.jpg
WARNING    2018-07-31 15:51:02,571 Not Found: /static/img/004.jpg
WARNING    2018-07-31 15:51:02,593 Not Found: /static/img/005.jpg
WARNING    2018-07-31 15:51:02,609 Not Found: /static/img/006.jpg
WARNING    2018-07-31 15:51:02,624 Not Found: /static/img/maestero.png
WARNING    2018-07-31 15:51:02,654 Not Found: /static/img/mastercard.png
WARNING    2018-07-31 15:51:02,665 Not Found: /static/img/aex.png
WARNING    2018-07-31 15:51:02,679 Not Found: /static/img/paypal.png
WARNING    2018-07-31 15:51:02,692 Not Found: /static/img/discover.png
WARNING    2018-07-31 15:51:02,704 Not Found: /static/img/visa_straight.png
ERROR      2018-07-31 15:51:07,281 Internal Server Error: /category/
Traceback (most recent call last):
  File "/home/oleg/.local/lib/python3.6/site-packages/django/core/handlers/exception.py", line 35, in inner
    response = get_response(request)
  File "/home/oleg/.local/lib/python3.6/site-packages/django/core/handlers/base.py", line 128, in _get_response
    response = self.process_exception_by_middleware(e, request)
  File "/home/oleg/.local/lib/python3.6/site-packages/django/core/handlers/base.py", line 126, in _get_response
    response = wrapped_callback(request, *callback_args, **callback_kwargs)
  File "/home/oleg/YandexDisk/Python_Lessons/Django/myproject/mainapp/views.py", line 37, in products
    links_menu = ProductCategory.objects.filter(is_active=True)
  File "/home/oleg/.local/lib/python3.6/site-packages/django/db/models/manager.py", line 82, in manager_method
    return getattr(self.get_queryset(), name)(*args, **kwargs)
  File "/home/oleg/.local/lib/python3.6/site-packages/django/db/models/query.py", line 836, in filter
    return self._filter_or_exclude(False, *args, **kwargs)
  File "/home/oleg/.local/lib/python3.6/site-packages/django/db/models/query.py", line 854, in _filter_or_exclude
    clone.query.add_q(Q(*args, **kwargs))
  File "/home/oleg/.local/lib/python3.6/site-packages/django/db/models/sql/query.py", line 1253, in add_q
    clause, _ = self._add_q(q_object, self.used_aliases)
  File "/home/oleg/.local/lib/python3.6/site-packages/django/db/models/sql/query.py", line 1277, in _add_q
    split_subq=split_subq,
  File "/home/oleg/.local/lib/python3.6/site-packages/django/db/models/sql/query.py", line 1153, in build_filter
    lookups, parts, reffed_expression = self.solve_lookup_type(arg)
  File "/home/oleg/.local/lib/python3.6/site-packages/django/db/models/sql/query.py", line 1015, in solve_lookup_type
    _, field, _, lookup_parts = self.names_to_path(lookup_splitted, self.get_meta())
  File "/home/oleg/.local/lib/python3.6/site-packages/django/db/models/sql/query.py", line 1379, in names_to_path
    "Choices are: %s" % (name, ", ".join(available)))
django.core.exceptions.FieldError: Cannot resolve keyword 'is_active' into field. Choices are: description, id, name, product
ERROR      2018-07-31 15:51:49,322 Internal Server Error: /category/
Traceback (most recent call last):
  File "/home/oleg/.local/lib/python3.6/site-packages/django/core/handlers/exception.py", line 35, in inner
    response = get_response(request)
  File "/home/oleg/.local/lib/python3.6/site-packages/django/core/handlers/base.py", line 128, in _get_response
    response = self.process_exception_by_middleware(e, request)
  File "/home/oleg/.local/lib/python3.6/site-packages/django/core/handlers/base.py", line 126, in _get_response
    response = wrapped_callback(request, *callback_args, **callback_kwargs)
  File "/home/oleg/YandexDisk/Python_Lessons/Django/myproject/mainapp/views.py", line 37, in products
    links_menu = ProductCategory.objects.filter(is_active=True)
  File "/home/oleg/.local/lib/python3.6/site-packages/django/db/models/manager.py", line 82, in manager_method
    return getattr(self.get_queryset(), name)(*args, **kwargs)
  File "/home/oleg/.local/lib/python3.6/site-packages/django/db/models/query.py", line 836, in filter
    return self._filter_or_exclude(False, *args, **kwargs)
  File "/home/oleg/.local/lib/python3.6/site-packages/django/db/models/query.py", line 854, in _filter_or_exclude
    clone.query.add_q(Q(*args, **kwargs))
  File "/home/oleg/.local/lib/python3.6/site-packages/django/db/models/sql/query.py", line 1253, in add_q
    clause, _ = self._add_q(q_object, self.used_aliases)
  File "/home/oleg/.local/lib/python3.6/site-packages/django/db/models/sql/query.py", line 1277, in _add_q
    split_subq=split_subq,
  File "/home/oleg/.local/lib/python3.6/site-packages/django/db/models/sql/query.py", line 1153, in build_filter
    lookups, parts, reffed_expression = self.solve_lookup_type(arg)
  File "/home/oleg/.local/lib/python3.6/site-packages/django/db/models/sql/query.py", line 1015, in solve_lookup_type
    _, field, _, lookup_parts = self.names_to_path(lookup_splitted, self.get_meta())
  File "/home/oleg/.local/lib/python3.6/site-packages/django/db/models/sql/query.py", line 1379, in names_to_path
    "Choices are: %s" % (name, ", ".join(available)))
django.core.exceptions.FieldError: Cannot resolve keyword 'is_active' into field. Choices are: description, id, name, product
ERROR      2018-07-31 16:09:10,743 Internal Server Error: /category/
Traceback (most recent call last):
  File "/home/oleg/.local/lib/python3.6/site-packages/django/db/backends/utils.py", line 85, in _execute
    return self.cursor.execute(sql, params)
psycopg2.ProgrammingError: column mainapp_productcategory.is_active does not exist
LINE 1: ...."name", "mainapp_productcategory"."description", "mainapp_p...
                                                             ^


The above exception was the direct cause of the following exception:

Traceback (most recent call last):
  File "/home/oleg/.local/lib/python3.6/site-packages/django/core/handlers/exception.py", line 35, in inner
    response = get_response(request)
  File "/home/oleg/.local/lib/python3.6/site-packages/django/core/handlers/base.py", line 128, in _get_response
    response = self.process_exception_by_middleware(e, request)
  File "/home/oleg/.local/lib/python3.6/site-packages/django/core/handlers/base.py", line 126, in _get_response
    response = wrapped_callback(request, *callback_args, **callback_kwargs)
  File "/home/oleg/YandexDisk/Python_Lessons/Django/myproject/mainapp/views.py", line 79, in products
    return render(request, 'mainapp/products_list.html', context)
  File "/home/oleg/.local/lib/python3.6/site-packages/django/shortcuts.py", line 36, in render
    content = loader.render_to_string(template_name, context, request, using=using)
  File "/home/oleg/.local/lib/python3.6/site-packages/django/template/loader.py", line 62, in render_to_string
    return template.render(context, request)
  File "/home/oleg/.local/lib/python3.6/site-packages/django/template/backends/django.py", line 61, in render
    return self.template.render(context)
  File "/home/oleg/.local/lib/python3.6/site-packages/django/template/base.py", line 175, in render
    return self._render(context)
  File "/home/oleg/.local/lib/python3.6/site-packages/django/template/base.py", line 167, in _render
    return self.nodelist.render(context)
  File "/home/oleg/.local/lib/python3.6/site-packages/django/template/base.py", line 943, in render
    bit = node.render_annotated(context)
  File "/home/oleg/.local/lib/python3.6/site-packages/django/template/base.py", line 910, in render_annotated
    return self.render(context)
  File "/home/oleg/.local/lib/python3.6/site-packages/django/template/loader_tags.py", line 155, in render
    return compiled_parent._render(context)
  File "/home/oleg/.local/lib/python3.6/site-packages/django/template/base.py", line 167, in _render
    return self.nodelist.render(context)
  File "/home/oleg/.local/lib/python3.6/site-packages/django/template/base.py", line 943, in render
    bit = node.render_annotated(context)
  File "/home/oleg/.local/lib/python3.6/site-packages/django/template/base.py", line 910, in render_annotated
    return self.render(context)
  File "/home/oleg/.local/lib/python3.6/site-packages/django/template/loader_tags.py", line 194, in render
    return template.render(context)
  File "/home/oleg/.local/lib/python3.6/site-packages/django/template/base.py", line 177, in render
    return self._render(context)
  File "/home/oleg/.local/lib/python3.6/site-packages/django/template/base.py", line 167, in _render
    return self.nodelist.render(context)
  File "/home/oleg/.local/lib/python3.6/site-packages/django/template/base.py", line 943, in render
    bit = node.render_annotated(context)
  File "/home/oleg/.local/lib/python3.6/site-packages/django/template/base.py", line 910, in render_annotated
    return self.render(context)
  File "/home/oleg/.local/lib/python3.6/site-packages/django/template/defaulttags.py", line 168, in render
    len_values = len(values)
  File "/home/oleg/.local/lib/python3.6/site-packages/django/db/models/query.py", line 254, in __len__
    self._fetch_all()
  File "/home/oleg/.local/lib/python3.6/site-packages/django/db/models/query.py", line 1179, in _fetch_all
    self._result_cache = list(self._iterable_class(self))
  File "/home/oleg/.local/lib/python3.6/site-packages/django/db/models/query.py", line 53, in __iter__
    results = compiler.execute_sql(chunked_fetch=self.chunked_fetch, chunk_size=self.chunk_size)
  File "/home/oleg/.local/lib/python3.6/site-packages/django/db/models/sql/compiler.py", line 1068, in execute_sql
    cursor.execute(sql, params)
  File "/home/oleg/.local/lib/python3.6/site-packages/django/db/backends/utils.py", line 100, in execute
    return super().execute(sql, params)
  File "/home/oleg/.local/lib/python3.6/site-packages/django/db/backends/utils.py", line 68, in execute
    return self._execute_with_wrappers(sql, params, many=False, executor=self._execute)
  File "/home/oleg/.local/lib/python3.6/site-packages/django/db/backends/utils.py", line 77, in _execute_with_wrappers
    return executor(sql, params, many, context)
  File "/home/oleg/.local/lib/python3.6/site-packages/django/db/backends/utils.py", line 85, in _execute
    return self.cursor.execute(sql, params)
  File "/home/oleg/.local/lib/python3.6/site-packages/django/db/utils.py", line 89, in __exit__
    raise dj_exc_value.with_traceback(traceback) from exc_value
  File "/home/oleg/.local/lib/python3.6/site-packages/django/db/backends/utils.py", line 85, in _execute
    return self.cursor.execute(sql, params)
django.db.utils.ProgrammingError: column mainapp_productcategory.is_active does not exist
LINE 1: ...."name", "mainapp_productcategory"."description", "mainapp_p...
                                                             ^

ERROR      2018-07-31 16:09:20,001 Internal Server Error: /category/
Traceback (most recent call last):
  File "/home/oleg/.local/lib/python3.6/site-packages/django/db/backends/utils.py", line 85, in _execute
    return self.cursor.execute(sql, params)
psycopg2.ProgrammingError: column mainapp_productcategory.is_active does not exist
LINE 1: ...."name", "mainapp_productcategory"."description", "mainapp_p...
                                                             ^


The above exception was the direct cause of the following exception:

Traceback (most recent call last):
  File "/home/oleg/.local/lib/python3.6/site-packages/django/core/handlers/exception.py", line 35, in inner
    response = get_response(request)
  File "/home/oleg/.local/lib/python3.6/site-packages/django/core/handlers/base.py", line 128, in _get_response
    response = self.process_exception_by_middleware(e, request)
  File "/home/oleg/.local/lib/python3.6/site-packages/django/core/handlers/base.py", line 126, in _get_response
    response = wrapped_callback(request, *callback_args, **callback_kwargs)
  File "/home/oleg/YandexDisk/Python_Lessons/Django/myproject/mainapp/views.py", line 79, in products
    return render(request, 'mainapp/products_list.html', context)
  File "/home/oleg/.local/lib/python3.6/site-packages/django/shortcuts.py", line 36, in render
    content = loader.render_to_string(template_name, context, request, using=using)
  File "/home/oleg/.local/lib/python3.6/site-packages/django/template/loader.py", line 62, in render_to_string
    return template.render(context, request)
  File "/home/oleg/.local/lib/python3.6/site-packages/django/template/backends/django.py", line 61, in render
    return self.template.render(context)
  File "/home/oleg/.local/lib/python3.6/site-packages/django/template/base.py", line 175, in render
    return self._render(context)
  File "/home/oleg/.local/lib/python3.6/site-packages/django/template/base.py", line 167, in _render
    return self.nodelist.render(context)
  File "/home/oleg/.local/lib/python3.6/site-packages/django/template/base.py", line 943, in render
    bit = node.render_annotated(context)
  File "/home/oleg/.local/lib/python3.6/site-packages/django/template/base.py", line 910, in render_annotated
    return self.render(context)
  File "/home/oleg/.local/lib/python3.6/site-packages/django/template/loader_tags.py", line 155, in render
    return compiled_parent._render(context)
  File "/home/oleg/.local/lib/python3.6/site-packages/django/template/base.py", line 167, in _render
    return self.nodelist.render(context)
  File "/home/oleg/.local/lib/python3.6/site-packages/django/template/base.py", line 943, in render
    bit = node.render_annotated(context)
  File "/home/oleg/.local/lib/python3.6/site-packages/django/template/base.py", line 910, in render_annotated
    return self.render(context)
  File "/home/oleg/.local/lib/python3.6/site-packages/django/template/loader_tags.py", line 194, in render
    return template.render(context)
  File "/home/oleg/.local/lib/python3.6/site-packages/django/template/base.py", line 177, in render
    return self._render(context)
  File "/home/oleg/.local/lib/python3.6/site-packages/django/template/base.py", line 167, in _render
    return self.nodelist.render(context)
  File "/home/oleg/.local/lib/python3.6/site-packages/django/template/base.py", line 943, in render
    bit = node.render_annotated(context)
  File "/home/oleg/.local/lib/python3.6/site-packages/django/template/base.py", line 910, in render_annotated
    return self.render(context)
  File "/home/oleg/.local/lib/python3.6/site-packages/django/template/defaulttags.py", line 168, in render
    len_values = len(values)
  File "/home/oleg/.local/lib/python3.6/site-packages/django/db/models/query.py", line 254, in __len__
    self._fetch_all()
  File "/home/oleg/.local/lib/python3.6/site-packages/django/db/models/query.py", line 1179, in _fetch_all
    self._result_cache = list(self._iterable_class(self))
  File "/home/oleg/.local/lib/python3.6/site-packages/django/db/models/query.py", line 53, in __iter__
    results = compiler.execute_sql(chunked_fetch=self.chunked_fetch, chunk_size=self.chunk_size)
  File "/home/oleg/.local/lib/python3.6/site-packages/django/db/models/sql/compiler.py", line 1068, in execute_sql
    cursor.execute(sql, params)
  File "/home/oleg/.local/lib/python3.6/site-packages/django/db/backends/utils.py", line 100, in execute
    return super().execute(sql, params)
  File "/home/oleg/.local/lib/python3.6/site-packages/django/db/backends/utils.py", line 68, in execute
    return self._execute_with_wrappers(sql, params, many=False, executor=self._execute)
  File "/home/oleg/.local/lib/python3.6/site-packages/django/db/backends/utils.py", line 77, in _execute_with_wrappers
    return executor(sql, params, many, context)
  File "/home/oleg/.local/lib/python3.6/site-packages/django/db/backends/utils.py", line 85, in _execute
    return self.cursor.execute(sql, params)
  File "/home/oleg/.local/lib/python3.6/site-packages/django/db/utils.py", line 89, in __exit__
    raise dj_exc_value.with_traceback(traceback) from exc_value
  File "/home/oleg/.local/lib/python3.6/site-packages/django/db/backends/utils.py", line 85, in _execute
    return self.cursor.execute(sql, params)
django.db.utils.ProgrammingError: column mainapp_productcategory.is_active does not exist
LINE 1: ...."name", "mainapp_productcategory"."description", "mainapp_p...
                                                             ^

WARNING    2018-08-03 12:52:35,989 Not Found: /media/
WARNING    2018-08-03 12:52:49,674 Not Found: /media/
