ERROR      2018-07-29 15:58:39,544 Internal Server Error: /
Traceback (most recent call last):
  File "/usr/local/lib/python3.6/dist-packages/django/core/handlers/exception.py", line 35, in inner
    response = get_response(request)
  File "/usr/local/lib/python3.6/dist-packages/django/core/handlers/base.py", line 128, in _get_response
    response = self.process_exception_by_middleware(e, request)
  File "/usr/local/lib/python3.6/dist-packages/django/core/handlers/base.py", line 126, in _get_response
    response = wrapped_callback(request, *callback_args, **callback_kwargs)
  File "/home/oleg/git/mainapp/views.py", line 17, in main
    return render(request, 'mainapp/base.html', content)
  File "/usr/local/lib/python3.6/dist-packages/django/shortcuts.py", line 36, in render
    content = loader.render_to_string(template_name, context, request, using=using)
  File "/usr/local/lib/python3.6/dist-packages/django/template/loader.py", line 62, in render_to_string
    return template.render(context, request)
  File "/usr/local/lib/python3.6/dist-packages/django/template/backends/django.py", line 61, in render
    return self.template.render(context)
  File "/usr/local/lib/python3.6/dist-packages/django/template/base.py", line 175, in render
    return self._render(context)
  File "/usr/local/lib/python3.6/dist-packages/django/template/base.py", line 167, in _render
    return self.nodelist.render(context)
  File "/usr/local/lib/python3.6/dist-packages/django/template/base.py", line 943, in render
    bit = node.render_annotated(context)
  File "/usr/local/lib/python3.6/dist-packages/django/template/base.py", line 910, in render_annotated
    return self.render(context)
  File "/usr/local/lib/python3.6/dist-packages/django/template/loader_tags.py", line 194, in render
    return template.render(context)
  File "/usr/local/lib/python3.6/dist-packages/django/template/base.py", line 177, in render
    return self._render(context)
  File "/usr/local/lib/python3.6/dist-packages/django/template/base.py", line 167, in _render
    return self.nodelist.render(context)
  File "/usr/local/lib/python3.6/dist-packages/django/template/base.py", line 943, in render
    bit = node.render_annotated(context)
  File "/usr/local/lib/python3.6/dist-packages/django/template/base.py", line 910, in render_annotated
    return self.render(context)
  File "/usr/local/lib/python3.6/dist-packages/django/template/defaulttags.py", line 447, in render
    url = reverse(view_name, args=args, kwargs=kwargs, current_app=current_app)
  File "/usr/local/lib/python3.6/dist-packages/django/urls/base.py", line 88, in reverse
    return iri_to_uri(resolver._reverse_with_prefix(view, prefix, *args, **kwargs))
  File "/usr/local/lib/python3.6/dist-packages/django/urls/resolvers.py", line 632, in _reverse_with_prefix
    raise NoReverseMatch(msg)
django.urls.exceptions.NoReverseMatch: Reverse for 'category' not found. 'category' is not a valid view function or pattern name.
ERROR      2018-07-29 15:59:43,572 Internal Server Error: /
Traceback (most recent call last):
  File "/usr/local/lib/python3.6/dist-packages/django/core/handlers/exception.py", line 35, in inner
    response = get_response(request)
  File "/usr/local/lib/python3.6/dist-packages/django/core/handlers/base.py", line 128, in _get_response
    response = self.process_exception_by_middleware(e, request)
  File "/usr/local/lib/python3.6/dist-packages/django/core/handlers/base.py", line 126, in _get_response
    response = wrapped_callback(request, *callback_args, **callback_kwargs)
  File "/home/oleg/git/mainapp/views.py", line 17, in main
    return render(request, 'mainapp/base.html', content)
  File "/usr/local/lib/python3.6/dist-packages/django/shortcuts.py", line 36, in render
    content = loader.render_to_string(template_name, context, request, using=using)
  File "/usr/local/lib/python3.6/dist-packages/django/template/loader.py", line 62, in render_to_string
    return template.render(context, request)
  File "/usr/local/lib/python3.6/dist-packages/django/template/backends/django.py", line 61, in render
    return self.template.render(context)
  File "/usr/local/lib/python3.6/dist-packages/django/template/base.py", line 175, in render
    return self._render(context)
  File "/usr/local/lib/python3.6/dist-packages/django/template/base.py", line 167, in _render
    return self.nodelist.render(context)
  File "/usr/local/lib/python3.6/dist-packages/django/template/base.py", line 943, in render
    bit = node.render_annotated(context)
  File "/usr/local/lib/python3.6/dist-packages/django/template/base.py", line 910, in render_annotated
    return self.render(context)
  File "/usr/local/lib/python3.6/dist-packages/django/template/loader_tags.py", line 194, in render
    return template.render(context)
  File "/usr/local/lib/python3.6/dist-packages/django/template/base.py", line 177, in render
    return self._render(context)
  File "/usr/local/lib/python3.6/dist-packages/django/template/base.py", line 167, in _render
    return self.nodelist.render(context)
  File "/usr/local/lib/python3.6/dist-packages/django/template/base.py", line 943, in render
    bit = node.render_annotated(context)
  File "/usr/local/lib/python3.6/dist-packages/django/template/base.py", line 910, in render_annotated
    return self.render(context)
  File "/usr/local/lib/python3.6/dist-packages/django/template/defaulttags.py", line 447, in render
    url = reverse(view_name, args=args, kwargs=kwargs, current_app=current_app)
  File "/usr/local/lib/python3.6/dist-packages/django/urls/base.py", line 88, in reverse
    return iri_to_uri(resolver._reverse_with_prefix(view, prefix, *args, **kwargs))
  File "/usr/local/lib/python3.6/dist-packages/django/urls/resolvers.py", line 632, in _reverse_with_prefix
    raise NoReverseMatch(msg)
django.urls.exceptions.NoReverseMatch: Reverse for 'category' with no arguments not found. 1 pattern(s) tried: ['category\\/\\((?P<pk>[0-9]+)\\)\\/page\\/\\((?P<page>[0-9]+)\\)\\/$']
ERROR      2018-07-29 16:01:15,139 Internal Server Error: /
Traceback (most recent call last):
  File "/usr/local/lib/python3.6/dist-packages/django/urls/base.py", line 74, in reverse
    extra, resolver = resolver.namespace_dict[ns]
KeyError: 'auth'

During handling of the above exception, another exception occurred:

Traceback (most recent call last):
  File "/usr/local/lib/python3.6/dist-packages/django/core/handlers/exception.py", line 35, in inner
    response = get_response(request)
  File "/usr/local/lib/python3.6/dist-packages/django/core/handlers/base.py", line 128, in _get_response
    response = self.process_exception_by_middleware(e, request)
  File "/usr/local/lib/python3.6/dist-packages/django/core/handlers/base.py", line 126, in _get_response
    response = wrapped_callback(request, *callback_args, **callback_kwargs)
  File "/home/oleg/git/mainapp/views.py", line 17, in main
    return render(request, 'mainapp/base.html', content)
  File "/usr/local/lib/python3.6/dist-packages/django/shortcuts.py", line 36, in render
    content = loader.render_to_string(template_name, context, request, using=using)
  File "/usr/local/lib/python3.6/dist-packages/django/template/loader.py", line 62, in render_to_string
    return template.render(context, request)
  File "/usr/local/lib/python3.6/dist-packages/django/template/backends/django.py", line 61, in render
    return self.template.render(context)
  File "/usr/local/lib/python3.6/dist-packages/django/template/base.py", line 175, in render
    return self._render(context)
  File "/usr/local/lib/python3.6/dist-packages/django/template/base.py", line 167, in _render
    return self.nodelist.render(context)
  File "/usr/local/lib/python3.6/dist-packages/django/template/base.py", line 943, in render
    bit = node.render_annotated(context)
  File "/usr/local/lib/python3.6/dist-packages/django/template/base.py", line 910, in render_annotated
    return self.render(context)
  File "/usr/local/lib/python3.6/dist-packages/django/template/loader_tags.py", line 194, in render
    return template.render(context)
  File "/usr/local/lib/python3.6/dist-packages/django/template/base.py", line 177, in render
    return self._render(context)
  File "/usr/local/lib/python3.6/dist-packages/django/template/base.py", line 167, in _render
    return self.nodelist.render(context)
  File "/usr/local/lib/python3.6/dist-packages/django/template/base.py", line 943, in render
    bit = node.render_annotated(context)
  File "/usr/local/lib/python3.6/dist-packages/django/template/base.py", line 910, in render_annotated
    return self.render(context)
  File "/usr/local/lib/python3.6/dist-packages/django/template/defaulttags.py", line 314, in render
    return nodelist.render(context)
  File "/usr/local/lib/python3.6/dist-packages/django/template/base.py", line 943, in render
    bit = node.render_annotated(context)
  File "/usr/local/lib/python3.6/dist-packages/django/template/base.py", line 910, in render_annotated
    return self.render(context)
  File "/usr/local/lib/python3.6/dist-packages/django/template/defaulttags.py", line 447, in render
    url = reverse(view_name, args=args, kwargs=kwargs, current_app=current_app)
  File "/usr/local/lib/python3.6/dist-packages/django/urls/base.py", line 84, in reverse
    raise NoReverseMatch("%s is not a registered namespace" % key)
django.urls.exceptions.NoReverseMatch: 'auth' is not a registered namespace
ERROR      2018-07-29 16:02:55,750 Internal Server Error: /
Traceback (most recent call last):
  File "/usr/local/lib/python3.6/dist-packages/django/urls/base.py", line 74, in reverse
    extra, resolver = resolver.namespace_dict[ns]
KeyError: 'auth'

During handling of the above exception, another exception occurred:

Traceback (most recent call last):
  File "/usr/local/lib/python3.6/dist-packages/django/core/handlers/exception.py", line 35, in inner
    response = get_response(request)
  File "/usr/local/lib/python3.6/dist-packages/django/core/handlers/base.py", line 128, in _get_response
    response = self.process_exception_by_middleware(e, request)
  File "/usr/local/lib/python3.6/dist-packages/django/core/handlers/base.py", line 126, in _get_response
    response = wrapped_callback(request, *callback_args, **callback_kwargs)
  File "/home/oleg/git/mainapp/views.py", line 17, in main
    return render(request, 'mainapp/base.html', content)
  File "/usr/local/lib/python3.6/dist-packages/django/shortcuts.py", line 36, in render
    content = loader.render_to_string(template_name, context, request, using=using)
  File "/usr/local/lib/python3.6/dist-packages/django/template/loader.py", line 62, in render_to_string
    return template.render(context, request)
  File "/usr/local/lib/python3.6/dist-packages/django/template/backends/django.py", line 61, in render
    return self.template.render(context)
  File "/usr/local/lib/python3.6/dist-packages/django/template/base.py", line 175, in render
    return self._render(context)
  File "/usr/local/lib/python3.6/dist-packages/django/template/base.py", line 167, in _render
    return self.nodelist.render(context)
  File "/usr/local/lib/python3.6/dist-packages/django/template/base.py", line 943, in render
    bit = node.render_annotated(context)
  File "/usr/local/lib/python3.6/dist-packages/django/template/base.py", line 910, in render_annotated
    return self.render(context)
  File "/usr/local/lib/python3.6/dist-packages/django/template/loader_tags.py", line 194, in render
    return template.render(context)
  File "/usr/local/lib/python3.6/dist-packages/django/template/base.py", line 177, in render
    return self._render(context)
  File "/usr/local/lib/python3.6/dist-packages/django/template/base.py", line 167, in _render
    return self.nodelist.render(context)
  File "/usr/local/lib/python3.6/dist-packages/django/template/base.py", line 943, in render
    bit = node.render_annotated(context)
  File "/usr/local/lib/python3.6/dist-packages/django/template/base.py", line 910, in render_annotated
    return self.render(context)
  File "/usr/local/lib/python3.6/dist-packages/django/template/defaulttags.py", line 314, in render
    return nodelist.render(context)
  File "/usr/local/lib/python3.6/dist-packages/django/template/base.py", line 943, in render
    bit = node.render_annotated(context)
  File "/usr/local/lib/python3.6/dist-packages/django/template/base.py", line 910, in render_annotated
    return self.render(context)
  File "/usr/local/lib/python3.6/dist-packages/django/template/defaulttags.py", line 447, in render
    url = reverse(view_name, args=args, kwargs=kwargs, current_app=current_app)
  File "/usr/local/lib/python3.6/dist-packages/django/urls/base.py", line 84, in reverse
    raise NoReverseMatch("%s is not a registered namespace" % key)
django.urls.exceptions.NoReverseMatch: 'auth' is not a registered namespace
ERROR      2018-07-29 16:27:10,291 Internal Server Error: /
Traceback (most recent call last):
  File "/usr/local/lib/python3.6/dist-packages/django/urls/base.py", line 74, in reverse
    extra, resolver = resolver.namespace_dict[ns]
KeyError: 'auth'

During handling of the above exception, another exception occurred:

Traceback (most recent call last):
  File "/usr/local/lib/python3.6/dist-packages/django/core/handlers/exception.py", line 35, in inner
    response = get_response(request)
  File "/usr/local/lib/python3.6/dist-packages/django/core/handlers/base.py", line 128, in _get_response
    response = self.process_exception_by_middleware(e, request)
  File "/usr/local/lib/python3.6/dist-packages/django/core/handlers/base.py", line 126, in _get_response
    response = wrapped_callback(request, *callback_args, **callback_kwargs)
  File "/home/oleg/git/mainapp/views.py", line 17, in main
    return render(request, 'mainapp/base.html', content)
  File "/usr/local/lib/python3.6/dist-packages/django/shortcuts.py", line 36, in render
    content = loader.render_to_string(template_name, context, request, using=using)
  File "/usr/local/lib/python3.6/dist-packages/django/template/loader.py", line 62, in render_to_string
    return template.render(context, request)
  File "/usr/local/lib/python3.6/dist-packages/django/template/backends/django.py", line 61, in render
    return self.template.render(context)
  File "/usr/local/lib/python3.6/dist-packages/django/template/base.py", line 175, in render
    return self._render(context)
  File "/usr/local/lib/python3.6/dist-packages/django/template/base.py", line 167, in _render
    return self.nodelist.render(context)
  File "/usr/local/lib/python3.6/dist-packages/django/template/base.py", line 943, in render
    bit = node.render_annotated(context)
  File "/usr/local/lib/python3.6/dist-packages/django/template/base.py", line 910, in render_annotated
    return self.render(context)
  File "/usr/local/lib/python3.6/dist-packages/django/template/loader_tags.py", line 194, in render
    return template.render(context)
  File "/usr/local/lib/python3.6/dist-packages/django/template/base.py", line 177, in render
    return self._render(context)
  File "/usr/local/lib/python3.6/dist-packages/django/template/base.py", line 167, in _render
    return self.nodelist.render(context)
  File "/usr/local/lib/python3.6/dist-packages/django/template/base.py", line 943, in render
    bit = node.render_annotated(context)
  File "/usr/local/lib/python3.6/dist-packages/django/template/base.py", line 910, in render_annotated
    return self.render(context)
  File "/usr/local/lib/python3.6/dist-packages/django/template/defaulttags.py", line 314, in render
    return nodelist.render(context)
  File "/usr/local/lib/python3.6/dist-packages/django/template/base.py", line 943, in render
    bit = node.render_annotated(context)
  File "/usr/local/lib/python3.6/dist-packages/django/template/base.py", line 910, in render_annotated
    return self.render(context)
  File "/usr/local/lib/python3.6/dist-packages/django/template/defaulttags.py", line 447, in render
    url = reverse(view_name, args=args, kwargs=kwargs, current_app=current_app)
  File "/usr/local/lib/python3.6/dist-packages/django/urls/base.py", line 84, in reverse
    raise NoReverseMatch("%s is not a registered namespace" % key)
django.urls.exceptions.NoReverseMatch: 'auth' is not a registered namespace
ERROR      2018-07-29 16:27:16,262 Internal Server Error: /
Traceback (most recent call last):
  File "/usr/local/lib/python3.6/dist-packages/django/urls/base.py", line 74, in reverse
    extra, resolver = resolver.namespace_dict[ns]
KeyError: 'auth'

During handling of the above exception, another exception occurred:

Traceback (most recent call last):
  File "/usr/local/lib/python3.6/dist-packages/django/core/handlers/exception.py", line 35, in inner
    response = get_response(request)
  File "/usr/local/lib/python3.6/dist-packages/django/core/handlers/base.py", line 128, in _get_response
    response = self.process_exception_by_middleware(e, request)
  File "/usr/local/lib/python3.6/dist-packages/django/core/handlers/base.py", line 126, in _get_response
    response = wrapped_callback(request, *callback_args, **callback_kwargs)
  File "/home/oleg/git/mainapp/views.py", line 17, in main
    return render(request, 'mainapp/base.html', content)
  File "/usr/local/lib/python3.6/dist-packages/django/shortcuts.py", line 36, in render
    content = loader.render_to_string(template_name, context, request, using=using)
  File "/usr/local/lib/python3.6/dist-packages/django/template/loader.py", line 62, in render_to_string
    return template.render(context, request)
  File "/usr/local/lib/python3.6/dist-packages/django/template/backends/django.py", line 61, in render
    return self.template.render(context)
  File "/usr/local/lib/python3.6/dist-packages/django/template/base.py", line 175, in render
    return self._render(context)
  File "/usr/local/lib/python3.6/dist-packages/django/template/base.py", line 167, in _render
    return self.nodelist.render(context)
  File "/usr/local/lib/python3.6/dist-packages/django/template/base.py", line 943, in render
    bit = node.render_annotated(context)
  File "/usr/local/lib/python3.6/dist-packages/django/template/base.py", line 910, in render_annotated
    return self.render(context)
  File "/usr/local/lib/python3.6/dist-packages/django/template/loader_tags.py", line 194, in render
    return template.render(context)
  File "/usr/local/lib/python3.6/dist-packages/django/template/base.py", line 177, in render
    return self._render(context)
  File "/usr/local/lib/python3.6/dist-packages/django/template/base.py", line 167, in _render
    return self.nodelist.render(context)
  File "/usr/local/lib/python3.6/dist-packages/django/template/base.py", line 943, in render
    bit = node.render_annotated(context)
  File "/usr/local/lib/python3.6/dist-packages/django/template/base.py", line 910, in render_annotated
    return self.render(context)
  File "/usr/local/lib/python3.6/dist-packages/django/template/defaulttags.py", line 314, in render
    return nodelist.render(context)
  File "/usr/local/lib/python3.6/dist-packages/django/template/base.py", line 943, in render
    bit = node.render_annotated(context)
  File "/usr/local/lib/python3.6/dist-packages/django/template/base.py", line 910, in render_annotated
    return self.render(context)
  File "/usr/local/lib/python3.6/dist-packages/django/template/defaulttags.py", line 447, in render
    url = reverse(view_name, args=args, kwargs=kwargs, current_app=current_app)
  File "/usr/local/lib/python3.6/dist-packages/django/urls/base.py", line 84, in reverse
    raise NoReverseMatch("%s is not a registered namespace" % key)
django.urls.exceptions.NoReverseMatch: 'auth' is not a registered namespace
ERROR      2018-07-29 16:35:28,912 Internal Server Error: /
Traceback (most recent call last):
  File "/usr/local/lib/python3.6/dist-packages/django/urls/base.py", line 74, in reverse
    extra, resolver = resolver.namespace_dict[ns]
KeyError: 'contacts'

During handling of the above exception, another exception occurred:

Traceback (most recent call last):
  File "/usr/local/lib/python3.6/dist-packages/django/core/handlers/exception.py", line 35, in inner
    response = get_response(request)
  File "/usr/local/lib/python3.6/dist-packages/django/core/handlers/base.py", line 128, in _get_response
    response = self.process_exception_by_middleware(e, request)
  File "/usr/local/lib/python3.6/dist-packages/django/core/handlers/base.py", line 126, in _get_response
    response = wrapped_callback(request, *callback_args, **callback_kwargs)
  File "/home/oleg/git/mainapp/views.py", line 17, in main
    return render(request, 'mainapp/base.html', content)
  File "/usr/local/lib/python3.6/dist-packages/django/shortcuts.py", line 36, in render
    content = loader.render_to_string(template_name, context, request, using=using)
  File "/usr/local/lib/python3.6/dist-packages/django/template/loader.py", line 62, in render_to_string
    return template.render(context, request)
  File "/usr/local/lib/python3.6/dist-packages/django/template/backends/django.py", line 61, in render
    return self.template.render(context)
  File "/usr/local/lib/python3.6/dist-packages/django/template/base.py", line 175, in render
    return self._render(context)
  File "/usr/local/lib/python3.6/dist-packages/django/template/base.py", line 167, in _render
    return self.nodelist.render(context)
  File "/usr/local/lib/python3.6/dist-packages/django/template/base.py", line 943, in render
    bit = node.render_annotated(context)
  File "/usr/local/lib/python3.6/dist-packages/django/template/base.py", line 910, in render_annotated
    return self.render(context)
  File "/usr/local/lib/python3.6/dist-packages/django/template/loader_tags.py", line 194, in render
    return template.render(context)
  File "/usr/local/lib/python3.6/dist-packages/django/template/base.py", line 177, in render
    return self._render(context)
  File "/usr/local/lib/python3.6/dist-packages/django/template/base.py", line 167, in _render
    return self.nodelist.render(context)
  File "/usr/local/lib/python3.6/dist-packages/django/template/base.py", line 943, in render
    bit = node.render_annotated(context)
  File "/usr/local/lib/python3.6/dist-packages/django/template/base.py", line 910, in render_annotated
    return self.render(context)
  File "/usr/local/lib/python3.6/dist-packages/django/template/defaulttags.py", line 447, in render
    url = reverse(view_name, args=args, kwargs=kwargs, current_app=current_app)
  File "/usr/local/lib/python3.6/dist-packages/django/urls/base.py", line 84, in reverse
    raise NoReverseMatch("%s is not a registered namespace" % key)
django.urls.exceptions.NoReverseMatch: 'contacts' is not a registered namespace
ERROR      2018-07-29 16:36:31,295 Internal Server Error: /
Traceback (most recent call last):
  File "/usr/local/lib/python3.6/dist-packages/django/urls/base.py", line 74, in reverse
    extra, resolver = resolver.namespace_dict[ns]
KeyError: 'contacts'

During handling of the above exception, another exception occurred:

Traceback (most recent call last):
  File "/usr/local/lib/python3.6/dist-packages/django/core/handlers/exception.py", line 35, in inner
    response = get_response(request)
  File "/usr/local/lib/python3.6/dist-packages/django/core/handlers/base.py", line 128, in _get_response
    response = self.process_exception_by_middleware(e, request)
  File "/usr/local/lib/python3.6/dist-packages/django/core/handlers/base.py", line 126, in _get_response
    response = wrapped_callback(request, *callback_args, **callback_kwargs)
  File "/home/oleg/git/mainapp/views.py", line 17, in main
    return render(request, 'mainapp/base.html', content)
  File "/usr/local/lib/python3.6/dist-packages/django/shortcuts.py", line 36, in render
    content = loader.render_to_string(template_name, context, request, using=using)
  File "/usr/local/lib/python3.6/dist-packages/django/template/loader.py", line 62, in render_to_string
    return template.render(context, request)
  File "/usr/local/lib/python3.6/dist-packages/django/template/backends/django.py", line 61, in render
    return self.template.render(context)
  File "/usr/local/lib/python3.6/dist-packages/django/template/base.py", line 175, in render
    return self._render(context)
  File "/usr/local/lib/python3.6/dist-packages/django/template/base.py", line 167, in _render
    return self.nodelist.render(context)
  File "/usr/local/lib/python3.6/dist-packages/django/template/base.py", line 943, in render
    bit = node.render_annotated(context)
  File "/usr/local/lib/python3.6/dist-packages/django/template/base.py", line 910, in render_annotated
    return self.render(context)
  File "/usr/local/lib/python3.6/dist-packages/django/template/loader_tags.py", line 194, in render
    return template.render(context)
  File "/usr/local/lib/python3.6/dist-packages/django/template/base.py", line 177, in render
    return self._render(context)
  File "/usr/local/lib/python3.6/dist-packages/django/template/base.py", line 167, in _render
    return self.nodelist.render(context)
  File "/usr/local/lib/python3.6/dist-packages/django/template/base.py", line 943, in render
    bit = node.render_annotated(context)
  File "/usr/local/lib/python3.6/dist-packages/django/template/base.py", line 910, in render_annotated
    return self.render(context)
  File "/usr/local/lib/python3.6/dist-packages/django/template/defaulttags.py", line 447, in render
    url = reverse(view_name, args=args, kwargs=kwargs, current_app=current_app)
  File "/usr/local/lib/python3.6/dist-packages/django/urls/base.py", line 84, in reverse
    raise NoReverseMatch("%s is not a registered namespace" % key)
django.urls.exceptions.NoReverseMatch: 'contacts' is not a registered namespace
ERROR      2018-07-29 16:37:12,975 Internal Server Error: /
Traceback (most recent call last):
  File "/usr/local/lib/python3.6/dist-packages/django/urls/base.py", line 74, in reverse
    extra, resolver = resolver.namespace_dict[ns]
KeyError: 'basket'

During handling of the above exception, another exception occurred:

Traceback (most recent call last):
  File "/usr/local/lib/python3.6/dist-packages/django/core/handlers/exception.py", line 35, in inner
    response = get_response(request)
  File "/usr/local/lib/python3.6/dist-packages/django/core/handlers/base.py", line 128, in _get_response
    response = self.process_exception_by_middleware(e, request)
  File "/usr/local/lib/python3.6/dist-packages/django/core/handlers/base.py", line 126, in _get_response
    response = wrapped_callback(request, *callback_args, **callback_kwargs)
  File "/home/oleg/git/mainapp/views.py", line 17, in main
    return render(request, 'mainapp/base.html', content)
  File "/usr/local/lib/python3.6/dist-packages/django/shortcuts.py", line 36, in render
    content = loader.render_to_string(template_name, context, request, using=using)
  File "/usr/local/lib/python3.6/dist-packages/django/template/loader.py", line 62, in render_to_string
    return template.render(context, request)
  File "/usr/local/lib/python3.6/dist-packages/django/template/backends/django.py", line 61, in render
    return self.template.render(context)
  File "/usr/local/lib/python3.6/dist-packages/django/template/base.py", line 175, in render
    return self._render(context)
  File "/usr/local/lib/python3.6/dist-packages/django/template/base.py", line 167, in _render
    return self.nodelist.render(context)
  File "/usr/local/lib/python3.6/dist-packages/django/template/base.py", line 943, in render
    bit = node.render_annotated(context)
  File "/usr/local/lib/python3.6/dist-packages/django/template/base.py", line 910, in render_annotated
    return self.render(context)
  File "/usr/local/lib/python3.6/dist-packages/django/template/loader_tags.py", line 194, in render
    return template.render(context)
  File "/usr/local/lib/python3.6/dist-packages/django/template/base.py", line 177, in render
    return self._render(context)
  File "/usr/local/lib/python3.6/dist-packages/django/template/base.py", line 167, in _render
    return self.nodelist.render(context)
  File "/usr/local/lib/python3.6/dist-packages/django/template/base.py", line 943, in render
    bit = node.render_annotated(context)
  File "/usr/local/lib/python3.6/dist-packages/django/template/base.py", line 910, in render_annotated
    return self.render(context)
  File "/usr/local/lib/python3.6/dist-packages/django/template/defaulttags.py", line 447, in render
    url = reverse(view_name, args=args, kwargs=kwargs, current_app=current_app)
  File "/usr/local/lib/python3.6/dist-packages/django/urls/base.py", line 84, in reverse
    raise NoReverseMatch("%s is not a registered namespace" % key)
django.urls.exceptions.NoReverseMatch: 'basket' is not a registered namespace
ERROR      2018-07-29 16:38:09,309 Internal Server Error: /
Traceback (most recent call last):
  File "/usr/local/lib/python3.6/dist-packages/django/urls/base.py", line 74, in reverse
    extra, resolver = resolver.namespace_dict[ns]
KeyError: 'contacts'

During handling of the above exception, another exception occurred:

Traceback (most recent call last):
  File "/usr/local/lib/python3.6/dist-packages/django/core/handlers/exception.py", line 35, in inner
    response = get_response(request)
  File "/usr/local/lib/python3.6/dist-packages/django/core/handlers/base.py", line 128, in _get_response
    response = self.process_exception_by_middleware(e, request)
  File "/usr/local/lib/python3.6/dist-packages/django/core/handlers/base.py", line 126, in _get_response
    response = wrapped_callback(request, *callback_args, **callback_kwargs)
  File "/home/oleg/git/mainapp/views.py", line 17, in main
    return render(request, 'mainapp/base.html', content)
  File "/usr/local/lib/python3.6/dist-packages/django/shortcuts.py", line 36, in render
    content = loader.render_to_string(template_name, context, request, using=using)
  File "/usr/local/lib/python3.6/dist-packages/django/template/loader.py", line 62, in render_to_string
    return template.render(context, request)
  File "/usr/local/lib/python3.6/dist-packages/django/template/backends/django.py", line 61, in render
    return self.template.render(context)
  File "/usr/local/lib/python3.6/dist-packages/django/template/base.py", line 175, in render
    return self._render(context)
  File "/usr/local/lib/python3.6/dist-packages/django/template/base.py", line 167, in _render
    return self.nodelist.render(context)
  File "/usr/local/lib/python3.6/dist-packages/django/template/base.py", line 943, in render
    bit = node.render_annotated(context)
  File "/usr/local/lib/python3.6/dist-packages/django/template/base.py", line 910, in render_annotated
    return self.render(context)
  File "/usr/local/lib/python3.6/dist-packages/django/template/loader_tags.py", line 194, in render
    return template.render(context)
  File "/usr/local/lib/python3.6/dist-packages/django/template/base.py", line 177, in render
    return self._render(context)
  File "/usr/local/lib/python3.6/dist-packages/django/template/base.py", line 167, in _render
    return self.nodelist.render(context)
  File "/usr/local/lib/python3.6/dist-packages/django/template/base.py", line 943, in render
    bit = node.render_annotated(context)
  File "/usr/local/lib/python3.6/dist-packages/django/template/base.py", line 910, in render_annotated
    return self.render(context)
  File "/usr/local/lib/python3.6/dist-packages/django/template/defaulttags.py", line 447, in render
    url = reverse(view_name, args=args, kwargs=kwargs, current_app=current_app)
  File "/usr/local/lib/python3.6/dist-packages/django/urls/base.py", line 84, in reverse
    raise NoReverseMatch("%s is not a registered namespace" % key)
django.urls.exceptions.NoReverseMatch: 'contacts' is not a registered namespace
WARNING    2018-07-29 16:38:57,797 Not Found: /basket/
ERROR      2018-07-29 16:41:28,801 Internal Server Error: /
Traceback (most recent call last):
  File "/usr/local/lib/python3.6/dist-packages/django/urls/base.py", line 74, in reverse
    extra, resolver = resolver.namespace_dict[ns]
KeyError: 'contacts'

During handling of the above exception, another exception occurred:

Traceback (most recent call last):
  File "/usr/local/lib/python3.6/dist-packages/django/core/handlers/exception.py", line 35, in inner
    response = get_response(request)
  File "/usr/local/lib/python3.6/dist-packages/django/core/handlers/base.py", line 128, in _get_response
    response = self.process_exception_by_middleware(e, request)
  File "/usr/local/lib/python3.6/dist-packages/django/core/handlers/base.py", line 126, in _get_response
    response = wrapped_callback(request, *callback_args, **callback_kwargs)
  File "/home/oleg/git/mainapp/views.py", line 17, in main
    return render(request, 'mainapp/base.html', content)
  File "/usr/local/lib/python3.6/dist-packages/django/shortcuts.py", line 36, in render
    content = loader.render_to_string(template_name, context, request, using=using)
  File "/usr/local/lib/python3.6/dist-packages/django/template/loader.py", line 62, in render_to_string
    return template.render(context, request)
  File "/usr/local/lib/python3.6/dist-packages/django/template/backends/django.py", line 61, in render
    return self.template.render(context)
  File "/usr/local/lib/python3.6/dist-packages/django/template/base.py", line 175, in render
    return self._render(context)
  File "/usr/local/lib/python3.6/dist-packages/django/template/base.py", line 167, in _render
    return self.nodelist.render(context)
  File "/usr/local/lib/python3.6/dist-packages/django/template/base.py", line 943, in render
    bit = node.render_annotated(context)
  File "/usr/local/lib/python3.6/dist-packages/django/template/base.py", line 910, in render_annotated
    return self.render(context)
  File "/usr/local/lib/python3.6/dist-packages/django/template/loader_tags.py", line 194, in render
    return template.render(context)
  File "/usr/local/lib/python3.6/dist-packages/django/template/base.py", line 177, in render
    return self._render(context)
  File "/usr/local/lib/python3.6/dist-packages/django/template/base.py", line 167, in _render
    return self.nodelist.render(context)
  File "/usr/local/lib/python3.6/dist-packages/django/template/base.py", line 943, in render
    bit = node.render_annotated(context)
  File "/usr/local/lib/python3.6/dist-packages/django/template/base.py", line 910, in render_annotated
    return self.render(context)
  File "/usr/local/lib/python3.6/dist-packages/django/template/defaulttags.py", line 447, in render
    url = reverse(view_name, args=args, kwargs=kwargs, current_app=current_app)
  File "/usr/local/lib/python3.6/dist-packages/django/urls/base.py", line 84, in reverse
    raise NoReverseMatch("%s is not a registered namespace" % key)
django.urls.exceptions.NoReverseMatch: 'contacts' is not a registered namespace
ERROR      2018-07-29 16:49:31,532 Internal Server Error: /
Traceback (most recent call last):
  File "/usr/local/lib/python3.6/dist-packages/django/urls/base.py", line 74, in reverse
    extra, resolver = resolver.namespace_dict[ns]
KeyError: 'contacts'

During handling of the above exception, another exception occurred:

Traceback (most recent call last):
  File "/usr/local/lib/python3.6/dist-packages/django/core/handlers/exception.py", line 35, in inner
    response = get_response(request)
  File "/usr/local/lib/python3.6/dist-packages/django/core/handlers/base.py", line 128, in _get_response
    response = self.process_exception_by_middleware(e, request)
  File "/usr/local/lib/python3.6/dist-packages/django/core/handlers/base.py", line 126, in _get_response
    response = wrapped_callback(request, *callback_args, **callback_kwargs)
  File "/home/oleg/git/mainapp/views.py", line 24, in main
    return render(request, 'mainapp/base.html', content)
  File "/usr/local/lib/python3.6/dist-packages/django/shortcuts.py", line 36, in render
    content = loader.render_to_string(template_name, context, request, using=using)
  File "/usr/local/lib/python3.6/dist-packages/django/template/loader.py", line 62, in render_to_string
    return template.render(context, request)
  File "/usr/local/lib/python3.6/dist-packages/django/template/backends/django.py", line 61, in render
    return self.template.render(context)
  File "/usr/local/lib/python3.6/dist-packages/django/template/base.py", line 175, in render
    return self._render(context)
  File "/usr/local/lib/python3.6/dist-packages/django/template/base.py", line 167, in _render
    return self.nodelist.render(context)
  File "/usr/local/lib/python3.6/dist-packages/django/template/base.py", line 943, in render
    bit = node.render_annotated(context)
  File "/usr/local/lib/python3.6/dist-packages/django/template/base.py", line 910, in render_annotated
    return self.render(context)
  File "/usr/local/lib/python3.6/dist-packages/django/template/loader_tags.py", line 194, in render
    return template.render(context)
  File "/usr/local/lib/python3.6/dist-packages/django/template/base.py", line 177, in render
    return self._render(context)
  File "/usr/local/lib/python3.6/dist-packages/django/template/base.py", line 167, in _render
    return self.nodelist.render(context)
  File "/usr/local/lib/python3.6/dist-packages/django/template/base.py", line 943, in render
    bit = node.render_annotated(context)
  File "/usr/local/lib/python3.6/dist-packages/django/template/base.py", line 910, in render_annotated
    return self.render(context)
  File "/usr/local/lib/python3.6/dist-packages/django/template/defaulttags.py", line 447, in render
    url = reverse(view_name, args=args, kwargs=kwargs, current_app=current_app)
  File "/usr/local/lib/python3.6/dist-packages/django/urls/base.py", line 84, in reverse
    raise NoReverseMatch("%s is not a registered namespace" % key)
django.urls.exceptions.NoReverseMatch: 'contacts' is not a registered namespace
ERROR      2018-07-29 16:52:04,106 Internal Server Error: /
Traceback (most recent call last):
  File "/usr/local/lib/python3.6/dist-packages/django/urls/base.py", line 74, in reverse
    extra, resolver = resolver.namespace_dict[ns]
KeyError: 'basket'

During handling of the above exception, another exception occurred:

Traceback (most recent call last):
  File "/usr/local/lib/python3.6/dist-packages/django/core/handlers/exception.py", line 35, in inner
    response = get_response(request)
  File "/usr/local/lib/python3.6/dist-packages/django/core/handlers/base.py", line 128, in _get_response
    response = self.process_exception_by_middleware(e, request)
  File "/usr/local/lib/python3.6/dist-packages/django/core/handlers/base.py", line 126, in _get_response
    response = wrapped_callback(request, *callback_args, **callback_kwargs)
  File "/home/oleg/git/mainapp/views.py", line 24, in main
    return render(request, 'mainapp/base.html', content)
  File "/usr/local/lib/python3.6/dist-packages/django/shortcuts.py", line 36, in render
    content = loader.render_to_string(template_name, context, request, using=using)
  File "/usr/local/lib/python3.6/dist-packages/django/template/loader.py", line 62, in render_to_string
    return template.render(context, request)
  File "/usr/local/lib/python3.6/dist-packages/django/template/backends/django.py", line 61, in render
    return self.template.render(context)
  File "/usr/local/lib/python3.6/dist-packages/django/template/base.py", line 175, in render
    return self._render(context)
  File "/usr/local/lib/python3.6/dist-packages/django/template/base.py", line 167, in _render
    return self.nodelist.render(context)
  File "/usr/local/lib/python3.6/dist-packages/django/template/base.py", line 943, in render
    bit = node.render_annotated(context)
  File "/usr/local/lib/python3.6/dist-packages/django/template/base.py", line 910, in render_annotated
    return self.render(context)
  File "/usr/local/lib/python3.6/dist-packages/django/template/loader_tags.py", line 194, in render
    return template.render(context)
  File "/usr/local/lib/python3.6/dist-packages/django/template/base.py", line 177, in render
    return self._render(context)
  File "/usr/local/lib/python3.6/dist-packages/django/template/base.py", line 167, in _render
    return self.nodelist.render(context)
  File "/usr/local/lib/python3.6/dist-packages/django/template/base.py", line 943, in render
    bit = node.render_annotated(context)
  File "/usr/local/lib/python3.6/dist-packages/django/template/base.py", line 910, in render_annotated
    return self.render(context)
  File "/usr/local/lib/python3.6/dist-packages/django/template/defaulttags.py", line 447, in render
    url = reverse(view_name, args=args, kwargs=kwargs, current_app=current_app)
  File "/usr/local/lib/python3.6/dist-packages/django/urls/base.py", line 84, in reverse
    raise NoReverseMatch("%s is not a registered namespace" % key)
django.urls.exceptions.NoReverseMatch: 'basket' is not a registered namespace
WARNING    2018-07-29 16:54:19,776 Not Found: /accounts/login/
ERROR      2018-07-29 16:54:53,076 Internal Server Error: /auth/login/
Traceback (most recent call last):
  File "/usr/local/lib/python3.6/dist-packages/django/db/backends/utils.py", line 85, in _execute
    return self.cursor.execute(sql, params)
psycopg2.ProgrammingError: relation "authapp_shopuser" does not exist
LINE 1: ...shopuser"."avatar", "authapp_shopuser"."age" FROM "authapp_s...
                                                             ^


The above exception was the direct cause of the following exception:

Traceback (most recent call last):
  File "/usr/local/lib/python3.6/dist-packages/django/core/handlers/exception.py", line 35, in inner
    response = get_response(request)
  File "/usr/local/lib/python3.6/dist-packages/django/core/handlers/base.py", line 128, in _get_response
    response = self.process_exception_by_middleware(e, request)
  File "/usr/local/lib/python3.6/dist-packages/django/core/handlers/base.py", line 126, in _get_response
    response = wrapped_callback(request, *callback_args, **callback_kwargs)
  File "/home/oleg/git/authapp/views.py", line 19, in login
    if request.method == 'POST' and login_form.is_valid():
  File "/usr/local/lib/python3.6/dist-packages/django/forms/forms.py", line 179, in is_valid
    return self.is_bound and not self.errors
  File "/usr/local/lib/python3.6/dist-packages/django/forms/forms.py", line 174, in errors
    self.full_clean()
  File "/usr/local/lib/python3.6/dist-packages/django/forms/forms.py", line 377, in full_clean
    self._clean_form()
  File "/usr/local/lib/python3.6/dist-packages/django/forms/forms.py", line 404, in _clean_form
    cleaned_data = self.clean()
  File "/usr/local/lib/python3.6/dist-packages/django/contrib/auth/forms.py", line 195, in clean
    self.user_cache = authenticate(self.request, username=username, password=password)
  File "/usr/local/lib/python3.6/dist-packages/django/contrib/auth/__init__.py", line 70, in authenticate
    user = _authenticate_with_backend(backend, backend_path, request, credentials)
  File "/usr/local/lib/python3.6/dist-packages/django/contrib/auth/__init__.py", line 116, in _authenticate_with_backend
    return backend.authenticate(*args, **credentials)
  File "/usr/local/lib/python3.6/dist-packages/django/contrib/auth/backends.py", line 16, in authenticate
    user = UserModel._default_manager.get_by_natural_key(username)
  File "/usr/local/lib/python3.6/dist-packages/django/contrib/auth/base_user.py", line 44, in get_by_natural_key
    return self.get(**{self.model.USERNAME_FIELD: username})
  File "/usr/local/lib/python3.6/dist-packages/django/db/models/manager.py", line 82, in manager_method
    return getattr(self.get_queryset(), name)(*args, **kwargs)
  File "/usr/local/lib/python3.6/dist-packages/django/db/models/query.py", line 397, in get
    num = len(clone)
  File "/usr/local/lib/python3.6/dist-packages/django/db/models/query.py", line 254, in __len__
    self._fetch_all()
  File "/usr/local/lib/python3.6/dist-packages/django/db/models/query.py", line 1179, in _fetch_all
    self._result_cache = list(self._iterable_class(self))
  File "/usr/local/lib/python3.6/dist-packages/django/db/models/query.py", line 53, in __iter__
    results = compiler.execute_sql(chunked_fetch=self.chunked_fetch, chunk_size=self.chunk_size)
  File "/usr/local/lib/python3.6/dist-packages/django/db/models/sql/compiler.py", line 1066, in execute_sql
    cursor.execute(sql, params)
  File "/usr/local/lib/python3.6/dist-packages/django/db/backends/utils.py", line 100, in execute
    return super().execute(sql, params)
  File "/usr/local/lib/python3.6/dist-packages/django/db/backends/utils.py", line 68, in execute
    return self._execute_with_wrappers(sql, params, many=False, executor=self._execute)
  File "/usr/local/lib/python3.6/dist-packages/django/db/backends/utils.py", line 77, in _execute_with_wrappers
    return executor(sql, params, many, context)
  File "/usr/local/lib/python3.6/dist-packages/django/db/backends/utils.py", line 85, in _execute
    return self.cursor.execute(sql, params)
  File "/usr/local/lib/python3.6/dist-packages/django/db/utils.py", line 89, in __exit__
    raise dj_exc_value.with_traceback(traceback) from exc_value
  File "/usr/local/lib/python3.6/dist-packages/django/db/backends/utils.py", line 85, in _execute
    return self.cursor.execute(sql, params)
django.db.utils.ProgrammingError: relation "authapp_shopuser" does not exist
LINE 1: ...shopuser"."avatar", "authapp_shopuser"."age" FROM "authapp_s...
                                                             ^

ERROR      2018-07-29 16:58:46,638 Internal Server Error: /auth/register/
Traceback (most recent call last):
  File "/usr/local/lib/python3.6/dist-packages/django/db/backends/utils.py", line 85, in _execute
    return self.cursor.execute(sql, params)
psycopg2.ProgrammingError: relation "authapp_shopuser" does not exist
LINE 1: SELECT (1) AS "a" FROM "authapp_shopuser" WHERE "authapp_sho...
                               ^


The above exception was the direct cause of the following exception:

Traceback (most recent call last):
  File "/usr/local/lib/python3.6/dist-packages/django/core/handlers/exception.py", line 35, in inner
    response = get_response(request)
  File "/usr/local/lib/python3.6/dist-packages/django/core/handlers/base.py", line 128, in _get_response
    response = self.process_exception_by_middleware(e, request)
  File "/usr/local/lib/python3.6/dist-packages/django/core/handlers/base.py", line 126, in _get_response
    response = wrapped_callback(request, *callback_args, **callback_kwargs)
  File "/home/oleg/git/authapp/views.py", line 46, in register
    if register_form.is_valid():
  File "/usr/local/lib/python3.6/dist-packages/django/forms/forms.py", line 179, in is_valid
    return self.is_bound and not self.errors
  File "/usr/local/lib/python3.6/dist-packages/django/forms/forms.py", line 174, in errors
    self.full_clean()
  File "/usr/local/lib/python3.6/dist-packages/django/forms/forms.py", line 378, in full_clean
    self._post_clean()
  File "/usr/local/lib/python3.6/dist-packages/django/contrib/auth/forms.py", line 106, in _post_clean
    super()._post_clean()
  File "/usr/local/lib/python3.6/dist-packages/django/forms/models.py", line 407, in _post_clean
    self.validate_unique()
  File "/usr/local/lib/python3.6/dist-packages/django/forms/models.py", line 416, in validate_unique
    self.instance.validate_unique(exclude=exclude)
  File "/usr/local/lib/python3.6/dist-packages/django/db/models/base.py", line 951, in validate_unique
    errors = self._perform_unique_checks(unique_checks)
  File "/usr/local/lib/python3.6/dist-packages/django/db/models/base.py", line 1047, in _perform_unique_checks
    if qs.exists():
  File "/usr/local/lib/python3.6/dist-packages/django/db/models/query.py", line 715, in exists
    return self.query.has_results(using=self.db)
  File "/usr/local/lib/python3.6/dist-packages/django/db/models/sql/query.py", line 509, in has_results
    return compiler.has_results()
  File "/usr/local/lib/python3.6/dist-packages/django/db/models/sql/compiler.py", line 1035, in has_results
    return bool(self.execute_sql(SINGLE))
  File "/usr/local/lib/python3.6/dist-packages/django/db/models/sql/compiler.py", line 1066, in execute_sql
    cursor.execute(sql, params)
  File "/usr/local/lib/python3.6/dist-packages/django/db/backends/utils.py", line 100, in execute
    return super().execute(sql, params)
  File "/usr/local/lib/python3.6/dist-packages/django/db/backends/utils.py", line 68, in execute
    return self._execute_with_wrappers(sql, params, many=False, executor=self._execute)
  File "/usr/local/lib/python3.6/dist-packages/django/db/backends/utils.py", line 77, in _execute_with_wrappers
    return executor(sql, params, many, context)
  File "/usr/local/lib/python3.6/dist-packages/django/db/backends/utils.py", line 85, in _execute
    return self.cursor.execute(sql, params)
  File "/usr/local/lib/python3.6/dist-packages/django/db/utils.py", line 89, in __exit__
    raise dj_exc_value.with_traceback(traceback) from exc_value
  File "/usr/local/lib/python3.6/dist-packages/django/db/backends/utils.py", line 85, in _execute
    return self.cursor.execute(sql, params)
django.db.utils.ProgrammingError: relation "authapp_shopuser" does not exist
LINE 1: SELECT (1) AS "a" FROM "authapp_shopuser" WHERE "authapp_sho...
                               ^

ERROR      2018-07-29 17:15:29,544 Internal Server Error: /category/
Traceback (most recent call last):
  File "/usr/local/lib/python3.6/dist-packages/django/core/handlers/exception.py", line 35, in inner
    response = get_response(request)
  File "/usr/local/lib/python3.6/dist-packages/django/core/handlers/base.py", line 128, in _get_response
    response = self.process_exception_by_middleware(e, request)
  File "/usr/local/lib/python3.6/dist-packages/django/core/handlers/base.py", line 126, in _get_response
    response = wrapped_callback(request, *callback_args, **callback_kwargs)
  File "/home/oleg/git/mainapp/views.py", line 36, in products
    links_menu = ProductCategory.objects.filter(is_active=True)
  File "/usr/local/lib/python3.6/dist-packages/django/db/models/manager.py", line 82, in manager_method
    return getattr(self.get_queryset(), name)(*args, **kwargs)
  File "/usr/local/lib/python3.6/dist-packages/django/db/models/query.py", line 836, in filter
    return self._filter_or_exclude(False, *args, **kwargs)
  File "/usr/local/lib/python3.6/dist-packages/django/db/models/query.py", line 854, in _filter_or_exclude
    clone.query.add_q(Q(*args, **kwargs))
  File "/usr/local/lib/python3.6/dist-packages/django/db/models/sql/query.py", line 1253, in add_q
    clause, _ = self._add_q(q_object, self.used_aliases)
  File "/usr/local/lib/python3.6/dist-packages/django/db/models/sql/query.py", line 1277, in _add_q
    split_subq=split_subq,
  File "/usr/local/lib/python3.6/dist-packages/django/db/models/sql/query.py", line 1153, in build_filter
    lookups, parts, reffed_expression = self.solve_lookup_type(arg)
  File "/usr/local/lib/python3.6/dist-packages/django/db/models/sql/query.py", line 1015, in solve_lookup_type
    _, field, _, lookup_parts = self.names_to_path(lookup_splitted, self.get_meta())
  File "/usr/local/lib/python3.6/dist-packages/django/db/models/sql/query.py", line 1379, in names_to_path
    "Choices are: %s" % (name, ", ".join(available)))
django.core.exceptions.FieldError: Cannot resolve keyword 'is_active' into field. Choices are: description, id, name, product
ERROR      2018-07-29 17:16:54,073 Internal Server Error: /admin/login/
Traceback (most recent call last):
  File "/usr/local/lib/python3.6/dist-packages/django/db/backends/utils.py", line 85, in _execute
    return self.cursor.execute(sql, params)
psycopg2.ProgrammingError: relation "authapp_shopuser" does not exist
LINE 1: ...shopuser"."avatar", "authapp_shopuser"."age" FROM "authapp_s...
                                                             ^


The above exception was the direct cause of the following exception:

Traceback (most recent call last):
  File "/usr/local/lib/python3.6/dist-packages/django/core/handlers/exception.py", line 35, in inner
    response = get_response(request)
  File "/usr/local/lib/python3.6/dist-packages/django/core/handlers/base.py", line 128, in _get_response
    response = self.process_exception_by_middleware(e, request)
  File "/usr/local/lib/python3.6/dist-packages/django/core/handlers/base.py", line 126, in _get_response
    response = wrapped_callback(request, *callback_args, **callback_kwargs)
  File "/usr/local/lib/python3.6/dist-packages/django/views/decorators/cache.py", line 44, in _wrapped_view_func
    response = view_func(request, *args, **kwargs)
  File "/usr/local/lib/python3.6/dist-packages/django/contrib/admin/sites.py", line 398, in login
    return LoginView.as_view(**defaults)(request)
  File "/usr/local/lib/python3.6/dist-packages/django/views/generic/base.py", line 69, in view
    return self.dispatch(request, *args, **kwargs)
  File "/usr/local/lib/python3.6/dist-packages/django/utils/decorators.py", line 62, in _wrapper
    return bound_func(*args, **kwargs)
  File "/usr/local/lib/python3.6/dist-packages/django/views/decorators/debug.py", line 76, in sensitive_post_parameters_wrapper
    return view(request, *args, **kwargs)
  File "/usr/local/lib/python3.6/dist-packages/django/utils/decorators.py", line 58, in bound_func
    return func.__get__(self, type(self))(*args2, **kwargs2)
  File "/usr/local/lib/python3.6/dist-packages/django/utils/decorators.py", line 62, in _wrapper
    return bound_func(*args, **kwargs)
  File "/usr/local/lib/python3.6/dist-packages/django/utils/decorators.py", line 142, in _wrapped_view
    response = view_func(request, *args, **kwargs)
  File "/usr/local/lib/python3.6/dist-packages/django/utils/decorators.py", line 58, in bound_func
    return func.__get__(self, type(self))(*args2, **kwargs2)
  File "/usr/local/lib/python3.6/dist-packages/django/utils/decorators.py", line 62, in _wrapper
    return bound_func(*args, **kwargs)
  File "/usr/local/lib/python3.6/dist-packages/django/views/decorators/cache.py", line 44, in _wrapped_view_func
    response = view_func(request, *args, **kwargs)
  File "/usr/local/lib/python3.6/dist-packages/django/utils/decorators.py", line 58, in bound_func
    return func.__get__(self, type(self))(*args2, **kwargs2)
  File "/usr/local/lib/python3.6/dist-packages/django/contrib/auth/views.py", line 66, in dispatch
    return super().dispatch(request, *args, **kwargs)
  File "/usr/local/lib/python3.6/dist-packages/django/views/generic/base.py", line 89, in dispatch
    return handler(request, *args, **kwargs)
  File "/usr/local/lib/python3.6/dist-packages/django/views/generic/edit.py", line 141, in post
    if form.is_valid():
  File "/usr/local/lib/python3.6/dist-packages/django/forms/forms.py", line 179, in is_valid
    return self.is_bound and not self.errors
  File "/usr/local/lib/python3.6/dist-packages/django/forms/forms.py", line 174, in errors
    self.full_clean()
  File "/usr/local/lib/python3.6/dist-packages/django/forms/forms.py", line 377, in full_clean
    self._clean_form()
  File "/usr/local/lib/python3.6/dist-packages/django/forms/forms.py", line 404, in _clean_form
    cleaned_data = self.clean()
  File "/usr/local/lib/python3.6/dist-packages/django/contrib/auth/forms.py", line 195, in clean
    self.user_cache = authenticate(self.request, username=username, password=password)
  File "/usr/local/lib/python3.6/dist-packages/django/contrib/auth/__init__.py", line 70, in authenticate
    user = _authenticate_with_backend(backend, backend_path, request, credentials)
  File "/usr/local/lib/python3.6/dist-packages/django/contrib/auth/__init__.py", line 116, in _authenticate_with_backend
    return backend.authenticate(*args, **credentials)
  File "/usr/local/lib/python3.6/dist-packages/django/contrib/auth/backends.py", line 16, in authenticate
    user = UserModel._default_manager.get_by_natural_key(username)
  File "/usr/local/lib/python3.6/dist-packages/django/contrib/auth/base_user.py", line 44, in get_by_natural_key
    return self.get(**{self.model.USERNAME_FIELD: username})
  File "/usr/local/lib/python3.6/dist-packages/django/db/models/manager.py", line 82, in manager_method
    return getattr(self.get_queryset(), name)(*args, **kwargs)
  File "/usr/local/lib/python3.6/dist-packages/django/db/models/query.py", line 397, in get
    num = len(clone)
  File "/usr/local/lib/python3.6/dist-packages/django/db/models/query.py", line 254, in __len__
    self._fetch_all()
  File "/usr/local/lib/python3.6/dist-packages/django/db/models/query.py", line 1179, in _fetch_all
    self._result_cache = list(self._iterable_class(self))
  File "/usr/local/lib/python3.6/dist-packages/django/db/models/query.py", line 53, in __iter__
    results = compiler.execute_sql(chunked_fetch=self.chunked_fetch, chunk_size=self.chunk_size)
  File "/usr/local/lib/python3.6/dist-packages/django/db/models/sql/compiler.py", line 1066, in execute_sql
    cursor.execute(sql, params)
  File "/usr/local/lib/python3.6/dist-packages/django/db/backends/utils.py", line 100, in execute
    return super().execute(sql, params)
  File "/usr/local/lib/python3.6/dist-packages/django/db/backends/utils.py", line 68, in execute
    return self._execute_with_wrappers(sql, params, many=False, executor=self._execute)
  File "/usr/local/lib/python3.6/dist-packages/django/db/backends/utils.py", line 77, in _execute_with_wrappers
    return executor(sql, params, many, context)
  File "/usr/local/lib/python3.6/dist-packages/django/db/backends/utils.py", line 85, in _execute
    return self.cursor.execute(sql, params)
  File "/usr/local/lib/python3.6/dist-packages/django/db/utils.py", line 89, in __exit__
    raise dj_exc_value.with_traceback(traceback) from exc_value
  File "/usr/local/lib/python3.6/dist-packages/django/db/backends/utils.py", line 85, in _execute
    return self.cursor.execute(sql, params)
django.db.utils.ProgrammingError: relation "authapp_shopuser" does not exist
LINE 1: ...shopuser"."avatar", "authapp_shopuser"."age" FROM "authapp_s...
                                                             ^

ERROR      2018-07-29 17:23:58,030 Internal Server Error: /admin/login/
Traceback (most recent call last):
  File "/usr/local/lib/python3.6/dist-packages/django/db/backends/utils.py", line 85, in _execute
    return self.cursor.execute(sql, params)
psycopg2.ProgrammingError: relation "authapp_shopuser" does not exist
LINE 1: ...shopuser"."avatar", "authapp_shopuser"."age" FROM "authapp_s...
                                                             ^


The above exception was the direct cause of the following exception:

Traceback (most recent call last):
  File "/usr/local/lib/python3.6/dist-packages/django/core/handlers/exception.py", line 35, in inner
    response = get_response(request)
  File "/usr/local/lib/python3.6/dist-packages/django/core/handlers/base.py", line 128, in _get_response
    response = self.process_exception_by_middleware(e, request)
  File "/usr/local/lib/python3.6/dist-packages/django/core/handlers/base.py", line 126, in _get_response
    response = wrapped_callback(request, *callback_args, **callback_kwargs)
  File "/usr/local/lib/python3.6/dist-packages/django/views/decorators/cache.py", line 44, in _wrapped_view_func
    response = view_func(request, *args, **kwargs)
  File "/usr/local/lib/python3.6/dist-packages/django/contrib/admin/sites.py", line 398, in login
    return LoginView.as_view(**defaults)(request)
  File "/usr/local/lib/python3.6/dist-packages/django/views/generic/base.py", line 69, in view
    return self.dispatch(request, *args, **kwargs)
  File "/usr/local/lib/python3.6/dist-packages/django/utils/decorators.py", line 62, in _wrapper
    return bound_func(*args, **kwargs)
  File "/usr/local/lib/python3.6/dist-packages/django/views/decorators/debug.py", line 76, in sensitive_post_parameters_wrapper
    return view(request, *args, **kwargs)
  File "/usr/local/lib/python3.6/dist-packages/django/utils/decorators.py", line 58, in bound_func
    return func.__get__(self, type(self))(*args2, **kwargs2)
  File "/usr/local/lib/python3.6/dist-packages/django/utils/decorators.py", line 62, in _wrapper
    return bound_func(*args, **kwargs)
  File "/usr/local/lib/python3.6/dist-packages/django/utils/decorators.py", line 142, in _wrapped_view
    response = view_func(request, *args, **kwargs)
  File "/usr/local/lib/python3.6/dist-packages/django/utils/decorators.py", line 58, in bound_func
    return func.__get__(self, type(self))(*args2, **kwargs2)
  File "/usr/local/lib/python3.6/dist-packages/django/utils/decorators.py", line 62, in _wrapper
    return bound_func(*args, **kwargs)
  File "/usr/local/lib/python3.6/dist-packages/django/views/decorators/cache.py", line 44, in _wrapped_view_func
    response = view_func(request, *args, **kwargs)
  File "/usr/local/lib/python3.6/dist-packages/django/utils/decorators.py", line 58, in bound_func
    return func.__get__(self, type(self))(*args2, **kwargs2)
  File "/usr/local/lib/python3.6/dist-packages/django/contrib/auth/views.py", line 66, in dispatch
    return super().dispatch(request, *args, **kwargs)
  File "/usr/local/lib/python3.6/dist-packages/django/views/generic/base.py", line 89, in dispatch
    return handler(request, *args, **kwargs)
  File "/usr/local/lib/python3.6/dist-packages/django/views/generic/edit.py", line 141, in post
    if form.is_valid():
  File "/usr/local/lib/python3.6/dist-packages/django/forms/forms.py", line 179, in is_valid
    return self.is_bound and not self.errors
  File "/usr/local/lib/python3.6/dist-packages/django/forms/forms.py", line 174, in errors
    self.full_clean()
  File "/usr/local/lib/python3.6/dist-packages/django/forms/forms.py", line 377, in full_clean
    self._clean_form()
  File "/usr/local/lib/python3.6/dist-packages/django/forms/forms.py", line 404, in _clean_form
    cleaned_data = self.clean()
  File "/usr/local/lib/python3.6/dist-packages/django/contrib/auth/forms.py", line 195, in clean
    self.user_cache = authenticate(self.request, username=username, password=password)
  File "/usr/local/lib/python3.6/dist-packages/django/contrib/auth/__init__.py", line 70, in authenticate
    user = _authenticate_with_backend(backend, backend_path, request, credentials)
  File "/usr/local/lib/python3.6/dist-packages/django/contrib/auth/__init__.py", line 116, in _authenticate_with_backend
    return backend.authenticate(*args, **credentials)
  File "/usr/local/lib/python3.6/dist-packages/django/contrib/auth/backends.py", line 16, in authenticate
    user = UserModel._default_manager.get_by_natural_key(username)
  File "/usr/local/lib/python3.6/dist-packages/django/contrib/auth/base_user.py", line 44, in get_by_natural_key
    return self.get(**{self.model.USERNAME_FIELD: username})
  File "/usr/local/lib/python3.6/dist-packages/django/db/models/manager.py", line 82, in manager_method
    return getattr(self.get_queryset(), name)(*args, **kwargs)
  File "/usr/local/lib/python3.6/dist-packages/django/db/models/query.py", line 397, in get
    num = len(clone)
  File "/usr/local/lib/python3.6/dist-packages/django/db/models/query.py", line 254, in __len__
    self._fetch_all()
  File "/usr/local/lib/python3.6/dist-packages/django/db/models/query.py", line 1179, in _fetch_all
    self._result_cache = list(self._iterable_class(self))
  File "/usr/local/lib/python3.6/dist-packages/django/db/models/query.py", line 53, in __iter__
    results = compiler.execute_sql(chunked_fetch=self.chunked_fetch, chunk_size=self.chunk_size)
  File "/usr/local/lib/python3.6/dist-packages/django/db/models/sql/compiler.py", line 1066, in execute_sql
    cursor.execute(sql, params)
  File "/usr/local/lib/python3.6/dist-packages/django/db/backends/utils.py", line 100, in execute
    return super().execute(sql, params)
  File "/usr/local/lib/python3.6/dist-packages/django/db/backends/utils.py", line 68, in execute
    return self._execute_with_wrappers(sql, params, many=False, executor=self._execute)
  File "/usr/local/lib/python3.6/dist-packages/django/db/backends/utils.py", line 77, in _execute_with_wrappers
    return executor(sql, params, many, context)
  File "/usr/local/lib/python3.6/dist-packages/django/db/backends/utils.py", line 85, in _execute
    return self.cursor.execute(sql, params)
  File "/usr/local/lib/python3.6/dist-packages/django/db/utils.py", line 89, in __exit__
    raise dj_exc_value.with_traceback(traceback) from exc_value
  File "/usr/local/lib/python3.6/dist-packages/django/db/backends/utils.py", line 85, in _execute
    return self.cursor.execute(sql, params)
django.db.utils.ProgrammingError: relation "authapp_shopuser" does not exist
LINE 1: ...shopuser"."avatar", "authapp_shopuser"."age" FROM "authapp_s...
                                                             ^

WARNING    2018-07-29 18:45:33,810 Not Found: /favicon.ico
ERROR      2018-07-29 18:46:56,546 Internal Server Error: /
Traceback (most recent call last):
  File "/usr/local/lib/python3.6/dist-packages/django/urls/base.py", line 74, in reverse
    extra, resolver = resolver.namespace_dict[ns]
KeyError: 'auth'

During handling of the above exception, another exception occurred:

Traceback (most recent call last):
  File "/usr/local/lib/python3.6/dist-packages/django/core/handlers/exception.py", line 35, in inner
    response = get_response(request)
  File "/usr/local/lib/python3.6/dist-packages/django/core/handlers/base.py", line 128, in _get_response
    response = self.process_exception_by_middleware(e, request)
  File "/usr/local/lib/python3.6/dist-packages/django/core/handlers/base.py", line 126, in _get_response
    response = wrapped_callback(request, *callback_args, **callback_kwargs)
  File "/home/oleg/git/mainapp/views.py", line 24, in main
    return render(request, 'mainapp/base.html', content)
  File "/usr/local/lib/python3.6/dist-packages/django/shortcuts.py", line 36, in render
    content = loader.render_to_string(template_name, context, request, using=using)
  File "/usr/local/lib/python3.6/dist-packages/django/template/loader.py", line 62, in render_to_string
    return template.render(context, request)
  File "/usr/local/lib/python3.6/dist-packages/django/template/backends/django.py", line 61, in render
    return self.template.render(context)
  File "/usr/local/lib/python3.6/dist-packages/django/template/base.py", line 175, in render
    return self._render(context)
  File "/usr/local/lib/python3.6/dist-packages/django/template/base.py", line 167, in _render
    return self.nodelist.render(context)
  File "/usr/local/lib/python3.6/dist-packages/django/template/base.py", line 943, in render
    bit = node.render_annotated(context)
  File "/usr/local/lib/python3.6/dist-packages/django/template/base.py", line 910, in render_annotated
    return self.render(context)
  File "/usr/local/lib/python3.6/dist-packages/django/template/loader_tags.py", line 194, in render
    return template.render(context)
  File "/usr/local/lib/python3.6/dist-packages/django/template/base.py", line 177, in render
    return self._render(context)
  File "/usr/local/lib/python3.6/dist-packages/django/template/base.py", line 167, in _render
    return self.nodelist.render(context)
  File "/usr/local/lib/python3.6/dist-packages/django/template/base.py", line 943, in render
    bit = node.render_annotated(context)
  File "/usr/local/lib/python3.6/dist-packages/django/template/base.py", line 910, in render_annotated
    return self.render(context)
  File "/usr/local/lib/python3.6/dist-packages/django/template/defaulttags.py", line 314, in render
    return nodelist.render(context)
  File "/usr/local/lib/python3.6/dist-packages/django/template/base.py", line 943, in render
    bit = node.render_annotated(context)
  File "/usr/local/lib/python3.6/dist-packages/django/template/base.py", line 910, in render_annotated
    return self.render(context)
  File "/usr/local/lib/python3.6/dist-packages/django/template/defaulttags.py", line 447, in render
    url = reverse(view_name, args=args, kwargs=kwargs, current_app=current_app)
  File "/usr/local/lib/python3.6/dist-packages/django/urls/base.py", line 84, in reverse
    raise NoReverseMatch("%s is not a registered namespace" % key)
django.urls.exceptions.NoReverseMatch: 'auth' is not a registered namespace
